[2023-05-18T05:45:38.651+0000] {taskinstance.py:1125} INFO - Dependencies all met for dep_context=non-requeueable deps ti=<TaskInstance: fondue_dag.clustering manual__2023-05-18T05:45:01.623732+00:00 [queued]>
[2023-05-18T05:45:38.662+0000] {taskinstance.py:1125} INFO - Dependencies all met for dep_context=requeueable deps ti=<TaskInstance: fondue_dag.clustering manual__2023-05-18T05:45:01.623732+00:00 [queued]>
[2023-05-18T05:45:38.663+0000] {taskinstance.py:1331} INFO - Starting attempt 1 of 2
[2023-05-18T05:45:38.683+0000] {taskinstance.py:1350} INFO - Executing <Task(PythonOperator): clustering> on 2023-05-18 05:45:01.623732+00:00
[2023-05-18T05:45:38.691+0000] {standard_task_runner.py:57} INFO - Started process 4797 to run task
[2023-05-18T05:45:38.694+0000] {standard_task_runner.py:84} INFO - Running: ['***', 'tasks', 'run', 'fondue_dag', 'clustering', 'manual__2023-05-18T05:45:01.623732+00:00', '--job-id', '82', '--raw', '--subdir', 'DAGS_FOLDER/fondue_dag.py', '--cfg-path', '/tmp/tmpfppxbhje']
[2023-05-18T05:45:38.696+0000] {standard_task_runner.py:85} INFO - Job 82: Subtask clustering
[2023-05-18T05:45:38.754+0000] {task_command.py:410} INFO - Running <TaskInstance: fondue_dag.clustering manual__2023-05-18T05:45:01.623732+00:00 [running]> on host b36de7cfc389
[2023-05-18T05:45:38.860+0000] {taskinstance.py:1570} INFO - Exporting env vars: AIRFLOW_CTX_DAG_EMAIL='Bhuribhat@gmail.com' AIRFLOW_CTX_DAG_OWNER='pras' AIRFLOW_CTX_DAG_ID='fondue_dag' AIRFLOW_CTX_TASK_ID='clustering' AIRFLOW_CTX_EXECUTION_DATE='2023-05-18T05:45:01.623732+00:00' AIRFLOW_CTX_TRY_NUMBER='1' AIRFLOW_CTX_DAG_RUN_ID='manual__2023-05-18T05:45:01.623732+00:00'
[2023-05-18T05:45:38.878+0000] {taskinstance.py:1847} ERROR - Task failed with exception
Traceback (most recent call last):
  File "/home/airflow/.local/lib/python3.7/site-packages/airflow/operators/python.py", line 181, in execute
    return_value = self.execute_callable()
  File "/home/airflow/.local/lib/python3.7/site-packages/airflow/operators/python.py", line 198, in execute_callable
    return self.python_callable(*self.op_args, **self.op_kwargs)
  File "/opt/airflow/dags/utils/clustering.py", line 25, in kmean_cluster
    scaler.fit(x)
  File "/home/airflow/.local/lib/python3.7/site-packages/sklearn/preprocessing/_data.py", line 806, in fit
    return self.partial_fit(X, y, sample_weight)
  File "/home/airflow/.local/lib/python3.7/site-packages/sklearn/preprocessing/_data.py", line 847, in partial_fit
    reset=first_call,
  File "/home/airflow/.local/lib/python3.7/site-packages/sklearn/base.py", line 566, in _validate_data
    X = check_array(X, **check_params)
  File "/home/airflow/.local/lib/python3.7/site-packages/sklearn/utils/validation.py", line 808, in check_array
    % (n_samples, array.shape, ensure_min_samples, context)
ValueError: Found array with 0 sample(s) (shape=(0, 2)) while a minimum of 1 is required by StandardScaler.
[2023-05-18T05:45:38.901+0000] {taskinstance.py:1373} INFO - Marking task as UP_FOR_RETRY. dag_id=fondue_dag, task_id=clustering, execution_date=20230518T054501, start_date=20230518T054538, end_date=20230518T054538
[2023-05-18T05:45:38.928+0000] {configuration.py:675} WARNING - section/key [smtp/smtp_user] not found in config
[2023-05-18T05:45:38.929+0000] {email.py:268} INFO - Email alerting: attempt 1
[2023-05-18T05:45:38.938+0000] {configuration.py:675} WARNING - section/key [smtp/smtp_user] not found in config
[2023-05-18T05:45:38.938+0000] {email.py:268} INFO - Email alerting: attempt 1
[2023-05-18T05:45:38.939+0000] {taskinstance.py:1912} ERROR - Failed to send email to: ['Bhuribhat@gmail.com']
Traceback (most recent call last):
  File "/home/airflow/.local/lib/python3.7/site-packages/airflow/models/taskinstance.py", line 1430, in _run_raw_task
    self._execute_task_with_callbacks(context, test_mode)
  File "/home/airflow/.local/lib/python3.7/site-packages/airflow/models/taskinstance.py", line 1581, in _execute_task_with_callbacks
    result = self._execute_task(context, task_orig)
  File "/home/airflow/.local/lib/python3.7/site-packages/airflow/models/taskinstance.py", line 1651, in _execute_task
    result = execute_callable(context=context)
  File "/home/airflow/.local/lib/python3.7/site-packages/airflow/operators/python.py", line 181, in execute
    return_value = self.execute_callable()
  File "/home/airflow/.local/lib/python3.7/site-packages/airflow/operators/python.py", line 198, in execute_callable
    return self.python_callable(*self.op_args, **self.op_kwargs)
  File "/opt/airflow/dags/utils/clustering.py", line 25, in kmean_cluster
    scaler.fit(x)
  File "/home/airflow/.local/lib/python3.7/site-packages/sklearn/preprocessing/_data.py", line 806, in fit
    return self.partial_fit(X, y, sample_weight)
  File "/home/airflow/.local/lib/python3.7/site-packages/sklearn/preprocessing/_data.py", line 847, in partial_fit
    reset=first_call,
  File "/home/airflow/.local/lib/python3.7/site-packages/sklearn/base.py", line 566, in _validate_data
    X = check_array(X, **check_params)
  File "/home/airflow/.local/lib/python3.7/site-packages/sklearn/utils/validation.py", line 808, in check_array
    % (n_samples, array.shape, ensure_min_samples, context)
ValueError: Found array with 0 sample(s) (shape=(0, 2)) while a minimum of 1 is required by StandardScaler.

During handling of the above exception, another exception occurred:

Traceback (most recent call last):
  File "/home/airflow/.local/lib/python3.7/site-packages/airflow/models/taskinstance.py", line 2318, in email_alert
    send_email(task.email, subject, html_content)
  File "/home/airflow/.local/lib/python3.7/site-packages/airflow/utils/email.py", line 91, in send_email
    **kwargs,
  File "/home/airflow/.local/lib/python3.7/site-packages/airflow/utils/email.py", line 152, in send_email_smtp
    send_mime_email(e_from=mail_from, e_to=recipients, mime_msg=msg, conn_id=conn_id, dryrun=dryrun)
  File "/home/airflow/.local/lib/python3.7/site-packages/airflow/utils/email.py", line 270, in send_mime_email
    smtp_conn = _get_smtp_connection(smtp_host, smtp_port, smtp_timeout, smtp_ssl)
  File "/home/airflow/.local/lib/python3.7/site-packages/airflow/utils/email.py", line 317, in _get_smtp_connection
    else smtplib.SMTP(host=host, port=port, timeout=timeout)
  File "/usr/local/lib/python3.7/smtplib.py", line 251, in __init__
    (code, msg) = self.connect(host, port)
  File "/usr/local/lib/python3.7/smtplib.py", line 336, in connect
    self.sock = self._get_socket(host, port, self.timeout)
  File "/usr/local/lib/python3.7/smtplib.py", line 307, in _get_socket
    self.source_address)
  File "/usr/local/lib/python3.7/socket.py", line 728, in create_connection
    raise err
  File "/usr/local/lib/python3.7/socket.py", line 716, in create_connection
    sock.connect(sa)
OSError: [Errno 99] Cannot assign requested address

During handling of the above exception, another exception occurred:

Traceback (most recent call last):
  File "/home/airflow/.local/lib/python3.7/site-packages/airflow/models/taskinstance.py", line 1910, in handle_failure
    self.email_alert(error, task)
  File "/home/airflow/.local/lib/python3.7/site-packages/airflow/models/taskinstance.py", line 2320, in email_alert
    send_email(task.email, subject, html_content_err)
  File "/home/airflow/.local/lib/python3.7/site-packages/airflow/utils/email.py", line 91, in send_email
    **kwargs,
  File "/home/airflow/.local/lib/python3.7/site-packages/airflow/utils/email.py", line 152, in send_email_smtp
    send_mime_email(e_from=mail_from, e_to=recipients, mime_msg=msg, conn_id=conn_id, dryrun=dryrun)
  File "/home/airflow/.local/lib/python3.7/site-packages/airflow/utils/email.py", line 270, in send_mime_email
    smtp_conn = _get_smtp_connection(smtp_host, smtp_port, smtp_timeout, smtp_ssl)
  File "/home/airflow/.local/lib/python3.7/site-packages/airflow/utils/email.py", line 317, in _get_smtp_connection
    else smtplib.SMTP(host=host, port=port, timeout=timeout)
  File "/usr/local/lib/python3.7/smtplib.py", line 251, in __init__
    (code, msg) = self.connect(host, port)
  File "/usr/local/lib/python3.7/smtplib.py", line 336, in connect
    self.sock = self._get_socket(host, port, self.timeout)
  File "/usr/local/lib/python3.7/smtplib.py", line 307, in _get_socket
    self.source_address)
  File "/usr/local/lib/python3.7/socket.py", line 728, in create_connection
    raise err
  File "/usr/local/lib/python3.7/socket.py", line 716, in create_connection
    sock.connect(sa)
OSError: [Errno 99] Cannot assign requested address
[2023-05-18T05:45:38.958+0000] {standard_task_runner.py:109} ERROR - Failed to execute job 82 for task clustering (Found array with 0 sample(s) (shape=(0, 2)) while a minimum of 1 is required by StandardScaler.; 4797)
[2023-05-18T05:45:38.987+0000] {local_task_job_runner.py:232} INFO - Task exited with return code 1
[2023-05-18T05:45:39.016+0000] {taskinstance.py:2674} INFO - 0 downstream tasks scheduled from follow-on schedule check
