[2023-05-17T16:46:25.797+0000] {taskinstance.py:1125} INFO - Dependencies all met for dep_context=non-requeueable deps ti=<TaskInstance: fondue_dag.clustering scheduled__2023-05-15T00:00:00+00:00 [queued]>
[2023-05-17T16:46:25.818+0000] {taskinstance.py:1125} INFO - Dependencies all met for dep_context=requeueable deps ti=<TaskInstance: fondue_dag.clustering scheduled__2023-05-15T00:00:00+00:00 [queued]>
[2023-05-17T16:46:25.819+0000] {taskinstance.py:1331} INFO - Starting attempt 1 of 2
[2023-05-17T16:46:25.846+0000] {taskinstance.py:1350} INFO - Executing <Task(PythonOperator): clustering> on 2023-05-15 00:00:00+00:00
[2023-05-17T16:46:25.859+0000] {standard_task_runner.py:57} INFO - Started process 1717 to run task
[2023-05-17T16:46:25.863+0000] {standard_task_runner.py:84} INFO - Running: ['***', 'tasks', 'run', 'fondue_dag', 'clustering', 'scheduled__2023-05-15T00:00:00+00:00', '--job-id', '34', '--raw', '--subdir', 'DAGS_FOLDER/fondue_dag.py', '--cfg-path', '/tmp/tmpodh5cy5j']
[2023-05-17T16:46:25.866+0000] {standard_task_runner.py:85} INFO - Job 34: Subtask clustering
[2023-05-17T16:46:25.947+0000] {task_command.py:410} INFO - Running <TaskInstance: fondue_dag.clustering scheduled__2023-05-15T00:00:00+00:00 [running]> on host 8cf8fb9e28f7
[2023-05-17T16:46:26.136+0000] {taskinstance.py:1570} INFO - Exporting env vars: AIRFLOW_CTX_DAG_EMAIL='Bhuribhat@gmail.com' AIRFLOW_CTX_DAG_OWNER='pras' AIRFLOW_CTX_DAG_ID='fondue_dag' AIRFLOW_CTX_TASK_ID='clustering' AIRFLOW_CTX_EXECUTION_DATE='2023-05-15T00:00:00+00:00' AIRFLOW_CTX_TRY_NUMBER='1' AIRFLOW_CTX_DAG_RUN_ID='scheduled__2023-05-15T00:00:00+00:00'
[2023-05-17T16:46:43.915+0000] {logging_mixin.py:149} WARNING - 2023/05/17 16:46:43 WARNING mlflow.utils.git_utils: Failed to import Git (the Git executable is probably not on your PATH), so Git SHA is not available. Error: Failed to initialize: Bad git executable.
The git executable must be specified in one of the following ways:
    - be included in your $PATH
    - be set via $GIT_PYTHON_GIT_EXECUTABLE
    - explicitly set via git.refresh()

All git commands will error until this is rectified.

This initial warning can be silenced or aggravated in the future by setting the
$GIT_PYTHON_REFRESH environment variable. Use one of the following values:
    - quiet|q|silence|s|none|n|0: for no warning or exception
    - warn|w|warning|1: for a printed warning
    - error|e|raise|r|2: for a raised exception

Example:
    export GIT_PYTHON_REFRESH=quiet
[2023-05-17T16:46:48.404+0000] {python.py:183} INFO - Done. Returned value was: None
[2023-05-17T16:46:48.416+0000] {taskinstance.py:1373} INFO - Marking task as SUCCESS. dag_id=fondue_dag, task_id=clustering, execution_date=20230515T000000, start_date=20230517T164625, end_date=20230517T164648
[2023-05-17T16:46:48.464+0000] {local_task_job_runner.py:232} INFO - Task exited with return code 0
[2023-05-17T16:46:48.486+0000] {taskinstance.py:2674} INFO - 1 downstream tasks scheduled from follow-on schedule check
<<<<<<< HEAD
[2023-05-17T17:55:05.783+0000] {taskinstance.py:1125} INFO - Dependencies all met for dep_context=non-requeueable deps ti=<TaskInstance: fondue_dag.clustering scheduled__2023-05-15T00:00:00+00:00 [queued]>
[2023-05-17T17:55:05.800+0000] {taskinstance.py:1125} INFO - Dependencies all met for dep_context=requeueable deps ti=<TaskInstance: fondue_dag.clustering scheduled__2023-05-15T00:00:00+00:00 [queued]>
[2023-05-17T17:55:05.801+0000] {taskinstance.py:1331} INFO - Starting attempt 1 of 2
[2023-05-17T17:55:05.829+0000] {taskinstance.py:1350} INFO - Executing <Task(PythonOperator): clustering> on 2023-05-15 00:00:00+00:00
[2023-05-17T17:55:05.840+0000] {standard_task_runner.py:57} INFO - Started process 863 to run task
[2023-05-17T17:55:05.844+0000] {standard_task_runner.py:84} INFO - Running: ['***', 'tasks', 'run', 'fondue_dag', 'clustering', 'scheduled__2023-05-15T00:00:00+00:00', '--job-id', '32', '--raw', '--subdir', 'DAGS_FOLDER/fondue_dag.py', '--cfg-path', '/tmp/tmpg8oannhk']
[2023-05-17T17:55:05.846+0000] {standard_task_runner.py:85} INFO - Job 32: Subtask clustering
[2023-05-17T17:55:05.913+0000] {task_command.py:410} INFO - Running <TaskInstance: fondue_dag.clustering scheduled__2023-05-15T00:00:00+00:00 [running]> on host a37c7bc3731c
[2023-05-17T17:55:06.106+0000] {taskinstance.py:1570} INFO - Exporting env vars: AIRFLOW_CTX_DAG_EMAIL='Bhuribhat@gmail.com' AIRFLOW_CTX_DAG_OWNER='pras' AIRFLOW_CTX_DAG_ID='fondue_dag' AIRFLOW_CTX_TASK_ID='clustering' AIRFLOW_CTX_EXECUTION_DATE='2023-05-15T00:00:00+00:00' AIRFLOW_CTX_TRY_NUMBER='1' AIRFLOW_CTX_DAG_RUN_ID='scheduled__2023-05-15T00:00:00+00:00'
[2023-05-17T17:55:28.277+0000] {logging_mixin.py:149} WARNING - 2023/05/17 17:55:28 WARNING mlflow.utils.git_utils: Failed to import Git (the Git executable is probably not on your PATH), so Git SHA is not available. Error: Failed to initialize: Bad git executable.
=======
[2023-05-18T04:22:22.808+0000] {logging_mixin.py:149} INFO - Changing /opt/***/logs/dag_id=fondue_dag/run_id=scheduled__2023-05-15T00:00:00+00:00/task_id=clustering permission to 509
[2023-05-18T04:22:22.811+0000] {logging_mixin.py:149} INFO - Failed to change /opt/***/logs/dag_id=fondue_dag/run_id=scheduled__2023-05-15T00:00:00+00:00/task_id=clustering permission to 509: [Errno 1] Operation not permitted: '/opt/***/logs/dag_id=fondue_dag/run_id=scheduled__2023-05-15T00:00:00+00:00/task_id=clustering'
[2023-05-18T04:22:22.892+0000] {logging_mixin.py:149} INFO - Changing /opt/***/logs/dag_id=fondue_dag/run_id=scheduled__2023-05-15T00:00:00+00:00/task_id=clustering permission to 509
[2023-05-18T04:22:22.895+0000] {logging_mixin.py:149} INFO - Failed to change /opt/***/logs/dag_id=fondue_dag/run_id=scheduled__2023-05-15T00:00:00+00:00/task_id=clustering permission to 509: [Errno 1] Operation not permitted: '/opt/***/logs/dag_id=fondue_dag/run_id=scheduled__2023-05-15T00:00:00+00:00/task_id=clustering'
[2023-05-18T04:22:22.982+0000] {taskinstance.py:1125} INFO - Dependencies all met for dep_context=non-requeueable deps ti=<TaskInstance: fondue_dag.clustering scheduled__2023-05-15T00:00:00+00:00 [queued]>
[2023-05-18T04:22:23.002+0000] {taskinstance.py:1125} INFO - Dependencies all met for dep_context=requeueable deps ti=<TaskInstance: fondue_dag.clustering scheduled__2023-05-15T00:00:00+00:00 [queued]>
[2023-05-18T04:22:23.007+0000] {taskinstance.py:1331} INFO - Starting attempt 1 of 2
[2023-05-18T04:22:23.078+0000] {taskinstance.py:1350} INFO - Executing <Task(PythonOperator): clustering> on 2023-05-15 00:00:00+00:00
[2023-05-18T04:22:23.102+0000] {standard_task_runner.py:57} INFO - Started process 571 to run task
[2023-05-18T04:22:23.121+0000] {standard_task_runner.py:84} INFO - Running: ['***', 'tasks', 'run', 'fondue_dag', 'clustering', 'scheduled__2023-05-15T00:00:00+00:00', '--job-id', '32', '--raw', '--subdir', 'DAGS_FOLDER/fondue_dag.py', '--cfg-path', '/tmp/tmp5my0tf7k']
[2023-05-18T04:22:23.124+0000] {standard_task_runner.py:85} INFO - Job 32: Subtask clustering
[2023-05-18T04:22:23.265+0000] {logging_mixin.py:149} INFO - Changing /opt/***/logs/dag_id=fondue_dag/run_id=scheduled__2023-05-15T00:00:00+00:00/task_id=clustering permission to 509
[2023-05-18T04:22:23.267+0000] {logging_mixin.py:149} INFO - Failed to change /opt/***/logs/dag_id=fondue_dag/run_id=scheduled__2023-05-15T00:00:00+00:00/task_id=clustering permission to 509: [Errno 1] Operation not permitted: '/opt/***/logs/dag_id=fondue_dag/run_id=scheduled__2023-05-15T00:00:00+00:00/task_id=clustering'
[2023-05-18T04:22:23.278+0000] {task_command.py:410} INFO - Running <TaskInstance: fondue_dag.clustering scheduled__2023-05-15T00:00:00+00:00 [running]> on host b36de7cfc389
[2023-05-18T04:22:23.541+0000] {taskinstance.py:1570} INFO - Exporting env vars: AIRFLOW_CTX_DAG_EMAIL='Bhuribhat@gmail.com' AIRFLOW_CTX_DAG_OWNER='pras' AIRFLOW_CTX_DAG_ID='fondue_dag' AIRFLOW_CTX_TASK_ID='clustering' AIRFLOW_CTX_EXECUTION_DATE='2023-05-15T00:00:00+00:00' AIRFLOW_CTX_TRY_NUMBER='1' AIRFLOW_CTX_DAG_RUN_ID='scheduled__2023-05-15T00:00:00+00:00'
[2023-05-18T04:23:08.431+0000] {logging_mixin.py:149} WARNING - 2023/05/18 04:23:08 WARNING mlflow.utils.git_utils: Failed to import Git (the Git executable is probably not on your PATH), so Git SHA is not available. Error: Failed to initialize: Bad git executable.
>>>>>>> 8e4a41b368593e9ce283ae02afd6c27252f67370
The git executable must be specified in one of the following ways:
    - be included in your $PATH
    - be set via $GIT_PYTHON_GIT_EXECUTABLE
    - explicitly set via git.refresh()

All git commands will error until this is rectified.

This initial warning can be silenced or aggravated in the future by setting the
$GIT_PYTHON_REFRESH environment variable. Use one of the following values:
    - quiet|q|silence|s|none|n|0: for no warning or exception
    - warn|w|warning|1: for a printed warning
    - error|e|raise|r|2: for a raised exception

Example:
    export GIT_PYTHON_REFRESH=quiet
<<<<<<< HEAD
[2023-05-17T17:55:34.421+0000] {python.py:183} INFO - Done. Returned value was: None
[2023-05-17T17:55:34.439+0000] {taskinstance.py:1373} INFO - Marking task as SUCCESS. dag_id=fondue_dag, task_id=clustering, execution_date=20230515T000000, start_date=20230517T175505, end_date=20230517T175534
[2023-05-17T17:55:34.486+0000] {local_task_job_runner.py:232} INFO - Task exited with return code 0
[2023-05-17T17:55:34.521+0000] {taskinstance.py:2674} INFO - 1 downstream tasks scheduled from follow-on schedule check
[2023-05-17T18:18:26.631+0000] {taskinstance.py:1125} INFO - Dependencies all met for dep_context=non-requeueable deps ti=<TaskInstance: fondue_dag.clustering scheduled__2023-05-15T00:00:00+00:00 [queued]>
[2023-05-17T18:18:26.688+0000] {taskinstance.py:1125} INFO - Dependencies all met for dep_context=requeueable deps ti=<TaskInstance: fondue_dag.clustering scheduled__2023-05-15T00:00:00+00:00 [queued]>
[2023-05-17T18:18:26.689+0000] {taskinstance.py:1331} INFO - Starting attempt 1 of 2
[2023-05-17T18:18:26.859+0000] {taskinstance.py:1350} INFO - Executing <Task(PythonOperator): clustering> on 2023-05-15 00:00:00+00:00
[2023-05-17T18:18:26.868+0000] {standard_task_runner.py:57} INFO - Started process 1114 to run task
[2023-05-17T18:18:26.882+0000] {standard_task_runner.py:84} INFO - Running: ['***', 'tasks', 'run', 'fondue_dag', 'clustering', 'scheduled__2023-05-15T00:00:00+00:00', '--job-id', '33', '--raw', '--subdir', 'DAGS_FOLDER/fondue_dag.py', '--cfg-path', '/tmp/tmpt6hw4gwx']
[2023-05-17T18:18:26.893+0000] {standard_task_runner.py:85} INFO - Job 33: Subtask clustering
[2023-05-17T18:18:27.012+0000] {task_command.py:410} INFO - Running <TaskInstance: fondue_dag.clustering scheduled__2023-05-15T00:00:00+00:00 [running]> on host 3390ff13fbf6
[2023-05-17T18:18:27.490+0000] {taskinstance.py:1570} INFO - Exporting env vars: AIRFLOW_CTX_DAG_EMAIL='Bhuribhat@gmail.com' AIRFLOW_CTX_DAG_OWNER='pras' AIRFLOW_CTX_DAG_ID='fondue_dag' AIRFLOW_CTX_TASK_ID='clustering' AIRFLOW_CTX_EXECUTION_DATE='2023-05-15T00:00:00+00:00' AIRFLOW_CTX_TRY_NUMBER='1' AIRFLOW_CTX_DAG_RUN_ID='scheduled__2023-05-15T00:00:00+00:00'
[2023-05-17T18:18:50.992+0000] {logging_mixin.py:149} WARNING - 2023/05/17 18:18:50 WARNING mlflow.utils.git_utils: Failed to import Git (the Git executable is probably not on your PATH), so Git SHA is not available. Error: Failed to initialize: Bad git executable.
The git executable must be specified in one of the following ways:
    - be included in your $PATH
    - be set via $GIT_PYTHON_GIT_EXECUTABLE
    - explicitly set via git.refresh()

All git commands will error until this is rectified.

This initial warning can be silenced or aggravated in the future by setting the
$GIT_PYTHON_REFRESH environment variable. Use one of the following values:
    - quiet|q|silence|s|none|n|0: for no warning or exception
    - warn|w|warning|1: for a printed warning
    - error|e|raise|r|2: for a raised exception

Example:
    export GIT_PYTHON_REFRESH=quiet
[2023-05-17T18:18:59.057+0000] {python.py:183} INFO - Done. Returned value was: None
[2023-05-17T18:18:59.092+0000] {taskinstance.py:1373} INFO - Marking task as SUCCESS. dag_id=fondue_dag, task_id=clustering, execution_date=20230515T000000, start_date=20230517T181826, end_date=20230517T181859
[2023-05-17T18:18:59.201+0000] {local_task_job_runner.py:232} INFO - Task exited with return code 0
[2023-05-17T18:18:59.232+0000] {taskinstance.py:2674} INFO - 1 downstream tasks scheduled from follow-on schedule check
[2023-05-17T18:26:00.156+0000] {taskinstance.py:1125} INFO - Dependencies all met for dep_context=non-requeueable deps ti=<TaskInstance: fondue_dag.clustering scheduled__2023-05-15T00:00:00+00:00 [queued]>
[2023-05-17T18:26:00.192+0000] {taskinstance.py:1125} INFO - Dependencies all met for dep_context=requeueable deps ti=<TaskInstance: fondue_dag.clustering scheduled__2023-05-15T00:00:00+00:00 [queued]>
[2023-05-17T18:26:00.196+0000] {taskinstance.py:1331} INFO - Starting attempt 1 of 2
[2023-05-17T18:26:00.249+0000] {taskinstance.py:1350} INFO - Executing <Task(PythonOperator): clustering> on 2023-05-15 00:00:00+00:00
[2023-05-17T18:26:00.257+0000] {standard_task_runner.py:57} INFO - Started process 1569 to run task
[2023-05-17T18:26:00.267+0000] {standard_task_runner.py:84} INFO - Running: ['***', 'tasks', 'run', 'fondue_dag', 'clustering', 'scheduled__2023-05-15T00:00:00+00:00', '--job-id', '37', '--raw', '--subdir', 'DAGS_FOLDER/fondue_dag.py', '--cfg-path', '/tmp/tmpajuj82vy']
[2023-05-17T18:26:00.270+0000] {standard_task_runner.py:85} INFO - Job 37: Subtask clustering
[2023-05-17T18:26:00.405+0000] {task_command.py:410} INFO - Running <TaskInstance: fondue_dag.clustering scheduled__2023-05-15T00:00:00+00:00 [running]> on host 70fcd41af239
[2023-05-17T18:26:00.656+0000] {taskinstance.py:1570} INFO - Exporting env vars: AIRFLOW_CTX_DAG_EMAIL='Bhuribhat@gmail.com' AIRFLOW_CTX_DAG_OWNER='pras' AIRFLOW_CTX_DAG_ID='fondue_dag' AIRFLOW_CTX_TASK_ID='clustering' AIRFLOW_CTX_EXECUTION_DATE='2023-05-15T00:00:00+00:00' AIRFLOW_CTX_TRY_NUMBER='1' AIRFLOW_CTX_DAG_RUN_ID='scheduled__2023-05-15T00:00:00+00:00'
[2023-05-17T18:26:13.927+0000] {logging_mixin.py:149} WARNING - 2023/05/17 18:26:13 WARNING mlflow.utils.git_utils: Failed to import Git (the Git executable is probably not on your PATH), so Git SHA is not available. Error: Failed to initialize: Bad git executable.
The git executable must be specified in one of the following ways:
    - be included in your $PATH
    - be set via $GIT_PYTHON_GIT_EXECUTABLE
    - explicitly set via git.refresh()

All git commands will error until this is rectified.

This initial warning can be silenced or aggravated in the future by setting the
$GIT_PYTHON_REFRESH environment variable. Use one of the following values:
    - quiet|q|silence|s|none|n|0: for no warning or exception
    - warn|w|warning|1: for a printed warning
    - error|e|raise|r|2: for a raised exception

Example:
    export GIT_PYTHON_REFRESH=quiet
[2023-05-17T18:26:18.689+0000] {python.py:183} INFO - Done. Returned value was: None
[2023-05-17T18:26:18.703+0000] {taskinstance.py:1373} INFO - Marking task as SUCCESS. dag_id=fondue_dag, task_id=clustering, execution_date=20230515T000000, start_date=20230517T182600, end_date=20230517T182618
[2023-05-17T18:26:18.742+0000] {local_task_job_runner.py:232} INFO - Task exited with return code 0
[2023-05-17T18:26:18.769+0000] {taskinstance.py:2674} INFO - 1 downstream tasks scheduled from follow-on schedule check
[2023-05-17T18:37:33.024+0000] {taskinstance.py:1125} INFO - Dependencies all met for dep_context=non-requeueable deps ti=<TaskInstance: fondue_dag.clustering scheduled__2023-05-15T00:00:00+00:00 [queued]>
[2023-05-17T18:37:33.066+0000] {taskinstance.py:1125} INFO - Dependencies all met for dep_context=requeueable deps ti=<TaskInstance: fondue_dag.clustering scheduled__2023-05-15T00:00:00+00:00 [queued]>
[2023-05-17T18:37:33.079+0000] {taskinstance.py:1331} INFO - Starting attempt 1 of 2
[2023-05-17T18:37:33.125+0000] {taskinstance.py:1350} INFO - Executing <Task(PythonOperator): clustering> on 2023-05-15 00:00:00+00:00
[2023-05-17T18:37:33.138+0000] {standard_task_runner.py:57} INFO - Started process 1604 to run task
[2023-05-17T18:37:33.142+0000] {standard_task_runner.py:84} INFO - Running: ['***', 'tasks', 'run', 'fondue_dag', 'clustering', 'scheduled__2023-05-15T00:00:00+00:00', '--job-id', '38', '--raw', '--subdir', 'DAGS_FOLDER/fondue_dag.py', '--cfg-path', '/tmp/tmpnt81o2s8']
[2023-05-17T18:37:33.145+0000] {standard_task_runner.py:85} INFO - Job 38: Subtask clustering
[2023-05-17T18:37:33.234+0000] {task_command.py:410} INFO - Running <TaskInstance: fondue_dag.clustering scheduled__2023-05-15T00:00:00+00:00 [running]> on host 1545bed90dab
[2023-05-17T18:37:33.413+0000] {taskinstance.py:1570} INFO - Exporting env vars: AIRFLOW_CTX_DAG_EMAIL='Bhuribhat@gmail.com' AIRFLOW_CTX_DAG_OWNER='pras' AIRFLOW_CTX_DAG_ID='fondue_dag' AIRFLOW_CTX_TASK_ID='clustering' AIRFLOW_CTX_EXECUTION_DATE='2023-05-15T00:00:00+00:00' AIRFLOW_CTX_TRY_NUMBER='1' AIRFLOW_CTX_DAG_RUN_ID='scheduled__2023-05-15T00:00:00+00:00'
[2023-05-17T18:37:35.301+0000] {logging_mixin.py:149} WARNING - 2023/05/17 18:37:35 WARNING mlflow.utils.git_utils: Failed to import Git (the Git executable is probably not on your PATH), so Git SHA is not available. Error: Failed to initialize: Bad git executable.
The git executable must be specified in one of the following ways:
    - be included in your $PATH
    - be set via $GIT_PYTHON_GIT_EXECUTABLE
    - explicitly set via git.refresh()

All git commands will error until this is rectified.

This initial warning can be silenced or aggravated in the future by setting the
$GIT_PYTHON_REFRESH environment variable. Use one of the following values:
    - quiet|q|silence|s|none|n|0: for no warning or exception
    - warn|w|warning|1: for a printed warning
    - error|e|raise|r|2: for a raised exception

Example:
    export GIT_PYTHON_REFRESH=quiet
[2023-05-17T18:37:40.208+0000] {python.py:183} INFO - Done. Returned value was: None
[2023-05-17T18:37:40.240+0000] {taskinstance.py:1373} INFO - Marking task as SUCCESS. dag_id=fondue_dag, task_id=clustering, execution_date=20230515T000000, start_date=20230517T183733, end_date=20230517T183740
[2023-05-17T18:37:40.317+0000] {local_task_job_runner.py:232} INFO - Task exited with return code 0
[2023-05-17T18:37:40.398+0000] {taskinstance.py:2674} INFO - 1 downstream tasks scheduled from follow-on schedule check
[2023-05-18T06:41:19.829+0000] {taskinstance.py:1125} INFO - Dependencies all met for dep_context=non-requeueable deps ti=<TaskInstance: fondue_dag.clustering scheduled__2023-05-15T00:00:00+00:00 [queued]>
[2023-05-18T06:41:19.854+0000] {taskinstance.py:1125} INFO - Dependencies all met for dep_context=requeueable deps ti=<TaskInstance: fondue_dag.clustering scheduled__2023-05-15T00:00:00+00:00 [queued]>
[2023-05-18T06:41:19.856+0000] {taskinstance.py:1331} INFO - Starting attempt 1 of 2
[2023-05-18T06:41:19.891+0000] {taskinstance.py:1350} INFO - Executing <Task(PythonOperator): clustering> on 2023-05-15 00:00:00+00:00
[2023-05-18T06:41:19.904+0000] {standard_task_runner.py:57} INFO - Started process 1391 to run task
[2023-05-18T06:41:19.911+0000] {standard_task_runner.py:84} INFO - Running: ['***', 'tasks', 'run', 'fondue_dag', 'clustering', 'scheduled__2023-05-15T00:00:00+00:00', '--job-id', '42', '--raw', '--subdir', 'DAGS_FOLDER/fondue_dag.py', '--cfg-path', '/tmp/tmpzw9nquhg']
[2023-05-18T06:41:19.915+0000] {standard_task_runner.py:85} INFO - Job 42: Subtask clustering
[2023-05-18T06:41:20.025+0000] {task_command.py:410} INFO - Running <TaskInstance: fondue_dag.clustering scheduled__2023-05-15T00:00:00+00:00 [running]> on host 714a0c7ad307
[2023-05-18T06:41:20.301+0000] {taskinstance.py:1570} INFO - Exporting env vars: AIRFLOW_CTX_DAG_EMAIL='Bhuribhat@gmail.com' AIRFLOW_CTX_DAG_OWNER='pras' AIRFLOW_CTX_DAG_ID='fondue_dag' AIRFLOW_CTX_TASK_ID='clustering' AIRFLOW_CTX_EXECUTION_DATE='2023-05-15T00:00:00+00:00' AIRFLOW_CTX_TRY_NUMBER='1' AIRFLOW_CTX_DAG_RUN_ID='scheduled__2023-05-15T00:00:00+00:00'
[2023-05-18T06:41:46.449+0000] {logging_mixin.py:149} WARNING - 2023/05/18 06:41:46 WARNING mlflow.utils.git_utils: Failed to import Git (the Git executable is probably not on your PATH), so Git SHA is not available. Error: Failed to initialize: Bad git executable.
The git executable must be specified in one of the following ways:
    - be included in your $PATH
    - be set via $GIT_PYTHON_GIT_EXECUTABLE
    - explicitly set via git.refresh()

All git commands will error until this is rectified.

This initial warning can be silenced or aggravated in the future by setting the
$GIT_PYTHON_REFRESH environment variable. Use one of the following values:
    - quiet|q|silence|s|none|n|0: for no warning or exception
    - warn|w|warning|1: for a printed warning
    - error|e|raise|r|2: for a raised exception

Example:
    export GIT_PYTHON_REFRESH=quiet
[2023-05-18T06:41:46.577+0000] {taskinstance.py:1847} ERROR - Task failed with exception
Traceback (most recent call last):
  File "/home/airflow/.local/lib/python3.7/site-packages/airflow/operators/python.py", line 181, in execute
    return_value = self.execute_callable()
  File "/home/airflow/.local/lib/python3.7/site-packages/airflow/operators/python.py", line 198, in execute_callable
    return self.python_callable(*self.op_args, **self.op_kwargs)
  File "/opt/airflow/dags/utils/clustering.py", line 46, in kmean_cluster
    with mlflow.start_run() as run:
  File "/home/airflow/.local/lib/python3.7/site-packages/mlflow/tracking/fluent.py", line 277, in start_run
    ).format(_active_run_stack[0].info.run_id)
Exception: Run with UUID a14f7e3e9d7f4ddab199e007275bb906 is already active. To start a new run, first end the current run with mlflow.end_run(). To start a nested run, call start_run with nested=True
[2023-05-18T06:41:46.599+0000] {taskinstance.py:1373} INFO - Marking task as UP_FOR_RETRY. dag_id=fondue_dag, task_id=clustering, execution_date=20230515T000000, start_date=20230518T064119, end_date=20230518T064146
[2023-05-18T06:41:46.634+0000] {configuration.py:675} WARNING - section/key [smtp/smtp_user] not found in config
[2023-05-18T06:41:46.635+0000] {email.py:268} INFO - Email alerting: attempt 1
[2023-05-18T06:41:46.647+0000] {configuration.py:675} WARNING - section/key [smtp/smtp_user] not found in config
[2023-05-18T06:41:46.648+0000] {email.py:268} INFO - Email alerting: attempt 1
[2023-05-18T06:41:46.650+0000] {taskinstance.py:1912} ERROR - Failed to send email to: ['Bhuribhat@gmail.com']
Traceback (most recent call last):
  File "/home/airflow/.local/lib/python3.7/site-packages/airflow/models/taskinstance.py", line 1430, in _run_raw_task
    self._execute_task_with_callbacks(context, test_mode)
  File "/home/airflow/.local/lib/python3.7/site-packages/airflow/models/taskinstance.py", line 1581, in _execute_task_with_callbacks
    result = self._execute_task(context, task_orig)
  File "/home/airflow/.local/lib/python3.7/site-packages/airflow/models/taskinstance.py", line 1651, in _execute_task
    result = execute_callable(context=context)
  File "/home/airflow/.local/lib/python3.7/site-packages/airflow/operators/python.py", line 181, in execute
    return_value = self.execute_callable()
  File "/home/airflow/.local/lib/python3.7/site-packages/airflow/operators/python.py", line 198, in execute_callable
    return self.python_callable(*self.op_args, **self.op_kwargs)
  File "/opt/airflow/dags/utils/clustering.py", line 46, in kmean_cluster
    with mlflow.start_run() as run:
  File "/home/airflow/.local/lib/python3.7/site-packages/mlflow/tracking/fluent.py", line 277, in start_run
    ).format(_active_run_stack[0].info.run_id)
Exception: Run with UUID a14f7e3e9d7f4ddab199e007275bb906 is already active. To start a new run, first end the current run with mlflow.end_run(). To start a nested run, call start_run with nested=True

During handling of the above exception, another exception occurred:

Traceback (most recent call last):
  File "/home/airflow/.local/lib/python3.7/site-packages/airflow/models/taskinstance.py", line 2318, in email_alert
    send_email(task.email, subject, html_content)
  File "/home/airflow/.local/lib/python3.7/site-packages/airflow/utils/email.py", line 91, in send_email
    **kwargs,
  File "/home/airflow/.local/lib/python3.7/site-packages/airflow/utils/email.py", line 152, in send_email_smtp
    send_mime_email(e_from=mail_from, e_to=recipients, mime_msg=msg, conn_id=conn_id, dryrun=dryrun)
  File "/home/airflow/.local/lib/python3.7/site-packages/airflow/utils/email.py", line 270, in send_mime_email
    smtp_conn = _get_smtp_connection(smtp_host, smtp_port, smtp_timeout, smtp_ssl)
  File "/home/airflow/.local/lib/python3.7/site-packages/airflow/utils/email.py", line 317, in _get_smtp_connection
    else smtplib.SMTP(host=host, port=port, timeout=timeout)
  File "/usr/local/lib/python3.7/smtplib.py", line 251, in __init__
    (code, msg) = self.connect(host, port)
  File "/usr/local/lib/python3.7/smtplib.py", line 336, in connect
    self.sock = self._get_socket(host, port, self.timeout)
  File "/usr/local/lib/python3.7/smtplib.py", line 307, in _get_socket
    self.source_address)
  File "/usr/local/lib/python3.7/socket.py", line 728, in create_connection
    raise err
  File "/usr/local/lib/python3.7/socket.py", line 716, in create_connection
    sock.connect(sa)
OSError: [Errno 99] Cannot assign requested address

During handling of the above exception, another exception occurred:

Traceback (most recent call last):
  File "/home/airflow/.local/lib/python3.7/site-packages/airflow/models/taskinstance.py", line 1910, in handle_failure
    self.email_alert(error, task)
  File "/home/airflow/.local/lib/python3.7/site-packages/airflow/models/taskinstance.py", line 2320, in email_alert
    send_email(task.email, subject, html_content_err)
  File "/home/airflow/.local/lib/python3.7/site-packages/airflow/utils/email.py", line 91, in send_email
    **kwargs,
  File "/home/airflow/.local/lib/python3.7/site-packages/airflow/utils/email.py", line 152, in send_email_smtp
    send_mime_email(e_from=mail_from, e_to=recipients, mime_msg=msg, conn_id=conn_id, dryrun=dryrun)
  File "/home/airflow/.local/lib/python3.7/site-packages/airflow/utils/email.py", line 270, in send_mime_email
    smtp_conn = _get_smtp_connection(smtp_host, smtp_port, smtp_timeout, smtp_ssl)
  File "/home/airflow/.local/lib/python3.7/site-packages/airflow/utils/email.py", line 317, in _get_smtp_connection
    else smtplib.SMTP(host=host, port=port, timeout=timeout)
  File "/usr/local/lib/python3.7/smtplib.py", line 251, in __init__
    (code, msg) = self.connect(host, port)
  File "/usr/local/lib/python3.7/smtplib.py", line 336, in connect
    self.sock = self._get_socket(host, port, self.timeout)
  File "/usr/local/lib/python3.7/smtplib.py", line 307, in _get_socket
    self.source_address)
  File "/usr/local/lib/python3.7/socket.py", line 728, in create_connection
    raise err
  File "/usr/local/lib/python3.7/socket.py", line 716, in create_connection
    sock.connect(sa)
OSError: [Errno 99] Cannot assign requested address
[2023-05-18T06:41:46.677+0000] {standard_task_runner.py:109} ERROR - Failed to execute job 42 for task clustering (Run with UUID a14f7e3e9d7f4ddab199e007275bb906 is already active. To start a new run, first end the current run with mlflow.end_run(). To start a nested run, call start_run with nested=True; 1391)
[2023-05-18T06:41:46.713+0000] {local_task_job_runner.py:232} INFO - Task exited with return code 1
[2023-05-18T06:41:46.747+0000] {taskinstance.py:2674} INFO - 0 downstream tasks scheduled from follow-on schedule check
[2023-05-18T06:53:30.023+0000] {taskinstance.py:1125} INFO - Dependencies all met for dep_context=non-requeueable deps ti=<TaskInstance: fondue_dag.clustering scheduled__2023-05-15T00:00:00+00:00 [queued]>
[2023-05-18T06:53:30.059+0000] {taskinstance.py:1125} INFO - Dependencies all met for dep_context=requeueable deps ti=<TaskInstance: fondue_dag.clustering scheduled__2023-05-15T00:00:00+00:00 [queued]>
[2023-05-18T06:53:30.062+0000] {taskinstance.py:1331} INFO - Starting attempt 1 of 2
[2023-05-18T06:53:30.159+0000] {taskinstance.py:1350} INFO - Executing <Task(PythonOperator): clustering> on 2023-05-15 00:00:00+00:00
[2023-05-18T06:53:30.170+0000] {standard_task_runner.py:57} INFO - Started process 1535 to run task
[2023-05-18T06:53:30.175+0000] {standard_task_runner.py:84} INFO - Running: ['***', 'tasks', 'run', 'fondue_dag', 'clustering', 'scheduled__2023-05-15T00:00:00+00:00', '--job-id', '38', '--raw', '--subdir', 'DAGS_FOLDER/fondue_dag.py', '--cfg-path', '/tmp/tmpsg03i856']
[2023-05-18T06:53:30.186+0000] {standard_task_runner.py:85} INFO - Job 38: Subtask clustering
[2023-05-18T06:53:30.312+0000] {task_command.py:410} INFO - Running <TaskInstance: fondue_dag.clustering scheduled__2023-05-15T00:00:00+00:00 [running]> on host 26547302378e
[2023-05-18T06:53:30.537+0000] {taskinstance.py:1570} INFO - Exporting env vars: AIRFLOW_CTX_DAG_EMAIL='Bhuribhat@gmail.com' AIRFLOW_CTX_DAG_OWNER='pras' AIRFLOW_CTX_DAG_ID='fondue_dag' AIRFLOW_CTX_TASK_ID='clustering' AIRFLOW_CTX_EXECUTION_DATE='2023-05-15T00:00:00+00:00' AIRFLOW_CTX_TRY_NUMBER='1' AIRFLOW_CTX_DAG_RUN_ID='scheduled__2023-05-15T00:00:00+00:00'
[2023-05-18T06:53:51.877+0000] {logging_mixin.py:149} WARNING - 2023/05/18 06:53:51 WARNING mlflow.utils.git_utils: Failed to import Git (the Git executable is probably not on your PATH), so Git SHA is not available. Error: Failed to initialize: Bad git executable.
The git executable must be specified in one of the following ways:
    - be included in your $PATH
    - be set via $GIT_PYTHON_GIT_EXECUTABLE
    - explicitly set via git.refresh()

All git commands will error until this is rectified.

This initial warning can be silenced or aggravated in the future by setting the
$GIT_PYTHON_REFRESH environment variable. Use one of the following values:
    - quiet|q|silence|s|none|n|0: for no warning or exception
    - warn|w|warning|1: for a printed warning
    - error|e|raise|r|2: for a raised exception

Example:
    export GIT_PYTHON_REFRESH=quiet
[2023-05-18T06:54:00.461+0000] {python.py:183} INFO - Done. Returned value was: None
[2023-05-18T06:54:00.478+0000] {taskinstance.py:1373} INFO - Marking task as SUCCESS. dag_id=fondue_dag, task_id=clustering, execution_date=20230515T000000, start_date=20230518T065330, end_date=20230518T065400
[2023-05-18T06:54:00.533+0000] {local_task_job_runner.py:232} INFO - Task exited with return code 0
[2023-05-18T06:54:00.568+0000] {taskinstance.py:2674} INFO - 1 downstream tasks scheduled from follow-on schedule check
=======
[2023-05-18T04:23:16.580+0000] {python.py:183} INFO - Done. Returned value was: None
[2023-05-18T04:23:16.614+0000] {taskinstance.py:1373} INFO - Marking task as SUCCESS. dag_id=fondue_dag, task_id=clustering, execution_date=20230515T000000, start_date=20230518T042222, end_date=20230518T042316
[2023-05-18T04:23:16.686+0000] {local_task_job_runner.py:232} INFO - Task exited with return code 0
[2023-05-18T04:23:16.716+0000] {taskinstance.py:2674} INFO - 1 downstream tasks scheduled from follow-on schedule check
<<<<<<< HEAD
[2023-05-18T07:19:54.685+0000] {logging_mixin.py:149} INFO - Changing /opt/***/logs/dag_id=fondue_dag/run_id=scheduled__2023-05-15T00:00:00+00:00/task_id=clustering permission to 509
[2023-05-18T07:19:54.687+0000] {logging_mixin.py:149} INFO - Failed to change /opt/***/logs/dag_id=fondue_dag/run_id=scheduled__2023-05-15T00:00:00+00:00/task_id=clustering permission to 509: [Errno 1] Operation not permitted: '/opt/***/logs/dag_id=fondue_dag/run_id=scheduled__2023-05-15T00:00:00+00:00/task_id=clustering'
[2023-05-18T07:19:54.748+0000] {logging_mixin.py:149} INFO - Changing /opt/***/logs/dag_id=fondue_dag/run_id=scheduled__2023-05-15T00:00:00+00:00/task_id=clustering permission to 509
[2023-05-18T07:19:54.751+0000] {logging_mixin.py:149} INFO - Failed to change /opt/***/logs/dag_id=fondue_dag/run_id=scheduled__2023-05-15T00:00:00+00:00/task_id=clustering permission to 509: [Errno 1] Operation not permitted: '/opt/***/logs/dag_id=fondue_dag/run_id=scheduled__2023-05-15T00:00:00+00:00/task_id=clustering'
[2023-05-18T07:19:54.804+0000] {taskinstance.py:1125} INFO - Dependencies all met for dep_context=non-requeueable deps ti=<TaskInstance: fondue_dag.clustering scheduled__2023-05-15T00:00:00+00:00 [queued]>
[2023-05-18T07:19:54.854+0000] {taskinstance.py:1125} INFO - Dependencies all met for dep_context=requeueable deps ti=<TaskInstance: fondue_dag.clustering scheduled__2023-05-15T00:00:00+00:00 [queued]>
[2023-05-18T07:19:54.861+0000] {taskinstance.py:1331} INFO - Starting attempt 1 of 2
[2023-05-18T07:19:54.920+0000] {taskinstance.py:1350} INFO - Executing <Task(PythonOperator): clustering> on 2023-05-15 00:00:00+00:00
[2023-05-18T07:19:54.938+0000] {standard_task_runner.py:57} INFO - Started process 620 to run task
[2023-05-18T07:19:54.956+0000] {standard_task_runner.py:84} INFO - Running: ['***', 'tasks', 'run', 'fondue_dag', 'clustering', 'scheduled__2023-05-15T00:00:00+00:00', '--job-id', '33', '--raw', '--subdir', 'DAGS_FOLDER/fondue_dag.py', '--cfg-path', '/tmp/tmpmwuk7b1g']
[2023-05-18T07:19:54.967+0000] {standard_task_runner.py:85} INFO - Job 33: Subtask clustering
[2023-05-18T07:19:55.090+0000] {logging_mixin.py:149} INFO - Changing /opt/***/logs/dag_id=fondue_dag/run_id=scheduled__2023-05-15T00:00:00+00:00/task_id=clustering permission to 509
[2023-05-18T07:19:55.091+0000] {logging_mixin.py:149} INFO - Failed to change /opt/***/logs/dag_id=fondue_dag/run_id=scheduled__2023-05-15T00:00:00+00:00/task_id=clustering permission to 509: [Errno 1] Operation not permitted: '/opt/***/logs/dag_id=fondue_dag/run_id=scheduled__2023-05-15T00:00:00+00:00/task_id=clustering'
[2023-05-18T07:19:55.096+0000] {task_command.py:410} INFO - Running <TaskInstance: fondue_dag.clustering scheduled__2023-05-15T00:00:00+00:00 [running]> on host e6cb8527e075
[2023-05-18T07:19:55.247+0000] {taskinstance.py:1570} INFO - Exporting env vars: AIRFLOW_CTX_DAG_EMAIL='Bhuribhat@gmail.com' AIRFLOW_CTX_DAG_OWNER='pras' AIRFLOW_CTX_DAG_ID='fondue_dag' AIRFLOW_CTX_TASK_ID='clustering' AIRFLOW_CTX_EXECUTION_DATE='2023-05-15T00:00:00+00:00' AIRFLOW_CTX_TRY_NUMBER='1' AIRFLOW_CTX_DAG_RUN_ID='scheduled__2023-05-15T00:00:00+00:00'
[2023-05-18T07:20:34.359+0000] {logging_mixin.py:149} WARNING - 2023/05/18 07:20:34 INFO mlflow.tracking.fluent: Experiment with name 'fondue' does not exist. Creating a new experiment.
[2023-05-18T07:20:34.845+0000] {logging_mixin.py:149} WARNING - 2023/05/18 07:20:34 WARNING mlflow.utils.git_utils: Failed to import Git (the Git executable is probably not on your PATH), so Git SHA is not available. Error: Failed to initialize: Bad git executable.
The git executable must be specified in one of the following ways:
    - be included in your $PATH
    - be set via $GIT_PYTHON_GIT_EXECUTABLE
    - explicitly set via git.refresh()

All git commands will error until this is rectified.

This initial warning can be silenced or aggravated in the future by setting the
$GIT_PYTHON_REFRESH environment variable. Use one of the following values:
    - quiet|q|silence|s|none|n|0: for no warning or exception
    - warn|w|warning|1: for a printed warning
    - error|e|raise|r|2: for a raised exception

Example:
    export GIT_PYTHON_REFRESH=quiet
[2023-05-18T07:20:45.115+0000] {python.py:183} INFO - Done. Returned value was: None
[2023-05-18T07:20:45.153+0000] {taskinstance.py:1373} INFO - Marking task as SUCCESS. dag_id=fondue_dag, task_id=clustering, execution_date=20230515T000000, start_date=20230518T071954, end_date=20230518T072045
[2023-05-18T07:20:45.286+0000] {local_task_job_runner.py:232} INFO - Task exited with return code 0
[2023-05-18T07:20:45.371+0000] {taskinstance.py:2674} INFO - 1 downstream tasks scheduled from follow-on schedule check
||||||| a5ba152
=======
>>>>>>> 8e4a41b368593e9ce283ae02afd6c27252f67370
>>>>>>> 91ffc1dfc3438700c5ce09776d21b07a1cb19181
