[2023-05-18T08:04:04.702+0000] {taskinstance.py:1125} INFO - Dependencies all met for dep_context=non-requeueable deps ti=<TaskInstance: fondue_dag.clustering manual__2023-05-18T08:03:40.873378+00:00 [queued]>
[2023-05-18T08:04:04.719+0000] {taskinstance.py:1125} INFO - Dependencies all met for dep_context=requeueable deps ti=<TaskInstance: fondue_dag.clustering manual__2023-05-18T08:03:40.873378+00:00 [queued]>
[2023-05-18T08:04:04.720+0000] {taskinstance.py:1331} INFO - Starting attempt 1 of 2
[2023-05-18T08:04:04.740+0000] {taskinstance.py:1350} INFO - Executing <Task(PythonOperator): clustering> on 2023-05-18 08:03:40.873378+00:00
[2023-05-18T08:04:04.747+0000] {standard_task_runner.py:57} INFO - Started process 4872 to run task
[2023-05-18T08:04:04.749+0000] {standard_task_runner.py:84} INFO - Running: ['***', 'tasks', 'run', 'fondue_dag', 'clustering', 'manual__2023-05-18T08:03:40.873378+00:00', '--job-id', '56', '--raw', '--subdir', 'DAGS_FOLDER/fondue_dag.py', '--cfg-path', '/tmp/tmplnm1tsjd']
[2023-05-18T08:04:04.751+0000] {standard_task_runner.py:85} INFO - Job 56: Subtask clustering
[2023-05-18T08:04:04.801+0000] {task_command.py:410} INFO - Running <TaskInstance: fondue_dag.clustering manual__2023-05-18T08:03:40.873378+00:00 [running]> on host 4fe746fadf66
[2023-05-18T08:04:04.908+0000] {taskinstance.py:1570} INFO - Exporting env vars: AIRFLOW_CTX_DAG_EMAIL='Bhuribhat@gmail.com' AIRFLOW_CTX_DAG_OWNER='pras' AIRFLOW_CTX_DAG_ID='fondue_dag' AIRFLOW_CTX_TASK_ID='clustering' AIRFLOW_CTX_EXECUTION_DATE='2023-05-18T08:03:40.873378+00:00' AIRFLOW_CTX_TRY_NUMBER='1' AIRFLOW_CTX_DAG_RUN_ID='manual__2023-05-18T08:03:40.873378+00:00'
[2023-05-18T08:04:04.997+0000] {file_store.py:280} WARNING - Malformed experiment 'models'. Detailed error Yaml file '/opt/***/mlruns/models/meta.yaml' does not exist.
Traceback (most recent call last):
  File "/home/airflow/.local/lib/python3.7/site-packages/mlflow/store/tracking/file_store.py", line 271, in list_experiments
    experiment = self._get_experiment(exp_id, view_type)
  File "/home/airflow/.local/lib/python3.7/site-packages/mlflow/store/tracking/file_store.py", line 405, in _get_experiment
    meta = FileStore._read_yaml(experiment_dir, FileStore.META_DATA_FILE_NAME)
  File "/home/airflow/.local/lib/python3.7/site-packages/mlflow/store/tracking/file_store.py", line 1109, in _read_yaml
    return _read_helper(root, file_name, attempts_remaining=retries)
  File "/home/airflow/.local/lib/python3.7/site-packages/mlflow/store/tracking/file_store.py", line 1102, in _read_helper
    result = read_yaml(root, file_name)
  File "/home/airflow/.local/lib/python3.7/site-packages/mlflow/utils/file_utils.py", line 183, in read_yaml
    raise MissingConfigException("Yaml file '%s' does not exist." % file_path)
mlflow.exceptions.MissingConfigException: Yaml file '/opt/***/mlruns/models/meta.yaml' does not exist.
[2023-05-18T08:04:05.051+0000] {file_store.py:280} WARNING - Malformed experiment 'models'. Detailed error Yaml file '/opt/***/mlruns/models/meta.yaml' does not exist.
Traceback (most recent call last):
  File "/home/airflow/.local/lib/python3.7/site-packages/mlflow/store/tracking/file_store.py", line 271, in list_experiments
    experiment = self._get_experiment(exp_id, view_type)
  File "/home/airflow/.local/lib/python3.7/site-packages/mlflow/store/tracking/file_store.py", line 405, in _get_experiment
    meta = FileStore._read_yaml(experiment_dir, FileStore.META_DATA_FILE_NAME)
  File "/home/airflow/.local/lib/python3.7/site-packages/mlflow/store/tracking/file_store.py", line 1109, in _read_yaml
    return _read_helper(root, file_name, attempts_remaining=retries)
  File "/home/airflow/.local/lib/python3.7/site-packages/mlflow/store/tracking/file_store.py", line 1102, in _read_helper
    result = read_yaml(root, file_name)
  File "/home/airflow/.local/lib/python3.7/site-packages/mlflow/utils/file_utils.py", line 183, in read_yaml
    raise MissingConfigException("Yaml file '%s' does not exist." % file_path)
mlflow.exceptions.MissingConfigException: Yaml file '/opt/***/mlruns/models/meta.yaml' does not exist.
[2023-05-18T08:04:05.142+0000] {logging_mixin.py:149} WARNING - 2023/05/18 08:04:05 WARNING mlflow.utils.git_utils: Failed to import Git (the Git executable is probably not on your PATH), so Git SHA is not available. Error: Failed to initialize: Bad git executable.
The git executable must be specified in one of the following ways:
    - be included in your $PATH
    - be set via $GIT_PYTHON_GIT_EXECUTABLE
    - explicitly set via git.refresh()

All git commands will error until this is rectified.

This initial warning can be silenced or aggravated in the future by setting the
$GIT_PYTHON_REFRESH environment variable. Use one of the following values:
    - quiet|q|silence|s|none|n|0: for no warning or exception
    - warn|w|warning|1: for a printed warning
    - error|e|raise|r|2: for a raised exception

Example:
    export GIT_PYTHON_REFRESH=quiet
[2023-05-18T08:05:49.053+0000] {python.py:183} INFO - Done. Returned value was: None
[2023-05-18T08:05:49.064+0000] {taskinstance.py:1373} INFO - Marking task as SUCCESS. dag_id=fondue_dag, task_id=clustering, execution_date=20230518T080340, start_date=20230518T080404, end_date=20230518T080549
[2023-05-18T08:05:49.109+0000] {local_task_job_runner.py:232} INFO - Task exited with return code 0
[2023-05-18T08:05:49.131+0000] {taskinstance.py:2674} INFO - 1 downstream tasks scheduled from follow-on schedule check
