[2023-05-18T06:47:54.610+0000] {taskinstance.py:1125} INFO - Dependencies all met for dep_context=non-requeueable deps ti=<TaskInstance: fondue_dag.open_mlflow_ui scheduled__2023-05-14T00:00:00+00:00 [queued]>
[2023-05-18T06:47:54.627+0000] {taskinstance.py:1125} INFO - Dependencies all met for dep_context=requeueable deps ti=<TaskInstance: fondue_dag.open_mlflow_ui scheduled__2023-05-14T00:00:00+00:00 [queued]>
[2023-05-18T06:47:54.628+0000] {taskinstance.py:1331} INFO - Starting attempt 1 of 2
[2023-05-18T06:47:54.655+0000] {taskinstance.py:1350} INFO - Executing <Task(BashOperator): open_mlflow_ui> on 2023-05-14 00:00:00+00:00
[2023-05-18T06:47:54.665+0000] {standard_task_runner.py:57} INFO - Started process 5091 to run task
[2023-05-18T06:47:54.669+0000] {standard_task_runner.py:84} INFO - Running: ['***', 'tasks', 'run', 'fondue_dag', 'open_mlflow_ui', 'scheduled__2023-05-14T00:00:00+00:00', '--job-id', '71', '--raw', '--subdir', 'DAGS_FOLDER/fondue_dag.py', '--cfg-path', '/tmp/tmpku0o1wvw']
[2023-05-18T06:47:54.671+0000] {standard_task_runner.py:85} INFO - Job 71: Subtask open_mlflow_ui
[2023-05-18T06:47:54.736+0000] {task_command.py:410} INFO - Running <TaskInstance: fondue_dag.open_mlflow_ui scheduled__2023-05-14T00:00:00+00:00 [running]> on host 714a0c7ad307
[2023-05-18T06:47:54.893+0000] {taskinstance.py:1570} INFO - Exporting env vars: AIRFLOW_CTX_DAG_EMAIL='Bhuribhat@gmail.com' AIRFLOW_CTX_DAG_OWNER='pras' AIRFLOW_CTX_DAG_ID='fondue_dag' AIRFLOW_CTX_TASK_ID='open_mlflow_ui' AIRFLOW_CTX_EXECUTION_DATE='2023-05-14T00:00:00+00:00' AIRFLOW_CTX_TRY_NUMBER='1' AIRFLOW_CTX_DAG_RUN_ID='scheduled__2023-05-14T00:00:00+00:00'
[2023-05-18T06:47:54.896+0000] {subprocess.py:63} INFO - Tmp dir root location: 
 /tmp
[2023-05-18T06:47:54.898+0000] {subprocess.py:75} INFO - Running command: ['/bin/bash', '-c', 'mlflow ui --host 0.0.0.0 --port 5000']
[2023-05-18T06:47:54.920+0000] {subprocess.py:86} INFO - Output:
[2023-05-18T06:47:59.179+0000] {subprocess.py:93} INFO - [2023-05-18 06:47:59 +0000] [5213] [INFO] Starting gunicorn 20.1.0
[2023-05-18T06:47:59.180+0000] {subprocess.py:93} INFO - [2023-05-18 06:47:59 +0000] [5213] [ERROR] Connection in use: ('0.0.0.0', 5000)
[2023-05-18T06:47:59.180+0000] {subprocess.py:93} INFO - [2023-05-18 06:47:59 +0000] [5213] [ERROR] Retrying in 1 second.
[2023-05-18T06:48:00.181+0000] {subprocess.py:93} INFO - [2023-05-18 06:48:00 +0000] [5213] [ERROR] Connection in use: ('0.0.0.0', 5000)
[2023-05-18T06:48:00.182+0000] {subprocess.py:93} INFO - [2023-05-18 06:48:00 +0000] [5213] [ERROR] Retrying in 1 second.
[2023-05-18T06:48:01.183+0000] {subprocess.py:93} INFO - [2023-05-18 06:48:01 +0000] [5213] [ERROR] Connection in use: ('0.0.0.0', 5000)
[2023-05-18T06:48:01.184+0000] {subprocess.py:93} INFO - [2023-05-18 06:48:01 +0000] [5213] [ERROR] Retrying in 1 second.
[2023-05-18T06:48:02.185+0000] {subprocess.py:93} INFO - [2023-05-18 06:48:02 +0000] [5213] [ERROR] Connection in use: ('0.0.0.0', 5000)
[2023-05-18T06:48:02.187+0000] {subprocess.py:93} INFO - [2023-05-18 06:48:02 +0000] [5213] [ERROR] Retrying in 1 second.
[2023-05-18T06:48:02.431+0000] {local_task_job_runner.py:122} ERROR - Received SIGTERM. Terminating subprocesses
[2023-05-18T06:48:02.500+0000] {process_utils.py:135} INFO - Sending Signals.SIGTERM to group 5091. PIDs of all processes in the group: [5097, 5213, 5091]
[2023-05-18T06:48:02.528+0000] {process_utils.py:86} INFO - Sending the signal Signals.SIGTERM to group 5091
[2023-05-18T06:48:02.546+0000] {taskinstance.py:1540} ERROR - Received SIGTERM. Terminating subprocesses.
[2023-05-18T06:48:02.563+0000] {subprocess.py:104} INFO - Sending SIGTERM signal to process group
[2023-05-18T06:48:02.662+0000] {taskinstance.py:1847} ERROR - Task failed with exception
Traceback (most recent call last):
  File "/home/airflow/.local/lib/python3.7/site-packages/airflow/operators/bash.py", line 205, in execute
    cwd=self.cwd,
  File "/home/airflow/.local/lib/python3.7/site-packages/airflow/hooks/subprocess.py", line 91, in run_command
    for raw_line in iter(self.sub_process.stdout.readline, b""):
  File "/home/airflow/.local/lib/python3.7/site-packages/airflow/models/taskinstance.py", line 1542, in signal_handler
    raise AirflowException("Task received SIGTERM signal")
airflow.exceptions.AirflowException: Task received SIGTERM signal
[2023-05-18T06:48:02.685+0000] {taskinstance.py:1373} INFO - Marking task as UP_FOR_RETRY. dag_id=fondue_dag, task_id=open_mlflow_ui, execution_date=20230514T000000, start_date=20230518T064754, end_date=20230518T064802
[2023-05-18T06:48:02.804+0000] {configuration.py:675} WARNING - section/key [smtp/smtp_user] not found in config
[2023-05-18T06:48:02.814+0000] {email.py:268} INFO - Email alerting: attempt 1
[2023-05-18T06:48:02.850+0000] {configuration.py:675} WARNING - section/key [smtp/smtp_user] not found in config
[2023-05-18T06:48:02.853+0000] {email.py:268} INFO - Email alerting: attempt 1
[2023-05-18T06:48:02.856+0000] {taskinstance.py:1912} ERROR - Failed to send email to: ['Bhuribhat@gmail.com']
Traceback (most recent call last):
  File "/home/airflow/.local/lib/python3.7/site-packages/airflow/models/taskinstance.py", line 1430, in _run_raw_task
    self._execute_task_with_callbacks(context, test_mode)
  File "/home/airflow/.local/lib/python3.7/site-packages/airflow/models/taskinstance.py", line 1581, in _execute_task_with_callbacks
    result = self._execute_task(context, task_orig)
  File "/home/airflow/.local/lib/python3.7/site-packages/airflow/models/taskinstance.py", line 1651, in _execute_task
    result = execute_callable(context=context)
  File "/home/airflow/.local/lib/python3.7/site-packages/airflow/operators/bash.py", line 205, in execute
    cwd=self.cwd,
  File "/home/airflow/.local/lib/python3.7/site-packages/airflow/hooks/subprocess.py", line 91, in run_command
    for raw_line in iter(self.sub_process.stdout.readline, b""):
  File "/home/airflow/.local/lib/python3.7/site-packages/airflow/models/taskinstance.py", line 1542, in signal_handler
    raise AirflowException("Task received SIGTERM signal")
airflow.exceptions.AirflowException: Task received SIGTERM signal

During handling of the above exception, another exception occurred:

Traceback (most recent call last):
  File "/home/airflow/.local/lib/python3.7/site-packages/airflow/models/taskinstance.py", line 2318, in email_alert
    send_email(task.email, subject, html_content)
  File "/home/airflow/.local/lib/python3.7/site-packages/airflow/utils/email.py", line 91, in send_email
    **kwargs,
  File "/home/airflow/.local/lib/python3.7/site-packages/airflow/utils/email.py", line 152, in send_email_smtp
    send_mime_email(e_from=mail_from, e_to=recipients, mime_msg=msg, conn_id=conn_id, dryrun=dryrun)
  File "/home/airflow/.local/lib/python3.7/site-packages/airflow/utils/email.py", line 270, in send_mime_email
    smtp_conn = _get_smtp_connection(smtp_host, smtp_port, smtp_timeout, smtp_ssl)
  File "/home/airflow/.local/lib/python3.7/site-packages/airflow/utils/email.py", line 317, in _get_smtp_connection
    else smtplib.SMTP(host=host, port=port, timeout=timeout)
  File "/usr/local/lib/python3.7/smtplib.py", line 251, in __init__
    (code, msg) = self.connect(host, port)
  File "/usr/local/lib/python3.7/smtplib.py", line 336, in connect
    self.sock = self._get_socket(host, port, self.timeout)
  File "/usr/local/lib/python3.7/smtplib.py", line 307, in _get_socket
    self.source_address)
  File "/usr/local/lib/python3.7/socket.py", line 728, in create_connection
    raise err
  File "/usr/local/lib/python3.7/socket.py", line 716, in create_connection
    sock.connect(sa)
OSError: [Errno 99] Cannot assign requested address

During handling of the above exception, another exception occurred:

Traceback (most recent call last):
  File "/home/airflow/.local/lib/python3.7/site-packages/airflow/models/taskinstance.py", line 1910, in handle_failure
    self.email_alert(error, task)
  File "/home/airflow/.local/lib/python3.7/site-packages/airflow/models/taskinstance.py", line 2320, in email_alert
    send_email(task.email, subject, html_content_err)
  File "/home/airflow/.local/lib/python3.7/site-packages/airflow/utils/email.py", line 91, in send_email
    **kwargs,
  File "/home/airflow/.local/lib/python3.7/site-packages/airflow/utils/email.py", line 152, in send_email_smtp
    send_mime_email(e_from=mail_from, e_to=recipients, mime_msg=msg, conn_id=conn_id, dryrun=dryrun)
  File "/home/airflow/.local/lib/python3.7/site-packages/airflow/utils/email.py", line 270, in send_mime_email
    smtp_conn = _get_smtp_connection(smtp_host, smtp_port, smtp_timeout, smtp_ssl)
  File "/home/airflow/.local/lib/python3.7/site-packages/airflow/utils/email.py", line 317, in _get_smtp_connection
    else smtplib.SMTP(host=host, port=port, timeout=timeout)
  File "/usr/local/lib/python3.7/smtplib.py", line 251, in __init__
    (code, msg) = self.connect(host, port)
  File "/usr/local/lib/python3.7/smtplib.py", line 336, in connect
    self.sock = self._get_socket(host, port, self.timeout)
  File "/usr/local/lib/python3.7/smtplib.py", line 307, in _get_socket
    self.source_address)
  File "/usr/local/lib/python3.7/socket.py", line 728, in create_connection
    raise err
  File "/usr/local/lib/python3.7/socket.py", line 716, in create_connection
    sock.connect(sa)
OSError: [Errno 99] Cannot assign requested address
[2023-05-18T06:48:02.904+0000] {standard_task_runner.py:109} ERROR - Failed to execute job 71 for task open_mlflow_ui (Task received SIGTERM signal; 5091)
[2023-05-18T06:48:02.934+0000] {process_utils.py:79} INFO - Process psutil.Process(pid=5091, status='terminated', exitcode=1, started='06:47:53') (5091) terminated with exit code 1
[2023-05-18T06:48:03.270+0000] {process_utils.py:79} INFO - Process psutil.Process(pid=5097, status='terminated', started='06:47:54') (5097) terminated with exit code None
[2023-05-18T06:48:04.305+0000] {process_utils.py:79} INFO - Process psutil.Process(pid=5213, status='terminated', started='06:47:57') (5213) terminated with exit code None
[2023-05-18T06:48:04.307+0000] {local_task_job_runner.py:232} INFO - Task exited with return code 143
[2023-05-18T06:48:04.383+0000] {taskinstance.py:2674} INFO - 0 downstream tasks scheduled from follow-on schedule check
