[2023-05-17T16:46:52.628+0000] {taskinstance.py:1125} INFO - Dependencies all met for dep_context=non-requeueable deps ti=<TaskInstance: fondue_dag.visualize_data scheduled__2023-05-10T00:00:00+00:00 [queued]>
[2023-05-17T16:46:52.643+0000] {taskinstance.py:1125} INFO - Dependencies all met for dep_context=requeueable deps ti=<TaskInstance: fondue_dag.visualize_data scheduled__2023-05-10T00:00:00+00:00 [queued]>
[2023-05-17T16:46:52.644+0000] {taskinstance.py:1331} INFO - Starting attempt 1 of 2
[2023-05-17T16:46:52.696+0000] {taskinstance.py:1350} INFO - Executing <Task(PythonOperator): visualize_data> on 2023-05-10 00:00:00+00:00
[2023-05-17T16:46:52.711+0000] {standard_task_runner.py:57} INFO - Started process 2727 to run task
[2023-05-17T16:46:52.717+0000] {standard_task_runner.py:84} INFO - Running: ['***', 'tasks', 'run', 'fondue_dag', 'visualize_data', 'scheduled__2023-05-10T00:00:00+00:00', '--job-id', '45', '--raw', '--subdir', 'DAGS_FOLDER/fondue_dag.py', '--cfg-path', '/tmp/tmpltsavq5j']
[2023-05-17T16:46:52.720+0000] {standard_task_runner.py:85} INFO - Job 45: Subtask visualize_data
[2023-05-17T16:46:52.789+0000] {task_command.py:410} INFO - Running <TaskInstance: fondue_dag.visualize_data scheduled__2023-05-10T00:00:00+00:00 [running]> on host 8cf8fb9e28f7
[2023-05-17T16:46:52.931+0000] {taskinstance.py:1570} INFO - Exporting env vars: AIRFLOW_CTX_DAG_EMAIL='Bhuribhat@gmail.com' AIRFLOW_CTX_DAG_OWNER='pras' AIRFLOW_CTX_DAG_ID='fondue_dag' AIRFLOW_CTX_TASK_ID='visualize_data' AIRFLOW_CTX_EXECUTION_DATE='2023-05-10T00:00:00+00:00' AIRFLOW_CTX_TRY_NUMBER='1' AIRFLOW_CTX_DAG_RUN_ID='scheduled__2023-05-10T00:00:00+00:00'
[2023-05-17T16:46:53.283+0000] {font_manager.py:1352} WARNING - findfont: Font family ['TH Sarabun Chula'] not found. Falling back to DejaVu Sans.
[2023-05-17T16:46:53.302+0000] {font_manager.py:1352} WARNING - findfont: Font family ['TH Sarabun Chula'] not found. Falling back to DejaVu Sans.
[2023-05-17T16:46:54.402+0000] {taskinstance.py:1847} ERROR - Task failed with exception
Traceback (most recent call last):
  File "/home/airflow/.local/lib/python3.7/site-packages/pandas/core/indexes/base.py", line 3361, in get_loc
    return self._engine.get_loc(casted_key)
  File "pandas/_libs/index.pyx", line 76, in pandas._libs.index.IndexEngine.get_loc
  File "pandas/_libs/index.pyx", line 108, in pandas._libs.index.IndexEngine.get_loc
  File "pandas/_libs/hashtable_class_helper.pxi", line 5198, in pandas._libs.hashtable.PyObjectHashTable.get_item
  File "pandas/_libs/hashtable_class_helper.pxi", line 5206, in pandas._libs.hashtable.PyObjectHashTable.get_item
KeyError: 'district'

The above exception was the direct cause of the following exception:

Traceback (most recent call last):
  File "/home/airflow/.local/lib/python3.7/site-packages/airflow/operators/python.py", line 181, in execute
    return_value = self.execute_callable()
  File "/home/airflow/.local/lib/python3.7/site-packages/airflow/operators/python.py", line 198, in execute_callable
    return self.python_callable(*self.op_args, **self.op_kwargs)
  File "/opt/airflow/dags/utils/visualize.py", line 194, in visualize_data
    plot_cluster_by_problems(broke_map)
  File "/opt/airflow/dags/utils/visualize.py", line 129, in plot_cluster_by_problems
    information += f"<br>District: {row['district']}<br>State: {row['state']}<br>Timestamp: {row['timestamp']}"
  File "/home/airflow/.local/lib/python3.7/site-packages/pandas/core/series.py", line 942, in __getitem__
    return self._get_value(key)
  File "/home/airflow/.local/lib/python3.7/site-packages/pandas/core/series.py", line 1051, in _get_value
    loc = self.index.get_loc(label)
  File "/home/airflow/.local/lib/python3.7/site-packages/pandas/core/indexes/base.py", line 3363, in get_loc
    raise KeyError(key) from err
KeyError: 'district'
[2023-05-17T16:46:54.425+0000] {taskinstance.py:1373} INFO - Marking task as UP_FOR_RETRY. dag_id=fondue_dag, task_id=visualize_data, execution_date=20230510T000000, start_date=20230517T164652, end_date=20230517T164654
[2023-05-17T16:46:54.451+0000] {configuration.py:675} WARNING - section/key [smtp/smtp_user] not found in config
[2023-05-17T16:46:54.452+0000] {email.py:268} INFO - Email alerting: attempt 1
[2023-05-17T16:46:54.461+0000] {configuration.py:675} WARNING - section/key [smtp/smtp_user] not found in config
[2023-05-17T16:46:54.462+0000] {email.py:268} INFO - Email alerting: attempt 1
[2023-05-17T16:46:54.463+0000] {taskinstance.py:1912} ERROR - Failed to send email to: ['Bhuribhat@gmail.com']
Traceback (most recent call last):
  File "/home/airflow/.local/lib/python3.7/site-packages/pandas/core/indexes/base.py", line 3361, in get_loc
    return self._engine.get_loc(casted_key)
  File "pandas/_libs/index.pyx", line 76, in pandas._libs.index.IndexEngine.get_loc
  File "pandas/_libs/index.pyx", line 108, in pandas._libs.index.IndexEngine.get_loc
  File "pandas/_libs/hashtable_class_helper.pxi", line 5198, in pandas._libs.hashtable.PyObjectHashTable.get_item
  File "pandas/_libs/hashtable_class_helper.pxi", line 5206, in pandas._libs.hashtable.PyObjectHashTable.get_item
KeyError: 'district'

The above exception was the direct cause of the following exception:

Traceback (most recent call last):
  File "/home/airflow/.local/lib/python3.7/site-packages/airflow/models/taskinstance.py", line 1430, in _run_raw_task
    self._execute_task_with_callbacks(context, test_mode)
  File "/home/airflow/.local/lib/python3.7/site-packages/airflow/models/taskinstance.py", line 1581, in _execute_task_with_callbacks
    result = self._execute_task(context, task_orig)
  File "/home/airflow/.local/lib/python3.7/site-packages/airflow/models/taskinstance.py", line 1651, in _execute_task
    result = execute_callable(context=context)
  File "/home/airflow/.local/lib/python3.7/site-packages/airflow/operators/python.py", line 181, in execute
    return_value = self.execute_callable()
  File "/home/airflow/.local/lib/python3.7/site-packages/airflow/operators/python.py", line 198, in execute_callable
    return self.python_callable(*self.op_args, **self.op_kwargs)
  File "/opt/airflow/dags/utils/visualize.py", line 194, in visualize_data
    plot_cluster_by_problems(broke_map)
  File "/opt/airflow/dags/utils/visualize.py", line 129, in plot_cluster_by_problems
    information += f"<br>District: {row['district']}<br>State: {row['state']}<br>Timestamp: {row['timestamp']}"
  File "/home/airflow/.local/lib/python3.7/site-packages/pandas/core/series.py", line 942, in __getitem__
    return self._get_value(key)
  File "/home/airflow/.local/lib/python3.7/site-packages/pandas/core/series.py", line 1051, in _get_value
    loc = self.index.get_loc(label)
  File "/home/airflow/.local/lib/python3.7/site-packages/pandas/core/indexes/base.py", line 3363, in get_loc
    raise KeyError(key) from err
KeyError: 'district'

During handling of the above exception, another exception occurred:

Traceback (most recent call last):
  File "/home/airflow/.local/lib/python3.7/site-packages/airflow/models/taskinstance.py", line 2318, in email_alert
    send_email(task.email, subject, html_content)
  File "/home/airflow/.local/lib/python3.7/site-packages/airflow/utils/email.py", line 91, in send_email
    **kwargs,
  File "/home/airflow/.local/lib/python3.7/site-packages/airflow/utils/email.py", line 152, in send_email_smtp
    send_mime_email(e_from=mail_from, e_to=recipients, mime_msg=msg, conn_id=conn_id, dryrun=dryrun)
  File "/home/airflow/.local/lib/python3.7/site-packages/airflow/utils/email.py", line 270, in send_mime_email
    smtp_conn = _get_smtp_connection(smtp_host, smtp_port, smtp_timeout, smtp_ssl)
  File "/home/airflow/.local/lib/python3.7/site-packages/airflow/utils/email.py", line 317, in _get_smtp_connection
    else smtplib.SMTP(host=host, port=port, timeout=timeout)
  File "/usr/local/lib/python3.7/smtplib.py", line 251, in __init__
    (code, msg) = self.connect(host, port)
  File "/usr/local/lib/python3.7/smtplib.py", line 336, in connect
    self.sock = self._get_socket(host, port, self.timeout)
  File "/usr/local/lib/python3.7/smtplib.py", line 307, in _get_socket
    self.source_address)
  File "/usr/local/lib/python3.7/socket.py", line 728, in create_connection
    raise err
  File "/usr/local/lib/python3.7/socket.py", line 716, in create_connection
    sock.connect(sa)
OSError: [Errno 99] Cannot assign requested address

During handling of the above exception, another exception occurred:

Traceback (most recent call last):
  File "/home/airflow/.local/lib/python3.7/site-packages/airflow/models/taskinstance.py", line 1910, in handle_failure
    self.email_alert(error, task)
  File "/home/airflow/.local/lib/python3.7/site-packages/airflow/models/taskinstance.py", line 2320, in email_alert
    send_email(task.email, subject, html_content_err)
  File "/home/airflow/.local/lib/python3.7/site-packages/airflow/utils/email.py", line 91, in send_email
    **kwargs,
  File "/home/airflow/.local/lib/python3.7/site-packages/airflow/utils/email.py", line 152, in send_email_smtp
    send_mime_email(e_from=mail_from, e_to=recipients, mime_msg=msg, conn_id=conn_id, dryrun=dryrun)
  File "/home/airflow/.local/lib/python3.7/site-packages/airflow/utils/email.py", line 270, in send_mime_email
    smtp_conn = _get_smtp_connection(smtp_host, smtp_port, smtp_timeout, smtp_ssl)
  File "/home/airflow/.local/lib/python3.7/site-packages/airflow/utils/email.py", line 317, in _get_smtp_connection
    else smtplib.SMTP(host=host, port=port, timeout=timeout)
  File "/usr/local/lib/python3.7/smtplib.py", line 251, in __init__
    (code, msg) = self.connect(host, port)
  File "/usr/local/lib/python3.7/smtplib.py", line 336, in connect
    self.sock = self._get_socket(host, port, self.timeout)
  File "/usr/local/lib/python3.7/smtplib.py", line 307, in _get_socket
    self.source_address)
  File "/usr/local/lib/python3.7/socket.py", line 728, in create_connection
    raise err
  File "/usr/local/lib/python3.7/socket.py", line 716, in create_connection
    sock.connect(sa)
OSError: [Errno 99] Cannot assign requested address
[2023-05-17T16:46:54.488+0000] {standard_task_runner.py:109} ERROR - Failed to execute job 45 for task visualize_data ('district'; 2727)
[2023-05-17T16:46:54.536+0000] {local_task_job_runner.py:232} INFO - Task exited with return code 1
[2023-05-17T16:46:54.555+0000] {taskinstance.py:2674} INFO - 0 downstream tasks scheduled from follow-on schedule check
[2023-05-18T04:23:22.432+0000] {logging_mixin.py:149} INFO - Changing /opt/***/logs/dag_id=fondue_dag/run_id=scheduled__2023-05-10T00:00:00+00:00/task_id=visualize_data permission to 509
[2023-05-18T04:23:22.434+0000] {logging_mixin.py:149} INFO - Failed to change /opt/***/logs/dag_id=fondue_dag/run_id=scheduled__2023-05-10T00:00:00+00:00/task_id=visualize_data permission to 509: [Errno 1] Operation not permitted: '/opt/***/logs/dag_id=fondue_dag/run_id=scheduled__2023-05-10T00:00:00+00:00/task_id=visualize_data'
[2023-05-18T04:23:22.497+0000] {logging_mixin.py:149} INFO - Changing /opt/***/logs/dag_id=fondue_dag/run_id=scheduled__2023-05-10T00:00:00+00:00/task_id=visualize_data permission to 509
[2023-05-18T04:23:22.499+0000] {logging_mixin.py:149} INFO - Failed to change /opt/***/logs/dag_id=fondue_dag/run_id=scheduled__2023-05-10T00:00:00+00:00/task_id=visualize_data permission to 509: [Errno 1] Operation not permitted: '/opt/***/logs/dag_id=fondue_dag/run_id=scheduled__2023-05-10T00:00:00+00:00/task_id=visualize_data'
[2023-05-18T04:23:22.568+0000] {taskinstance.py:1125} INFO - Dependencies all met for dep_context=non-requeueable deps ti=<TaskInstance: fondue_dag.visualize_data scheduled__2023-05-10T00:00:00+00:00 [queued]>
[2023-05-18T04:23:22.603+0000] {taskinstance.py:1125} INFO - Dependencies all met for dep_context=requeueable deps ti=<TaskInstance: fondue_dag.visualize_data scheduled__2023-05-10T00:00:00+00:00 [queued]>
[2023-05-18T04:23:22.612+0000] {taskinstance.py:1331} INFO - Starting attempt 1 of 2
[2023-05-18T04:23:22.647+0000] {taskinstance.py:1350} INFO - Executing <Task(PythonOperator): visualize_data> on 2023-05-10 00:00:00+00:00
[2023-05-18T04:23:22.661+0000] {standard_task_runner.py:57} INFO - Started process 962 to run task
[2023-05-18T04:23:22.667+0000] {standard_task_runner.py:84} INFO - Running: ['***', 'tasks', 'run', 'fondue_dag', 'visualize_data', 'scheduled__2023-05-10T00:00:00+00:00', '--job-id', '41', '--raw', '--subdir', 'DAGS_FOLDER/fondue_dag.py', '--cfg-path', '/tmp/tmp3c6pnusl']
[2023-05-18T04:23:22.672+0000] {standard_task_runner.py:85} INFO - Job 41: Subtask visualize_data
[2023-05-18T04:23:22.798+0000] {logging_mixin.py:149} INFO - Changing /opt/***/logs/dag_id=fondue_dag/run_id=scheduled__2023-05-10T00:00:00+00:00/task_id=visualize_data permission to 509
[2023-05-18T04:23:22.800+0000] {logging_mixin.py:149} INFO - Failed to change /opt/***/logs/dag_id=fondue_dag/run_id=scheduled__2023-05-10T00:00:00+00:00/task_id=visualize_data permission to 509: [Errno 1] Operation not permitted: '/opt/***/logs/dag_id=fondue_dag/run_id=scheduled__2023-05-10T00:00:00+00:00/task_id=visualize_data'
[2023-05-18T04:23:22.816+0000] {task_command.py:410} INFO - Running <TaskInstance: fondue_dag.visualize_data scheduled__2023-05-10T00:00:00+00:00 [running]> on host b36de7cfc389
[2023-05-18T04:23:23.150+0000] {taskinstance.py:1570} INFO - Exporting env vars: AIRFLOW_CTX_DAG_EMAIL='Bhuribhat@gmail.com' AIRFLOW_CTX_DAG_OWNER='pras' AIRFLOW_CTX_DAG_ID='fondue_dag' AIRFLOW_CTX_TASK_ID='visualize_data' AIRFLOW_CTX_EXECUTION_DATE='2023-05-10T00:00:00+00:00' AIRFLOW_CTX_TRY_NUMBER='1' AIRFLOW_CTX_DAG_RUN_ID='scheduled__2023-05-10T00:00:00+00:00'
[2023-05-18T04:23:23.155+0000] {taskinstance.py:1847} ERROR - Task failed with exception
Traceback (most recent call last):
  File "/home/airflow/.local/lib/python3.7/site-packages/airflow/operators/python.py", line 181, in execute
    return_value = self.execute_callable()
  File "/home/airflow/.local/lib/python3.7/site-packages/airflow/operators/python.py", line 198, in execute_callable
    return self.python_callable(*self.op_args, **self.op_kwargs)
  File "/opt/airflow/dags/utils/visualize.py", line 189, in visualize_data
    geospatial_visualize()
  File "/opt/airflow/dags/utils/visualize.py", line 78, in geospatial_visualize
    df = load_files(['data_cleaned_by_length'])[0]
IndexError: list index out of range
[2023-05-18T04:23:23.218+0000] {taskinstance.py:1373} INFO - Marking task as UP_FOR_RETRY. dag_id=fondue_dag, task_id=visualize_data, execution_date=20230510T000000, start_date=20230518T042322, end_date=20230518T042323
[2023-05-18T04:23:23.247+0000] {configuration.py:675} WARNING - section/key [smtp/smtp_user] not found in config
[2023-05-18T04:23:23.249+0000] {email.py:268} INFO - Email alerting: attempt 1
[2023-05-18T04:23:23.265+0000] {configuration.py:675} WARNING - section/key [smtp/smtp_user] not found in config
[2023-05-18T04:23:23.266+0000] {email.py:268} INFO - Email alerting: attempt 1
[2023-05-18T04:23:23.272+0000] {taskinstance.py:1912} ERROR - Failed to send email to: ['Bhuribhat@gmail.com']
Traceback (most recent call last):
  File "/home/airflow/.local/lib/python3.7/site-packages/airflow/models/taskinstance.py", line 1430, in _run_raw_task
    self._execute_task_with_callbacks(context, test_mode)
  File "/home/airflow/.local/lib/python3.7/site-packages/airflow/models/taskinstance.py", line 1581, in _execute_task_with_callbacks
    result = self._execute_task(context, task_orig)
  File "/home/airflow/.local/lib/python3.7/site-packages/airflow/models/taskinstance.py", line 1651, in _execute_task
    result = execute_callable(context=context)
  File "/home/airflow/.local/lib/python3.7/site-packages/airflow/operators/python.py", line 181, in execute
    return_value = self.execute_callable()
  File "/home/airflow/.local/lib/python3.7/site-packages/airflow/operators/python.py", line 198, in execute_callable
    return self.python_callable(*self.op_args, **self.op_kwargs)
  File "/opt/airflow/dags/utils/visualize.py", line 189, in visualize_data
    geospatial_visualize()
  File "/opt/airflow/dags/utils/visualize.py", line 78, in geospatial_visualize
    df = load_files(['data_cleaned_by_length'])[0]
IndexError: list index out of range

During handling of the above exception, another exception occurred:

Traceback (most recent call last):
  File "/home/airflow/.local/lib/python3.7/site-packages/airflow/models/taskinstance.py", line 2318, in email_alert
    send_email(task.email, subject, html_content)
  File "/home/airflow/.local/lib/python3.7/site-packages/airflow/utils/email.py", line 91, in send_email
    **kwargs,
  File "/home/airflow/.local/lib/python3.7/site-packages/airflow/utils/email.py", line 152, in send_email_smtp
    send_mime_email(e_from=mail_from, e_to=recipients, mime_msg=msg, conn_id=conn_id, dryrun=dryrun)
  File "/home/airflow/.local/lib/python3.7/site-packages/airflow/utils/email.py", line 270, in send_mime_email
    smtp_conn = _get_smtp_connection(smtp_host, smtp_port, smtp_timeout, smtp_ssl)
  File "/home/airflow/.local/lib/python3.7/site-packages/airflow/utils/email.py", line 317, in _get_smtp_connection
    else smtplib.SMTP(host=host, port=port, timeout=timeout)
  File "/usr/local/lib/python3.7/smtplib.py", line 251, in __init__
    (code, msg) = self.connect(host, port)
  File "/usr/local/lib/python3.7/smtplib.py", line 336, in connect
    self.sock = self._get_socket(host, port, self.timeout)
  File "/usr/local/lib/python3.7/smtplib.py", line 307, in _get_socket
    self.source_address)
  File "/usr/local/lib/python3.7/socket.py", line 728, in create_connection
    raise err
  File "/usr/local/lib/python3.7/socket.py", line 716, in create_connection
    sock.connect(sa)
OSError: [Errno 99] Cannot assign requested address

During handling of the above exception, another exception occurred:

Traceback (most recent call last):
  File "/home/airflow/.local/lib/python3.7/site-packages/airflow/models/taskinstance.py", line 1910, in handle_failure
    self.email_alert(error, task)
  File "/home/airflow/.local/lib/python3.7/site-packages/airflow/models/taskinstance.py", line 2320, in email_alert
    send_email(task.email, subject, html_content_err)
  File "/home/airflow/.local/lib/python3.7/site-packages/airflow/utils/email.py", line 91, in send_email
    **kwargs,
  File "/home/airflow/.local/lib/python3.7/site-packages/airflow/utils/email.py", line 152, in send_email_smtp
    send_mime_email(e_from=mail_from, e_to=recipients, mime_msg=msg, conn_id=conn_id, dryrun=dryrun)
  File "/home/airflow/.local/lib/python3.7/site-packages/airflow/utils/email.py", line 270, in send_mime_email
    smtp_conn = _get_smtp_connection(smtp_host, smtp_port, smtp_timeout, smtp_ssl)
  File "/home/airflow/.local/lib/python3.7/site-packages/airflow/utils/email.py", line 317, in _get_smtp_connection
    else smtplib.SMTP(host=host, port=port, timeout=timeout)
  File "/usr/local/lib/python3.7/smtplib.py", line 251, in __init__
    (code, msg) = self.connect(host, port)
  File "/usr/local/lib/python3.7/smtplib.py", line 336, in connect
    self.sock = self._get_socket(host, port, self.timeout)
  File "/usr/local/lib/python3.7/smtplib.py", line 307, in _get_socket
    self.source_address)
  File "/usr/local/lib/python3.7/socket.py", line 728, in create_connection
    raise err
  File "/usr/local/lib/python3.7/socket.py", line 716, in create_connection
    sock.connect(sa)
OSError: [Errno 99] Cannot assign requested address
[2023-05-18T04:23:23.328+0000] {standard_task_runner.py:109} ERROR - Failed to execute job 41 for task visualize_data (list index out of range; 962)
[2023-05-18T04:23:23.363+0000] {local_task_job_runner.py:232} INFO - Task exited with return code 1
[2023-05-18T04:23:23.392+0000] {taskinstance.py:2674} INFO - 0 downstream tasks scheduled from follow-on schedule check
[2023-05-18T07:20:55.992+0000] {logging_mixin.py:149} INFO - Changing /opt/***/logs/dag_id=fondue_dag/run_id=scheduled__2023-05-10T00:00:00+00:00/task_id=visualize_data permission to 509
[2023-05-18T07:20:55.994+0000] {logging_mixin.py:149} INFO - Failed to change /opt/***/logs/dag_id=fondue_dag/run_id=scheduled__2023-05-10T00:00:00+00:00/task_id=visualize_data permission to 509: [Errno 1] Operation not permitted: '/opt/***/logs/dag_id=fondue_dag/run_id=scheduled__2023-05-10T00:00:00+00:00/task_id=visualize_data'
[2023-05-18T07:20:56.182+0000] {logging_mixin.py:149} INFO - Changing /opt/***/logs/dag_id=fondue_dag/run_id=scheduled__2023-05-10T00:00:00+00:00/task_id=visualize_data permission to 509
[2023-05-18T07:20:56.193+0000] {logging_mixin.py:149} INFO - Failed to change /opt/***/logs/dag_id=fondue_dag/run_id=scheduled__2023-05-10T00:00:00+00:00/task_id=visualize_data permission to 509: [Errno 1] Operation not permitted: '/opt/***/logs/dag_id=fondue_dag/run_id=scheduled__2023-05-10T00:00:00+00:00/task_id=visualize_data'
[2023-05-18T07:20:56.282+0000] {taskinstance.py:1125} INFO - Dependencies all met for dep_context=non-requeueable deps ti=<TaskInstance: fondue_dag.visualize_data scheduled__2023-05-10T00:00:00+00:00 [queued]>
[2023-05-18T07:20:56.337+0000] {taskinstance.py:1125} INFO - Dependencies all met for dep_context=requeueable deps ti=<TaskInstance: fondue_dag.visualize_data scheduled__2023-05-10T00:00:00+00:00 [queued]>
[2023-05-18T07:20:56.338+0000] {taskinstance.py:1331} INFO - Starting attempt 1 of 2
[2023-05-18T07:20:56.386+0000] {taskinstance.py:1350} INFO - Executing <Task(PythonOperator): visualize_data> on 2023-05-10 00:00:00+00:00
[2023-05-18T07:20:56.410+0000] {standard_task_runner.py:57} INFO - Started process 1091 to run task
[2023-05-18T07:20:56.417+0000] {standard_task_runner.py:84} INFO - Running: ['***', 'tasks', 'run', 'fondue_dag', 'visualize_data', 'scheduled__2023-05-10T00:00:00+00:00', '--job-id', '44', '--raw', '--subdir', 'DAGS_FOLDER/fondue_dag.py', '--cfg-path', '/tmp/tmpdnil0_jx']
[2023-05-18T07:20:56.422+0000] {standard_task_runner.py:85} INFO - Job 44: Subtask visualize_data
[2023-05-18T07:20:56.540+0000] {logging_mixin.py:149} INFO - Changing /opt/***/logs/dag_id=fondue_dag/run_id=scheduled__2023-05-10T00:00:00+00:00/task_id=visualize_data permission to 509
[2023-05-18T07:20:56.542+0000] {logging_mixin.py:149} INFO - Failed to change /opt/***/logs/dag_id=fondue_dag/run_id=scheduled__2023-05-10T00:00:00+00:00/task_id=visualize_data permission to 509: [Errno 1] Operation not permitted: '/opt/***/logs/dag_id=fondue_dag/run_id=scheduled__2023-05-10T00:00:00+00:00/task_id=visualize_data'
[2023-05-18T07:20:56.554+0000] {task_command.py:410} INFO - Running <TaskInstance: fondue_dag.visualize_data scheduled__2023-05-10T00:00:00+00:00 [running]> on host e6cb8527e075
[2023-05-18T07:20:56.796+0000] {taskinstance.py:1570} INFO - Exporting env vars: AIRFLOW_CTX_DAG_EMAIL='Bhuribhat@gmail.com' AIRFLOW_CTX_DAG_OWNER='pras' AIRFLOW_CTX_DAG_ID='fondue_dag' AIRFLOW_CTX_TASK_ID='visualize_data' AIRFLOW_CTX_EXECUTION_DATE='2023-05-10T00:00:00+00:00' AIRFLOW_CTX_TRY_NUMBER='1' AIRFLOW_CTX_DAG_RUN_ID='scheduled__2023-05-10T00:00:00+00:00'
[2023-05-18T07:21:03.755+0000] {font_manager.py:1352} WARNING - findfont: Font family ['TH Sarabun Chula'] not found. Falling back to DejaVu Sans.
[2023-05-18T07:21:03.766+0000] {font_manager.py:1352} WARNING - findfont: Font family ['TH Sarabun Chula'] not found. Falling back to DejaVu Sans.
[2023-05-18T07:21:17.897+0000] {python.py:183} INFO - Done. Returned value was: None
[2023-05-18T07:21:17.912+0000] {taskinstance.py:1373} INFO - Marking task as SUCCESS. dag_id=fondue_dag, task_id=visualize_data, execution_date=20230510T000000, start_date=20230518T072056, end_date=20230518T072117
[2023-05-18T07:21:18.060+0000] {local_task_job_runner.py:232} INFO - Task exited with return code 0
[2023-05-18T07:21:18.211+0000] {taskinstance.py:2674} INFO - 0 downstream tasks scheduled from follow-on schedule check
