[2023-05-17T16:51:58.323+0000] {taskinstance.py:1125} INFO - Dependencies all met for dep_context=non-requeueable deps ti=<TaskInstance: fondue_dag.visualize_data scheduled__2023-05-10T00:00:00+00:00 [queued]>
[2023-05-17T16:51:58.340+0000] {taskinstance.py:1125} INFO - Dependencies all met for dep_context=requeueable deps ti=<TaskInstance: fondue_dag.visualize_data scheduled__2023-05-10T00:00:00+00:00 [queued]>
[2023-05-17T16:51:58.340+0000] {taskinstance.py:1331} INFO - Starting attempt 2 of 2
[2023-05-17T16:51:58.363+0000] {taskinstance.py:1350} INFO - Executing <Task(PythonOperator): visualize_data> on 2023-05-10 00:00:00+00:00
[2023-05-17T16:51:58.372+0000] {standard_task_runner.py:57} INFO - Started process 3500 to run task
[2023-05-17T16:51:58.375+0000] {standard_task_runner.py:84} INFO - Running: ['***', 'tasks', 'run', 'fondue_dag', 'visualize_data', 'scheduled__2023-05-10T00:00:00+00:00', '--job-id', '60', '--raw', '--subdir', 'DAGS_FOLDER/fondue_dag.py', '--cfg-path', '/tmp/tmpfk1xmhrq']
[2023-05-17T16:51:58.378+0000] {standard_task_runner.py:85} INFO - Job 60: Subtask visualize_data
[2023-05-17T16:51:58.440+0000] {task_command.py:410} INFO - Running <TaskInstance: fondue_dag.visualize_data scheduled__2023-05-10T00:00:00+00:00 [running]> on host 8cf8fb9e28f7
[2023-05-17T16:51:58.560+0000] {taskinstance.py:1570} INFO - Exporting env vars: AIRFLOW_CTX_DAG_EMAIL='Bhuribhat@gmail.com' AIRFLOW_CTX_DAG_OWNER='pras' AIRFLOW_CTX_DAG_ID='fondue_dag' AIRFLOW_CTX_TASK_ID='visualize_data' AIRFLOW_CTX_EXECUTION_DATE='2023-05-10T00:00:00+00:00' AIRFLOW_CTX_TRY_NUMBER='2' AIRFLOW_CTX_DAG_RUN_ID='scheduled__2023-05-10T00:00:00+00:00'
[2023-05-17T16:51:58.883+0000] {font_manager.py:1352} WARNING - findfont: Font family ['TH Sarabun Chula'] not found. Falling back to DejaVu Sans.
[2023-05-17T16:51:58.946+0000] {font_manager.py:1352} WARNING - findfont: Font family ['TH Sarabun Chula'] not found. Falling back to DejaVu Sans.
[2023-05-17T16:51:59.878+0000] {taskinstance.py:1847} ERROR - Task failed with exception
Traceback (most recent call last):
  File "/home/airflow/.local/lib/python3.7/site-packages/pandas/core/indexes/base.py", line 3361, in get_loc
    return self._engine.get_loc(casted_key)
  File "pandas/_libs/index.pyx", line 76, in pandas._libs.index.IndexEngine.get_loc
  File "pandas/_libs/index.pyx", line 108, in pandas._libs.index.IndexEngine.get_loc
  File "pandas/_libs/hashtable_class_helper.pxi", line 5198, in pandas._libs.hashtable.PyObjectHashTable.get_item
  File "pandas/_libs/hashtable_class_helper.pxi", line 5206, in pandas._libs.hashtable.PyObjectHashTable.get_item
KeyError: 'district'

The above exception was the direct cause of the following exception:

Traceback (most recent call last):
  File "/home/airflow/.local/lib/python3.7/site-packages/airflow/operators/python.py", line 181, in execute
    return_value = self.execute_callable()
  File "/home/airflow/.local/lib/python3.7/site-packages/airflow/operators/python.py", line 198, in execute_callable
    return self.python_callable(*self.op_args, **self.op_kwargs)
  File "/opt/airflow/dags/utils/visualize.py", line 196, in visualize_data
    plot_cluster_by_problems(broke_map)
  File "/opt/airflow/dags/utils/visualize.py", line 129, in plot_cluster_by_problems
    information += f"<br>District: {row['district']}<br>State: {row['state']}<br>Timestamp: {row['timestamp']}"
  File "/home/airflow/.local/lib/python3.7/site-packages/pandas/core/series.py", line 942, in __getitem__
    return self._get_value(key)
  File "/home/airflow/.local/lib/python3.7/site-packages/pandas/core/series.py", line 1051, in _get_value
    loc = self.index.get_loc(label)
  File "/home/airflow/.local/lib/python3.7/site-packages/pandas/core/indexes/base.py", line 3363, in get_loc
    raise KeyError(key) from err
KeyError: 'district'
[2023-05-17T16:51:59.893+0000] {taskinstance.py:1373} INFO - Marking task as FAILED. dag_id=fondue_dag, task_id=visualize_data, execution_date=20230510T000000, start_date=20230517T165158, end_date=20230517T165159
[2023-05-17T16:51:59.909+0000] {standard_task_runner.py:109} ERROR - Failed to execute job 60 for task visualize_data ('district'; 3500)
[2023-05-17T16:51:59.922+0000] {local_task_job_runner.py:232} INFO - Task exited with return code 1
[2023-05-17T16:51:59.941+0000] {taskinstance.py:2674} INFO - 0 downstream tasks scheduled from follow-on schedule check
