[2023-05-16T07:14:35.983+0000] {taskinstance.py:1125} INFO - Dependencies all met for dep_context=non-requeueable deps ti=<TaskInstance: fondue_dag.clean_fondue_data manual__2023-05-16T07:14:21.687537+00:00 [queued]>
[2023-05-16T07:14:35.994+0000] {taskinstance.py:1125} INFO - Dependencies all met for dep_context=requeueable deps ti=<TaskInstance: fondue_dag.clean_fondue_data manual__2023-05-16T07:14:21.687537+00:00 [queued]>
[2023-05-16T07:14:35.995+0000] {taskinstance.py:1331} INFO - Starting attempt 1 of 2
[2023-05-16T07:14:36.012+0000] {taskinstance.py:1350} INFO - Executing <Task(PythonOperator): clean_fondue_data> on 2023-05-16 07:14:21.687537+00:00
[2023-05-16T07:14:36.018+0000] {standard_task_runner.py:57} INFO - Started process 877 to run task
[2023-05-16T07:14:36.020+0000] {standard_task_runner.py:84} INFO - Running: ['***', 'tasks', 'run', 'fondue_dag', 'clean_fondue_data', 'manual__2023-05-16T07:14:21.687537+00:00', '--job-id', '36', '--raw', '--subdir', 'DAGS_FOLDER/fondue_dag.py', '--cfg-path', '/tmp/tmpdqfq99z1']
[2023-05-16T07:14:36.022+0000] {standard_task_runner.py:85} INFO - Job 36: Subtask clean_fondue_data
[2023-05-16T07:14:36.071+0000] {task_command.py:410} INFO - Running <TaskInstance: fondue_dag.clean_fondue_data manual__2023-05-16T07:14:21.687537+00:00 [running]> on host a76a3b1a3408
[2023-05-16T07:14:36.163+0000] {taskinstance.py:1570} INFO - Exporting env vars: AIRFLOW_CTX_DAG_EMAIL='Bhuribhat@gmail.com' AIRFLOW_CTX_DAG_OWNER='pras' AIRFLOW_CTX_DAG_ID='fondue_dag' AIRFLOW_CTX_TASK_ID='clean_fondue_data' AIRFLOW_CTX_EXECUTION_DATE='2023-05-16T07:14:21.687537+00:00' AIRFLOW_CTX_TRY_NUMBER='1' AIRFLOW_CTX_DAG_RUN_ID='manual__2023-05-16T07:14:21.687537+00:00'
[2023-05-16T07:14:36.204+0000] {taskinstance.py:1847} ERROR - Task failed with exception
Traceback (most recent call last):
  File "/home/airflow/.local/lib/python3.7/site-packages/pandas/core/indexes/base.py", line 3361, in get_loc
    return self._engine.get_loc(casted_key)
  File "pandas/_libs/index.pyx", line 76, in pandas._libs.index.IndexEngine.get_loc
  File "pandas/_libs/index.pyx", line 108, in pandas._libs.index.IndexEngine.get_loc
  File "pandas/_libs/hashtable_class_helper.pxi", line 5198, in pandas._libs.hashtable.PyObjectHashTable.get_item
  File "pandas/_libs/hashtable_class_helper.pxi", line 5206, in pandas._libs.hashtable.PyObjectHashTable.get_item
KeyError: 'address'

The above exception was the direct cause of the following exception:

Traceback (most recent call last):
  File "/home/airflow/.local/lib/python3.7/site-packages/airflow/operators/python.py", line 181, in execute
    return_value = self.execute_callable()
  File "/home/airflow/.local/lib/python3.7/site-packages/airflow/operators/python.py", line 198, in execute_callable
    return self.python_callable(*self.op_args, **self.op_kwargs)
  File "/opt/airflow/dags/utils/clean_data.py", line 25, in clean_data
    df['province'] = df['address'].str.split(' ')[-3]
  File "/home/airflow/.local/lib/python3.7/site-packages/pandas/core/frame.py", line 3458, in __getitem__
    indexer = self.columns.get_loc(key)
  File "/home/airflow/.local/lib/python3.7/site-packages/pandas/core/indexes/base.py", line 3363, in get_loc
    raise KeyError(key) from err
KeyError: 'address'
[2023-05-16T07:14:36.222+0000] {taskinstance.py:1373} INFO - Marking task as UP_FOR_RETRY. dag_id=fondue_dag, task_id=clean_fondue_data, execution_date=20230516T071421, start_date=20230516T071435, end_date=20230516T071436
[2023-05-16T07:14:36.243+0000] {logging_mixin.py:149} WARNING - /home/***/.local/lib/python3.7/site-packages/***/utils/email.py:152 RemovedInAirflow3Warning: Fetching SMTP credentials from configuration variables will be deprecated in a future release. Please set credentials using a connection instead.
[2023-05-16T07:14:36.244+0000] {configuration.py:675} WARNING - section/key [smtp/smtp_user] not found in config
[2023-05-16T07:14:36.245+0000] {email.py:268} INFO - Email alerting: attempt 1
[2023-05-16T07:14:36.251+0000] {configuration.py:675} WARNING - section/key [smtp/smtp_user] not found in config
[2023-05-16T07:14:36.252+0000] {email.py:268} INFO - Email alerting: attempt 1
[2023-05-16T07:14:36.253+0000] {taskinstance.py:1912} ERROR - Failed to send email to: ['Bhuribhat@gmail.com']
Traceback (most recent call last):
  File "/home/airflow/.local/lib/python3.7/site-packages/pandas/core/indexes/base.py", line 3361, in get_loc
    return self._engine.get_loc(casted_key)
  File "pandas/_libs/index.pyx", line 76, in pandas._libs.index.IndexEngine.get_loc
  File "pandas/_libs/index.pyx", line 108, in pandas._libs.index.IndexEngine.get_loc
  File "pandas/_libs/hashtable_class_helper.pxi", line 5198, in pandas._libs.hashtable.PyObjectHashTable.get_item
  File "pandas/_libs/hashtable_class_helper.pxi", line 5206, in pandas._libs.hashtable.PyObjectHashTable.get_item
KeyError: 'address'

The above exception was the direct cause of the following exception:

Traceback (most recent call last):
  File "/home/airflow/.local/lib/python3.7/site-packages/airflow/models/taskinstance.py", line 1430, in _run_raw_task
    self._execute_task_with_callbacks(context, test_mode)
  File "/home/airflow/.local/lib/python3.7/site-packages/airflow/models/taskinstance.py", line 1581, in _execute_task_with_callbacks
    result = self._execute_task(context, task_orig)
  File "/home/airflow/.local/lib/python3.7/site-packages/airflow/models/taskinstance.py", line 1651, in _execute_task
    result = execute_callable(context=context)
  File "/home/airflow/.local/lib/python3.7/site-packages/airflow/operators/python.py", line 181, in execute
    return_value = self.execute_callable()
  File "/home/airflow/.local/lib/python3.7/site-packages/airflow/operators/python.py", line 198, in execute_callable
    return self.python_callable(*self.op_args, **self.op_kwargs)
  File "/opt/airflow/dags/utils/clean_data.py", line 25, in clean_data
    df['province'] = df['address'].str.split(' ')[-3]
  File "/home/airflow/.local/lib/python3.7/site-packages/pandas/core/frame.py", line 3458, in __getitem__
    indexer = self.columns.get_loc(key)
  File "/home/airflow/.local/lib/python3.7/site-packages/pandas/core/indexes/base.py", line 3363, in get_loc
    raise KeyError(key) from err
KeyError: 'address'

During handling of the above exception, another exception occurred:

Traceback (most recent call last):
  File "/home/airflow/.local/lib/python3.7/site-packages/airflow/models/taskinstance.py", line 2318, in email_alert
    send_email(task.email, subject, html_content)
  File "/home/airflow/.local/lib/python3.7/site-packages/airflow/utils/email.py", line 91, in send_email
    **kwargs,
  File "/home/airflow/.local/lib/python3.7/site-packages/airflow/utils/email.py", line 152, in send_email_smtp
    send_mime_email(e_from=mail_from, e_to=recipients, mime_msg=msg, conn_id=conn_id, dryrun=dryrun)
  File "/home/airflow/.local/lib/python3.7/site-packages/airflow/utils/email.py", line 270, in send_mime_email
    smtp_conn = _get_smtp_connection(smtp_host, smtp_port, smtp_timeout, smtp_ssl)
  File "/home/airflow/.local/lib/python3.7/site-packages/airflow/utils/email.py", line 317, in _get_smtp_connection
    else smtplib.SMTP(host=host, port=port, timeout=timeout)
  File "/usr/local/lib/python3.7/smtplib.py", line 251, in __init__
    (code, msg) = self.connect(host, port)
  File "/usr/local/lib/python3.7/smtplib.py", line 336, in connect
    self.sock = self._get_socket(host, port, self.timeout)
  File "/usr/local/lib/python3.7/smtplib.py", line 307, in _get_socket
    self.source_address)
  File "/usr/local/lib/python3.7/socket.py", line 728, in create_connection
    raise err
  File "/usr/local/lib/python3.7/socket.py", line 716, in create_connection
    sock.connect(sa)
OSError: [Errno 99] Cannot assign requested address

During handling of the above exception, another exception occurred:

Traceback (most recent call last):
  File "/home/airflow/.local/lib/python3.7/site-packages/airflow/models/taskinstance.py", line 1910, in handle_failure
    self.email_alert(error, task)
  File "/home/airflow/.local/lib/python3.7/site-packages/airflow/models/taskinstance.py", line 2320, in email_alert
    send_email(task.email, subject, html_content_err)
  File "/home/airflow/.local/lib/python3.7/site-packages/airflow/utils/email.py", line 91, in send_email
    **kwargs,
  File "/home/airflow/.local/lib/python3.7/site-packages/airflow/utils/email.py", line 152, in send_email_smtp
    send_mime_email(e_from=mail_from, e_to=recipients, mime_msg=msg, conn_id=conn_id, dryrun=dryrun)
  File "/home/airflow/.local/lib/python3.7/site-packages/airflow/utils/email.py", line 270, in send_mime_email
    smtp_conn = _get_smtp_connection(smtp_host, smtp_port, smtp_timeout, smtp_ssl)
  File "/home/airflow/.local/lib/python3.7/site-packages/airflow/utils/email.py", line 317, in _get_smtp_connection
    else smtplib.SMTP(host=host, port=port, timeout=timeout)
  File "/usr/local/lib/python3.7/smtplib.py", line 251, in __init__
    (code, msg) = self.connect(host, port)
  File "/usr/local/lib/python3.7/smtplib.py", line 336, in connect
    self.sock = self._get_socket(host, port, self.timeout)
  File "/usr/local/lib/python3.7/smtplib.py", line 307, in _get_socket
    self.source_address)
  File "/usr/local/lib/python3.7/socket.py", line 728, in create_connection
    raise err
  File "/usr/local/lib/python3.7/socket.py", line 716, in create_connection
    sock.connect(sa)
OSError: [Errno 99] Cannot assign requested address
[2023-05-16T07:14:36.271+0000] {standard_task_runner.py:109} ERROR - Failed to execute job 36 for task clean_fondue_data ('address'; 877)
[2023-05-16T07:14:36.314+0000] {local_task_job_runner.py:232} INFO - Task exited with return code 1
[2023-05-16T07:14:36.334+0000] {taskinstance.py:2674} INFO - 0 downstream tasks scheduled from follow-on schedule check
