[2023-05-17T16:46:25.835+0000] {taskinstance.py:1125} INFO - Dependencies all met for dep_context=non-requeueable deps ti=<TaskInstance: fondue_dag.clustering scheduled__2023-05-14T00:00:00+00:00 [queued]>
[2023-05-17T16:46:25.857+0000] {taskinstance.py:1125} INFO - Dependencies all met for dep_context=requeueable deps ti=<TaskInstance: fondue_dag.clustering scheduled__2023-05-14T00:00:00+00:00 [queued]>
[2023-05-17T16:46:25.858+0000] {taskinstance.py:1331} INFO - Starting attempt 1 of 2
[2023-05-17T16:46:25.890+0000] {taskinstance.py:1350} INFO - Executing <Task(PythonOperator): clustering> on 2023-05-14 00:00:00+00:00
[2023-05-17T16:46:25.900+0000] {standard_task_runner.py:57} INFO - Started process 1718 to run task
[2023-05-17T16:46:25.904+0000] {standard_task_runner.py:84} INFO - Running: ['***', 'tasks', 'run', 'fondue_dag', 'clustering', 'scheduled__2023-05-14T00:00:00+00:00', '--job-id', '36', '--raw', '--subdir', 'DAGS_FOLDER/fondue_dag.py', '--cfg-path', '/tmp/tmpy2yorl6b']
[2023-05-17T16:46:25.907+0000] {standard_task_runner.py:85} INFO - Job 36: Subtask clustering
[2023-05-17T16:46:25.985+0000] {task_command.py:410} INFO - Running <TaskInstance: fondue_dag.clustering scheduled__2023-05-14T00:00:00+00:00 [running]> on host 8cf8fb9e28f7
[2023-05-17T16:46:26.210+0000] {taskinstance.py:1570} INFO - Exporting env vars: AIRFLOW_CTX_DAG_EMAIL='Bhuribhat@gmail.com' AIRFLOW_CTX_DAG_OWNER='pras' AIRFLOW_CTX_DAG_ID='fondue_dag' AIRFLOW_CTX_TASK_ID='clustering' AIRFLOW_CTX_EXECUTION_DATE='2023-05-14T00:00:00+00:00' AIRFLOW_CTX_TRY_NUMBER='1' AIRFLOW_CTX_DAG_RUN_ID='scheduled__2023-05-14T00:00:00+00:00'
[2023-05-17T16:46:43.882+0000] {logging_mixin.py:149} WARNING - 2023/05/17 16:46:43 WARNING mlflow.utils.git_utils: Failed to import Git (the Git executable is probably not on your PATH), so Git SHA is not available. Error: Failed to initialize: Bad git executable.
The git executable must be specified in one of the following ways:
    - be included in your $PATH
    - be set via $GIT_PYTHON_GIT_EXECUTABLE
    - explicitly set via git.refresh()

All git commands will error until this is rectified.

This initial warning can be silenced or aggravated in the future by setting the
$GIT_PYTHON_REFRESH environment variable. Use one of the following values:
    - quiet|q|silence|s|none|n|0: for no warning or exception
    - warn|w|warning|1: for a printed warning
    - error|e|raise|r|2: for a raised exception

Example:
    export GIT_PYTHON_REFRESH=quiet
[2023-05-17T16:46:48.404+0000] {python.py:183} INFO - Done. Returned value was: None
[2023-05-17T16:46:48.417+0000] {taskinstance.py:1373} INFO - Marking task as SUCCESS. dag_id=fondue_dag, task_id=clustering, execution_date=20230514T000000, start_date=20230517T164625, end_date=20230517T164648
[2023-05-17T16:46:48.462+0000] {local_task_job_runner.py:232} INFO - Task exited with return code 0
[2023-05-17T16:46:48.485+0000] {taskinstance.py:2674} INFO - 1 downstream tasks scheduled from follow-on schedule check
<<<<<<< HEAD
[2023-05-17T17:55:05.752+0000] {taskinstance.py:1125} INFO - Dependencies all met for dep_context=non-requeueable deps ti=<TaskInstance: fondue_dag.clustering scheduled__2023-05-14T00:00:00+00:00 [queued]>
[2023-05-17T17:55:05.771+0000] {taskinstance.py:1125} INFO - Dependencies all met for dep_context=requeueable deps ti=<TaskInstance: fondue_dag.clustering scheduled__2023-05-14T00:00:00+00:00 [queued]>
[2023-05-17T17:55:05.772+0000] {taskinstance.py:1331} INFO - Starting attempt 1 of 2
[2023-05-17T17:55:05.798+0000] {taskinstance.py:1350} INFO - Executing <Task(PythonOperator): clustering> on 2023-05-14 00:00:00+00:00
[2023-05-17T17:55:05.808+0000] {standard_task_runner.py:57} INFO - Started process 862 to run task
[2023-05-17T17:55:05.812+0000] {standard_task_runner.py:84} INFO - Running: ['***', 'tasks', 'run', 'fondue_dag', 'clustering', 'scheduled__2023-05-14T00:00:00+00:00', '--job-id', '31', '--raw', '--subdir', 'DAGS_FOLDER/fondue_dag.py', '--cfg-path', '/tmp/tmp58pjtvlc']
[2023-05-17T17:55:05.814+0000] {standard_task_runner.py:85} INFO - Job 31: Subtask clustering
[2023-05-17T17:55:05.882+0000] {task_command.py:410} INFO - Running <TaskInstance: fondue_dag.clustering scheduled__2023-05-14T00:00:00+00:00 [running]> on host a37c7bc3731c
[2023-05-17T17:55:06.011+0000] {taskinstance.py:1570} INFO - Exporting env vars: AIRFLOW_CTX_DAG_EMAIL='Bhuribhat@gmail.com' AIRFLOW_CTX_DAG_OWNER='pras' AIRFLOW_CTX_DAG_ID='fondue_dag' AIRFLOW_CTX_TASK_ID='clustering' AIRFLOW_CTX_EXECUTION_DATE='2023-05-14T00:00:00+00:00' AIRFLOW_CTX_TRY_NUMBER='1' AIRFLOW_CTX_DAG_RUN_ID='scheduled__2023-05-14T00:00:00+00:00'
[2023-05-17T17:55:28.227+0000] {logging_mixin.py:149} WARNING - 2023/05/17 17:55:28 WARNING mlflow.utils.git_utils: Failed to import Git (the Git executable is probably not on your PATH), so Git SHA is not available. Error: Failed to initialize: Bad git executable.
=======
[2023-05-18T04:22:23.190+0000] {logging_mixin.py:149} INFO - Changing /opt/***/logs/dag_id=fondue_dag/run_id=scheduled__2023-05-14T00:00:00+00:00/task_id=clustering permission to 509
[2023-05-18T04:22:23.191+0000] {logging_mixin.py:149} INFO - Failed to change /opt/***/logs/dag_id=fondue_dag/run_id=scheduled__2023-05-14T00:00:00+00:00/task_id=clustering permission to 509: [Errno 1] Operation not permitted: '/opt/***/logs/dag_id=fondue_dag/run_id=scheduled__2023-05-14T00:00:00+00:00/task_id=clustering'
[2023-05-18T04:22:23.288+0000] {logging_mixin.py:149} INFO - Changing /opt/***/logs/dag_id=fondue_dag/run_id=scheduled__2023-05-14T00:00:00+00:00/task_id=clustering permission to 509
[2023-05-18T04:22:23.289+0000] {logging_mixin.py:149} INFO - Failed to change /opt/***/logs/dag_id=fondue_dag/run_id=scheduled__2023-05-14T00:00:00+00:00/task_id=clustering permission to 509: [Errno 1] Operation not permitted: '/opt/***/logs/dag_id=fondue_dag/run_id=scheduled__2023-05-14T00:00:00+00:00/task_id=clustering'
[2023-05-18T04:22:23.337+0000] {taskinstance.py:1125} INFO - Dependencies all met for dep_context=non-requeueable deps ti=<TaskInstance: fondue_dag.clustering scheduled__2023-05-14T00:00:00+00:00 [queued]>
[2023-05-18T04:22:23.355+0000] {taskinstance.py:1125} INFO - Dependencies all met for dep_context=requeueable deps ti=<TaskInstance: fondue_dag.clustering scheduled__2023-05-14T00:00:00+00:00 [queued]>
[2023-05-18T04:22:23.355+0000] {taskinstance.py:1331} INFO - Starting attempt 1 of 2
[2023-05-18T04:22:23.417+0000] {taskinstance.py:1350} INFO - Executing <Task(PythonOperator): clustering> on 2023-05-14 00:00:00+00:00
[2023-05-18T04:22:23.439+0000] {standard_task_runner.py:57} INFO - Started process 573 to run task
[2023-05-18T04:22:23.462+0000] {standard_task_runner.py:84} INFO - Running: ['***', 'tasks', 'run', 'fondue_dag', 'clustering', 'scheduled__2023-05-14T00:00:00+00:00', '--job-id', '34', '--raw', '--subdir', 'DAGS_FOLDER/fondue_dag.py', '--cfg-path', '/tmp/tmp6_2h5eey']
[2023-05-18T04:22:23.466+0000] {standard_task_runner.py:85} INFO - Job 34: Subtask clustering
[2023-05-18T04:22:23.589+0000] {logging_mixin.py:149} INFO - Changing /opt/***/logs/dag_id=fondue_dag/run_id=scheduled__2023-05-14T00:00:00+00:00/task_id=clustering permission to 509
[2023-05-18T04:22:23.589+0000] {logging_mixin.py:149} INFO - Failed to change /opt/***/logs/dag_id=fondue_dag/run_id=scheduled__2023-05-14T00:00:00+00:00/task_id=clustering permission to 509: [Errno 1] Operation not permitted: '/opt/***/logs/dag_id=fondue_dag/run_id=scheduled__2023-05-14T00:00:00+00:00/task_id=clustering'
[2023-05-18T04:22:23.597+0000] {task_command.py:410} INFO - Running <TaskInstance: fondue_dag.clustering scheduled__2023-05-14T00:00:00+00:00 [running]> on host b36de7cfc389
[2023-05-18T04:22:23.799+0000] {taskinstance.py:1570} INFO - Exporting env vars: AIRFLOW_CTX_DAG_EMAIL='Bhuribhat@gmail.com' AIRFLOW_CTX_DAG_OWNER='pras' AIRFLOW_CTX_DAG_ID='fondue_dag' AIRFLOW_CTX_TASK_ID='clustering' AIRFLOW_CTX_EXECUTION_DATE='2023-05-14T00:00:00+00:00' AIRFLOW_CTX_TRY_NUMBER='1' AIRFLOW_CTX_DAG_RUN_ID='scheduled__2023-05-14T00:00:00+00:00'
[2023-05-18T04:23:07.639+0000] {logging_mixin.py:149} WARNING - 2023/05/18 04:23:07 WARNING mlflow.utils.git_utils: Failed to import Git (the Git executable is probably not on your PATH), so Git SHA is not available. Error: Failed to initialize: Bad git executable.
>>>>>>> 8e4a41b368593e9ce283ae02afd6c27252f67370
The git executable must be specified in one of the following ways:
    - be included in your $PATH
    - be set via $GIT_PYTHON_GIT_EXECUTABLE
    - explicitly set via git.refresh()

All git commands will error until this is rectified.

This initial warning can be silenced or aggravated in the future by setting the
$GIT_PYTHON_REFRESH environment variable. Use one of the following values:
    - quiet|q|silence|s|none|n|0: for no warning or exception
    - warn|w|warning|1: for a printed warning
    - error|e|raise|r|2: for a raised exception

Example:
    export GIT_PYTHON_REFRESH=quiet
<<<<<<< HEAD
[2023-05-17T17:55:34.474+0000] {python.py:183} INFO - Done. Returned value was: None
[2023-05-17T17:55:34.493+0000] {taskinstance.py:1373} INFO - Marking task as SUCCESS. dag_id=fondue_dag, task_id=clustering, execution_date=20230514T000000, start_date=20230517T175505, end_date=20230517T175534
[2023-05-17T17:55:34.554+0000] {local_task_job_runner.py:232} INFO - Task exited with return code 0
[2023-05-17T17:55:34.592+0000] {taskinstance.py:2674} INFO - 1 downstream tasks scheduled from follow-on schedule check
[2023-05-17T18:18:26.873+0000] {taskinstance.py:1125} INFO - Dependencies all met for dep_context=non-requeueable deps ti=<TaskInstance: fondue_dag.clustering scheduled__2023-05-14T00:00:00+00:00 [queued]>
[2023-05-17T18:18:26.927+0000] {taskinstance.py:1125} INFO - Dependencies all met for dep_context=requeueable deps ti=<TaskInstance: fondue_dag.clustering scheduled__2023-05-14T00:00:00+00:00 [queued]>
[2023-05-17T18:18:26.928+0000] {taskinstance.py:1331} INFO - Starting attempt 1 of 2
[2023-05-17T18:18:26.999+0000] {taskinstance.py:1350} INFO - Executing <Task(PythonOperator): clustering> on 2023-05-14 00:00:00+00:00
[2023-05-17T18:18:27.019+0000] {standard_task_runner.py:57} INFO - Started process 1115 to run task
[2023-05-17T18:18:27.022+0000] {standard_task_runner.py:84} INFO - Running: ['***', 'tasks', 'run', 'fondue_dag', 'clustering', 'scheduled__2023-05-14T00:00:00+00:00', '--job-id', '35', '--raw', '--subdir', 'DAGS_FOLDER/fondue_dag.py', '--cfg-path', '/tmp/tmpail6790p']
[2023-05-17T18:18:27.024+0000] {standard_task_runner.py:85} INFO - Job 35: Subtask clustering
[2023-05-17T18:18:27.213+0000] {task_command.py:410} INFO - Running <TaskInstance: fondue_dag.clustering scheduled__2023-05-14T00:00:00+00:00 [running]> on host 3390ff13fbf6
[2023-05-17T18:18:28.218+0000] {taskinstance.py:1570} INFO - Exporting env vars: AIRFLOW_CTX_DAG_EMAIL='Bhuribhat@gmail.com' AIRFLOW_CTX_DAG_OWNER='pras' AIRFLOW_CTX_DAG_ID='fondue_dag' AIRFLOW_CTX_TASK_ID='clustering' AIRFLOW_CTX_EXECUTION_DATE='2023-05-14T00:00:00+00:00' AIRFLOW_CTX_TRY_NUMBER='1' AIRFLOW_CTX_DAG_RUN_ID='scheduled__2023-05-14T00:00:00+00:00'
[2023-05-17T18:18:52.412+0000] {logging_mixin.py:149} WARNING - 2023/05/17 18:18:52 WARNING mlflow.utils.git_utils: Failed to import Git (the Git executable is probably not on your PATH), so Git SHA is not available. Error: Failed to initialize: Bad git executable.
The git executable must be specified in one of the following ways:
    - be included in your $PATH
    - be set via $GIT_PYTHON_GIT_EXECUTABLE
    - explicitly set via git.refresh()

All git commands will error until this is rectified.

This initial warning can be silenced or aggravated in the future by setting the
$GIT_PYTHON_REFRESH environment variable. Use one of the following values:
    - quiet|q|silence|s|none|n|0: for no warning or exception
    - warn|w|warning|1: for a printed warning
    - error|e|raise|r|2: for a raised exception

Example:
    export GIT_PYTHON_REFRESH=quiet
[2023-05-17T18:18:59.029+0000] {python.py:183} INFO - Done. Returned value was: None
[2023-05-17T18:18:59.068+0000] {taskinstance.py:1373} INFO - Marking task as SUCCESS. dag_id=fondue_dag, task_id=clustering, execution_date=20230514T000000, start_date=20230517T181826, end_date=20230517T181859
[2023-05-17T18:18:59.157+0000] {local_task_job_runner.py:232} INFO - Task exited with return code 0
[2023-05-17T18:18:59.209+0000] {taskinstance.py:2674} INFO - 1 downstream tasks scheduled from follow-on schedule check
[2023-05-17T18:26:00.546+0000] {taskinstance.py:1125} INFO - Dependencies all met for dep_context=non-requeueable deps ti=<TaskInstance: fondue_dag.clustering scheduled__2023-05-14T00:00:00+00:00 [queued]>
[2023-05-17T18:26:00.605+0000] {taskinstance.py:1125} INFO - Dependencies all met for dep_context=requeueable deps ti=<TaskInstance: fondue_dag.clustering scheduled__2023-05-14T00:00:00+00:00 [queued]>
[2023-05-17T18:26:00.614+0000] {taskinstance.py:1331} INFO - Starting attempt 1 of 2
[2023-05-17T18:26:00.717+0000] {taskinstance.py:1350} INFO - Executing <Task(PythonOperator): clustering> on 2023-05-14 00:00:00+00:00
[2023-05-17T18:26:00.731+0000] {standard_task_runner.py:57} INFO - Started process 1607 to run task
[2023-05-17T18:26:00.767+0000] {standard_task_runner.py:84} INFO - Running: ['***', 'tasks', 'run', 'fondue_dag', 'clustering', 'scheduled__2023-05-14T00:00:00+00:00', '--job-id', '38', '--raw', '--subdir', 'DAGS_FOLDER/fondue_dag.py', '--cfg-path', '/tmp/tmpi444jtpa']
[2023-05-17T18:26:00.775+0000] {standard_task_runner.py:85} INFO - Job 38: Subtask clustering
[2023-05-17T18:26:00.897+0000] {task_command.py:410} INFO - Running <TaskInstance: fondue_dag.clustering scheduled__2023-05-14T00:00:00+00:00 [running]> on host 70fcd41af239
[2023-05-17T18:26:01.102+0000] {taskinstance.py:1570} INFO - Exporting env vars: AIRFLOW_CTX_DAG_EMAIL='Bhuribhat@gmail.com' AIRFLOW_CTX_DAG_OWNER='pras' AIRFLOW_CTX_DAG_ID='fondue_dag' AIRFLOW_CTX_TASK_ID='clustering' AIRFLOW_CTX_EXECUTION_DATE='2023-05-14T00:00:00+00:00' AIRFLOW_CTX_TRY_NUMBER='1' AIRFLOW_CTX_DAG_RUN_ID='scheduled__2023-05-14T00:00:00+00:00'
[2023-05-17T18:26:14.103+0000] {logging_mixin.py:149} WARNING - 2023/05/17 18:26:14 WARNING mlflow.utils.git_utils: Failed to import Git (the Git executable is probably not on your PATH), so Git SHA is not available. Error: Failed to initialize: Bad git executable.
The git executable must be specified in one of the following ways:
    - be included in your $PATH
    - be set via $GIT_PYTHON_GIT_EXECUTABLE
    - explicitly set via git.refresh()

All git commands will error until this is rectified.

This initial warning can be silenced or aggravated in the future by setting the
$GIT_PYTHON_REFRESH environment variable. Use one of the following values:
    - quiet|q|silence|s|none|n|0: for no warning or exception
    - warn|w|warning|1: for a printed warning
    - error|e|raise|r|2: for a raised exception

Example:
    export GIT_PYTHON_REFRESH=quiet
[2023-05-17T18:26:18.791+0000] {python.py:183} INFO - Done. Returned value was: None
[2023-05-17T18:26:18.806+0000] {taskinstance.py:1373} INFO - Marking task as SUCCESS. dag_id=fondue_dag, task_id=clustering, execution_date=20230514T000000, start_date=20230517T182600, end_date=20230517T182618
[2023-05-17T18:26:18.856+0000] {local_task_job_runner.py:232} INFO - Task exited with return code 0
[2023-05-17T18:26:18.882+0000] {taskinstance.py:2674} INFO - 1 downstream tasks scheduled from follow-on schedule check
[2023-05-17T18:37:30.080+0000] {taskinstance.py:1125} INFO - Dependencies all met for dep_context=non-requeueable deps ti=<TaskInstance: fondue_dag.clustering scheduled__2023-05-14T00:00:00+00:00 [queued]>
[2023-05-17T18:37:30.110+0000] {taskinstance.py:1125} INFO - Dependencies all met for dep_context=requeueable deps ti=<TaskInstance: fondue_dag.clustering scheduled__2023-05-14T00:00:00+00:00 [queued]>
[2023-05-17T18:37:30.111+0000] {taskinstance.py:1331} INFO - Starting attempt 1 of 2
[2023-05-17T18:37:30.149+0000] {taskinstance.py:1350} INFO - Executing <Task(PythonOperator): clustering> on 2023-05-14 00:00:00+00:00
[2023-05-17T18:37:30.161+0000] {standard_task_runner.py:57} INFO - Started process 1464 to run task
[2023-05-17T18:37:30.166+0000] {standard_task_runner.py:84} INFO - Running: ['***', 'tasks', 'run', 'fondue_dag', 'clustering', 'scheduled__2023-05-14T00:00:00+00:00', '--job-id', '35', '--raw', '--subdir', 'DAGS_FOLDER/fondue_dag.py', '--cfg-path', '/tmp/tmpcbwqucm1']
[2023-05-17T18:37:30.169+0000] {standard_task_runner.py:85} INFO - Job 35: Subtask clustering
[2023-05-17T18:37:30.258+0000] {task_command.py:410} INFO - Running <TaskInstance: fondue_dag.clustering scheduled__2023-05-14T00:00:00+00:00 [running]> on host 1545bed90dab
[2023-05-17T18:37:30.458+0000] {taskinstance.py:1570} INFO - Exporting env vars: AIRFLOW_CTX_DAG_EMAIL='Bhuribhat@gmail.com' AIRFLOW_CTX_DAG_OWNER='pras' AIRFLOW_CTX_DAG_ID='fondue_dag' AIRFLOW_CTX_TASK_ID='clustering' AIRFLOW_CTX_EXECUTION_DATE='2023-05-14T00:00:00+00:00' AIRFLOW_CTX_TRY_NUMBER='1' AIRFLOW_CTX_DAG_RUN_ID='scheduled__2023-05-14T00:00:00+00:00'
[2023-05-17T18:37:33.171+0000] {logging_mixin.py:149} WARNING - 2023/05/17 18:37:33 WARNING mlflow.utils.git_utils: Failed to import Git (the Git executable is probably not on your PATH), so Git SHA is not available. Error: Failed to initialize: Bad git executable.
The git executable must be specified in one of the following ways:
    - be included in your $PATH
    - be set via $GIT_PYTHON_GIT_EXECUTABLE
    - explicitly set via git.refresh()

All git commands will error until this is rectified.

This initial warning can be silenced or aggravated in the future by setting the
$GIT_PYTHON_REFRESH environment variable. Use one of the following values:
    - quiet|q|silence|s|none|n|0: for no warning or exception
    - warn|w|warning|1: for a printed warning
    - error|e|raise|r|2: for a raised exception

Example:
    export GIT_PYTHON_REFRESH=quiet
[2023-05-17T18:37:37.755+0000] {python.py:183} INFO - Done. Returned value was: None
[2023-05-17T18:37:37.782+0000] {taskinstance.py:1373} INFO - Marking task as SUCCESS. dag_id=fondue_dag, task_id=clustering, execution_date=20230514T000000, start_date=20230517T183730, end_date=20230517T183737
[2023-05-17T18:37:37.882+0000] {local_task_job_runner.py:232} INFO - Task exited with return code 0
[2023-05-17T18:37:37.921+0000] {taskinstance.py:2674} INFO - 1 downstream tasks scheduled from follow-on schedule check
[2023-05-18T06:41:19.613+0000] {taskinstance.py:1125} INFO - Dependencies all met for dep_context=non-requeueable deps ti=<TaskInstance: fondue_dag.clustering scheduled__2023-05-14T00:00:00+00:00 [queued]>
[2023-05-18T06:41:19.635+0000] {taskinstance.py:1125} INFO - Dependencies all met for dep_context=requeueable deps ti=<TaskInstance: fondue_dag.clustering scheduled__2023-05-14T00:00:00+00:00 [queued]>
[2023-05-18T06:41:19.637+0000] {taskinstance.py:1331} INFO - Starting attempt 1 of 2
[2023-05-18T06:41:19.669+0000] {taskinstance.py:1350} INFO - Executing <Task(PythonOperator): clustering> on 2023-05-14 00:00:00+00:00
[2023-05-18T06:41:19.682+0000] {standard_task_runner.py:57} INFO - Started process 1384 to run task
[2023-05-18T06:41:19.686+0000] {standard_task_runner.py:84} INFO - Running: ['***', 'tasks', 'run', 'fondue_dag', 'clustering', 'scheduled__2023-05-14T00:00:00+00:00', '--job-id', '35', '--raw', '--subdir', 'DAGS_FOLDER/fondue_dag.py', '--cfg-path', '/tmp/tmpljhox5ta']
[2023-05-18T06:41:19.689+0000] {standard_task_runner.py:85} INFO - Job 35: Subtask clustering
[2023-05-18T06:41:19.798+0000] {task_command.py:410} INFO - Running <TaskInstance: fondue_dag.clustering scheduled__2023-05-14T00:00:00+00:00 [running]> on host 714a0c7ad307
[2023-05-18T06:41:19.993+0000] {taskinstance.py:1570} INFO - Exporting env vars: AIRFLOW_CTX_DAG_EMAIL='Bhuribhat@gmail.com' AIRFLOW_CTX_DAG_OWNER='pras' AIRFLOW_CTX_DAG_ID='fondue_dag' AIRFLOW_CTX_TASK_ID='clustering' AIRFLOW_CTX_EXECUTION_DATE='2023-05-14T00:00:00+00:00' AIRFLOW_CTX_TRY_NUMBER='1' AIRFLOW_CTX_DAG_RUN_ID='scheduled__2023-05-14T00:00:00+00:00'
[2023-05-18T06:41:46.447+0000] {logging_mixin.py:149} WARNING - 2023/05/18 06:41:46 WARNING mlflow.utils.git_utils: Failed to import Git (the Git executable is probably not on your PATH), so Git SHA is not available. Error: Failed to initialize: Bad git executable.
The git executable must be specified in one of the following ways:
    - be included in your $PATH
    - be set via $GIT_PYTHON_GIT_EXECUTABLE
    - explicitly set via git.refresh()

All git commands will error until this is rectified.

This initial warning can be silenced or aggravated in the future by setting the
$GIT_PYTHON_REFRESH environment variable. Use one of the following values:
    - quiet|q|silence|s|none|n|0: for no warning or exception
    - warn|w|warning|1: for a printed warning
    - error|e|raise|r|2: for a raised exception

Example:
    export GIT_PYTHON_REFRESH=quiet
[2023-05-18T06:41:46.575+0000] {taskinstance.py:1847} ERROR - Task failed with exception
Traceback (most recent call last):
  File "/home/airflow/.local/lib/python3.7/site-packages/airflow/operators/python.py", line 181, in execute
    return_value = self.execute_callable()
  File "/home/airflow/.local/lib/python3.7/site-packages/airflow/operators/python.py", line 198, in execute_callable
    return self.python_callable(*self.op_args, **self.op_kwargs)
  File "/opt/airflow/dags/utils/clustering.py", line 46, in kmean_cluster
    with mlflow.start_run() as run:
  File "/home/airflow/.local/lib/python3.7/site-packages/mlflow/tracking/fluent.py", line 277, in start_run
    ).format(_active_run_stack[0].info.run_id)
Exception: Run with UUID 52768072cdfb4f859021f1d8cadca716 is already active. To start a new run, first end the current run with mlflow.end_run(). To start a nested run, call start_run with nested=True
[2023-05-18T06:41:46.599+0000] {taskinstance.py:1373} INFO - Marking task as UP_FOR_RETRY. dag_id=fondue_dag, task_id=clustering, execution_date=20230514T000000, start_date=20230518T064119, end_date=20230518T064146
[2023-05-18T06:41:46.634+0000] {configuration.py:675} WARNING - section/key [smtp/smtp_user] not found in config
[2023-05-18T06:41:46.635+0000] {email.py:268} INFO - Email alerting: attempt 1
[2023-05-18T06:41:46.647+0000] {configuration.py:675} WARNING - section/key [smtp/smtp_user] not found in config
[2023-05-18T06:41:46.648+0000] {email.py:268} INFO - Email alerting: attempt 1
[2023-05-18T06:41:46.650+0000] {taskinstance.py:1912} ERROR - Failed to send email to: ['Bhuribhat@gmail.com']
Traceback (most recent call last):
  File "/home/airflow/.local/lib/python3.7/site-packages/airflow/models/taskinstance.py", line 1430, in _run_raw_task
    self._execute_task_with_callbacks(context, test_mode)
  File "/home/airflow/.local/lib/python3.7/site-packages/airflow/models/taskinstance.py", line 1581, in _execute_task_with_callbacks
    result = self._execute_task(context, task_orig)
  File "/home/airflow/.local/lib/python3.7/site-packages/airflow/models/taskinstance.py", line 1651, in _execute_task
    result = execute_callable(context=context)
  File "/home/airflow/.local/lib/python3.7/site-packages/airflow/operators/python.py", line 181, in execute
    return_value = self.execute_callable()
  File "/home/airflow/.local/lib/python3.7/site-packages/airflow/operators/python.py", line 198, in execute_callable
    return self.python_callable(*self.op_args, **self.op_kwargs)
  File "/opt/airflow/dags/utils/clustering.py", line 46, in kmean_cluster
    with mlflow.start_run() as run:
  File "/home/airflow/.local/lib/python3.7/site-packages/mlflow/tracking/fluent.py", line 277, in start_run
    ).format(_active_run_stack[0].info.run_id)
Exception: Run with UUID 52768072cdfb4f859021f1d8cadca716 is already active. To start a new run, first end the current run with mlflow.end_run(). To start a nested run, call start_run with nested=True

During handling of the above exception, another exception occurred:

Traceback (most recent call last):
  File "/home/airflow/.local/lib/python3.7/site-packages/airflow/models/taskinstance.py", line 2318, in email_alert
    send_email(task.email, subject, html_content)
  File "/home/airflow/.local/lib/python3.7/site-packages/airflow/utils/email.py", line 91, in send_email
    **kwargs,
  File "/home/airflow/.local/lib/python3.7/site-packages/airflow/utils/email.py", line 152, in send_email_smtp
    send_mime_email(e_from=mail_from, e_to=recipients, mime_msg=msg, conn_id=conn_id, dryrun=dryrun)
  File "/home/airflow/.local/lib/python3.7/site-packages/airflow/utils/email.py", line 270, in send_mime_email
    smtp_conn = _get_smtp_connection(smtp_host, smtp_port, smtp_timeout, smtp_ssl)
  File "/home/airflow/.local/lib/python3.7/site-packages/airflow/utils/email.py", line 317, in _get_smtp_connection
    else smtplib.SMTP(host=host, port=port, timeout=timeout)
  File "/usr/local/lib/python3.7/smtplib.py", line 251, in __init__
    (code, msg) = self.connect(host, port)
  File "/usr/local/lib/python3.7/smtplib.py", line 336, in connect
    self.sock = self._get_socket(host, port, self.timeout)
  File "/usr/local/lib/python3.7/smtplib.py", line 307, in _get_socket
    self.source_address)
  File "/usr/local/lib/python3.7/socket.py", line 728, in create_connection
    raise err
  File "/usr/local/lib/python3.7/socket.py", line 716, in create_connection
    sock.connect(sa)
OSError: [Errno 99] Cannot assign requested address

During handling of the above exception, another exception occurred:

Traceback (most recent call last):
  File "/home/airflow/.local/lib/python3.7/site-packages/airflow/models/taskinstance.py", line 1910, in handle_failure
    self.email_alert(error, task)
  File "/home/airflow/.local/lib/python3.7/site-packages/airflow/models/taskinstance.py", line 2320, in email_alert
    send_email(task.email, subject, html_content_err)
  File "/home/airflow/.local/lib/python3.7/site-packages/airflow/utils/email.py", line 91, in send_email
    **kwargs,
  File "/home/airflow/.local/lib/python3.7/site-packages/airflow/utils/email.py", line 152, in send_email_smtp
    send_mime_email(e_from=mail_from, e_to=recipients, mime_msg=msg, conn_id=conn_id, dryrun=dryrun)
  File "/home/airflow/.local/lib/python3.7/site-packages/airflow/utils/email.py", line 270, in send_mime_email
    smtp_conn = _get_smtp_connection(smtp_host, smtp_port, smtp_timeout, smtp_ssl)
  File "/home/airflow/.local/lib/python3.7/site-packages/airflow/utils/email.py", line 317, in _get_smtp_connection
    else smtplib.SMTP(host=host, port=port, timeout=timeout)
  File "/usr/local/lib/python3.7/smtplib.py", line 251, in __init__
    (code, msg) = self.connect(host, port)
  File "/usr/local/lib/python3.7/smtplib.py", line 336, in connect
    self.sock = self._get_socket(host, port, self.timeout)
  File "/usr/local/lib/python3.7/smtplib.py", line 307, in _get_socket
    self.source_address)
  File "/usr/local/lib/python3.7/socket.py", line 728, in create_connection
    raise err
  File "/usr/local/lib/python3.7/socket.py", line 716, in create_connection
    sock.connect(sa)
OSError: [Errno 99] Cannot assign requested address
[2023-05-18T06:41:46.678+0000] {standard_task_runner.py:109} ERROR - Failed to execute job 35 for task clustering (Run with UUID 52768072cdfb4f859021f1d8cadca716 is already active. To start a new run, first end the current run with mlflow.end_run(). To start a nested run, call start_run with nested=True; 1384)
[2023-05-18T06:41:46.707+0000] {local_task_job_runner.py:232} INFO - Task exited with return code 1
[2023-05-18T06:41:46.743+0000] {taskinstance.py:2674} INFO - 0 downstream tasks scheduled from follow-on schedule check
[2023-05-18T06:53:29.428+0000] {taskinstance.py:1125} INFO - Dependencies all met for dep_context=non-requeueable deps ti=<TaskInstance: fondue_dag.clustering scheduled__2023-05-14T00:00:00+00:00 [queued]>
[2023-05-18T06:53:29.481+0000] {taskinstance.py:1125} INFO - Dependencies all met for dep_context=requeueable deps ti=<TaskInstance: fondue_dag.clustering scheduled__2023-05-14T00:00:00+00:00 [queued]>
[2023-05-18T06:53:29.482+0000] {taskinstance.py:1331} INFO - Starting attempt 1 of 2
[2023-05-18T06:53:29.546+0000] {taskinstance.py:1350} INFO - Executing <Task(PythonOperator): clustering> on 2023-05-14 00:00:00+00:00
[2023-05-18T06:53:29.556+0000] {standard_task_runner.py:57} INFO - Started process 1481 to run task
[2023-05-18T06:53:29.570+0000] {standard_task_runner.py:84} INFO - Running: ['***', 'tasks', 'run', 'fondue_dag', 'clustering', 'scheduled__2023-05-14T00:00:00+00:00', '--job-id', '34', '--raw', '--subdir', 'DAGS_FOLDER/fondue_dag.py', '--cfg-path', '/tmp/tmp3vil575q']
[2023-05-18T06:53:29.582+0000] {standard_task_runner.py:85} INFO - Job 34: Subtask clustering
[2023-05-18T06:53:29.676+0000] {task_command.py:410} INFO - Running <TaskInstance: fondue_dag.clustering scheduled__2023-05-14T00:00:00+00:00 [running]> on host 26547302378e
[2023-05-18T06:53:29.887+0000] {taskinstance.py:1570} INFO - Exporting env vars: AIRFLOW_CTX_DAG_EMAIL='Bhuribhat@gmail.com' AIRFLOW_CTX_DAG_OWNER='pras' AIRFLOW_CTX_DAG_ID='fondue_dag' AIRFLOW_CTX_TASK_ID='clustering' AIRFLOW_CTX_EXECUTION_DATE='2023-05-14T00:00:00+00:00' AIRFLOW_CTX_TRY_NUMBER='1' AIRFLOW_CTX_DAG_RUN_ID='scheduled__2023-05-14T00:00:00+00:00'
[2023-05-18T06:53:51.086+0000] {logging_mixin.py:149} WARNING - 2023/05/18 06:53:51 WARNING mlflow.utils.git_utils: Failed to import Git (the Git executable is probably not on your PATH), so Git SHA is not available. Error: Failed to initialize: Bad git executable.
The git executable must be specified in one of the following ways:
    - be included in your $PATH
    - be set via $GIT_PYTHON_GIT_EXECUTABLE
    - explicitly set via git.refresh()

All git commands will error until this is rectified.

This initial warning can be silenced or aggravated in the future by setting the
$GIT_PYTHON_REFRESH environment variable. Use one of the following values:
    - quiet|q|silence|s|none|n|0: for no warning or exception
    - warn|w|warning|1: for a printed warning
    - error|e|raise|r|2: for a raised exception

Example:
    export GIT_PYTHON_REFRESH=quiet
[2023-05-18T06:53:59.729+0000] {python.py:183} INFO - Done. Returned value was: None
[2023-05-18T06:53:59.764+0000] {taskinstance.py:1373} INFO - Marking task as SUCCESS. dag_id=fondue_dag, task_id=clustering, execution_date=20230514T000000, start_date=20230518T065329, end_date=20230518T065359
[2023-05-18T06:53:59.946+0000] {local_task_job_runner.py:232} INFO - Task exited with return code 0
[2023-05-18T06:53:59.995+0000] {taskinstance.py:2674} INFO - 1 downstream tasks scheduled from follow-on schedule check
=======
[2023-05-18T04:23:16.093+0000] {python.py:183} INFO - Done. Returned value was: None
[2023-05-18T04:23:16.127+0000] {taskinstance.py:1373} INFO - Marking task as SUCCESS. dag_id=fondue_dag, task_id=clustering, execution_date=20230514T000000, start_date=20230518T042223, end_date=20230518T042316
[2023-05-18T04:23:16.269+0000] {local_task_job_runner.py:232} INFO - Task exited with return code 0
[2023-05-18T04:23:16.349+0000] {taskinstance.py:2674} INFO - 1 downstream tasks scheduled from follow-on schedule check
>>>>>>> 8e4a41b368593e9ce283ae02afd6c27252f67370
