[2023-05-16T16:20:31.115+0000] {taskinstance.py:1125} INFO - Dependencies all met for dep_context=non-requeueable deps ti=<TaskInstance: fondue_dag.visualize_data manual__2023-05-16T16:14:54.869822+00:00 [queued]>
[2023-05-16T16:20:31.129+0000] {taskinstance.py:1125} INFO - Dependencies all met for dep_context=requeueable deps ti=<TaskInstance: fondue_dag.visualize_data manual__2023-05-16T16:14:54.869822+00:00 [queued]>
[2023-05-16T16:20:31.130+0000] {taskinstance.py:1331} INFO - Starting attempt 2 of 2
[2023-05-16T16:20:31.148+0000] {taskinstance.py:1350} INFO - Executing <Task(PythonOperator): visualize_data> on 2023-05-16 16:14:54.869822+00:00
[2023-05-16T16:20:31.215+0000] {standard_task_runner.py:57} INFO - Started process 4026 to run task
[2023-05-16T16:20:31.218+0000] {standard_task_runner.py:84} INFO - Running: ['***', 'tasks', 'run', 'fondue_dag', 'visualize_data', 'manual__2023-05-16T16:14:54.869822+00:00', '--job-id', '32', '--raw', '--subdir', 'DAGS_FOLDER/fondue_dag.py', '--cfg-path', '/tmp/tmppnjer7vl']
[2023-05-16T16:20:31.220+0000] {standard_task_runner.py:85} INFO - Job 32: Subtask visualize_data
[2023-05-16T16:20:31.281+0000] {task_command.py:410} INFO - Running <TaskInstance: fondue_dag.visualize_data manual__2023-05-16T16:14:54.869822+00:00 [running]> on host 9a20db09badf
[2023-05-16T16:20:31.389+0000] {taskinstance.py:1570} INFO - Exporting env vars: AIRFLOW_CTX_DAG_EMAIL='Bhuribhat@gmail.com' AIRFLOW_CTX_DAG_OWNER='pras' AIRFLOW_CTX_DAG_ID='fondue_dag' AIRFLOW_CTX_TASK_ID='visualize_data' AIRFLOW_CTX_EXECUTION_DATE='2023-05-16T16:14:54.869822+00:00' AIRFLOW_CTX_TRY_NUMBER='2' AIRFLOW_CTX_DAG_RUN_ID='manual__2023-05-16T16:14:54.869822+00:00'
[2023-05-16T16:20:31.594+0000] {font_manager.py:1352} WARNING - findfont: Font family ['TH Sarabun Chula'] not found. Falling back to DejaVu Sans.
[2023-05-16T16:20:31.604+0000] {font_manager.py:1352} WARNING - findfont: Font family ['TH Sarabun Chula'] not found. Falling back to DejaVu Sans.
[2023-05-16T16:20:31.984+0000] {taskinstance.py:1847} ERROR - Task failed with exception
Traceback (most recent call last):
  File "/home/airflow/.local/lib/python3.7/site-packages/pandas/core/indexes/base.py", line 3361, in get_loc
    return self._engine.get_loc(casted_key)
  File "pandas/_libs/index.pyx", line 76, in pandas._libs.index.IndexEngine.get_loc
  File "pandas/_libs/index.pyx", line 108, in pandas._libs.index.IndexEngine.get_loc
  File "pandas/_libs/hashtable_class_helper.pxi", line 5198, in pandas._libs.hashtable.PyObjectHashTable.get_item
  File "pandas/_libs/hashtable_class_helper.pxi", line 5206, in pandas._libs.hashtable.PyObjectHashTable.get_item
KeyError: 'type_count'

The above exception was the direct cause of the following exception:

Traceback (most recent call last):
  File "/home/airflow/.local/lib/python3.7/site-packages/airflow/operators/python.py", line 181, in execute
    return_value = self.execute_callable()
  File "/home/airflow/.local/lib/python3.7/site-packages/airflow/operators/python.py", line 198, in execute_callable
    return self.python_callable(*self.op_args, **self.op_kwargs)
  File "/opt/airflow/dags/utils/visualize.py", line 104, in visualize_data
    compare_count_plot(df, 'type_count', 'Problems Count')
  File "/opt/airflow/dags/utils/visualize.py", line 32, in compare_count_plot
    type_list = data[column].value_counts().index
  File "/home/airflow/.local/lib/python3.7/site-packages/pandas/core/frame.py", line 3458, in __getitem__
    indexer = self.columns.get_loc(key)
  File "/home/airflow/.local/lib/python3.7/site-packages/pandas/core/indexes/base.py", line 3363, in get_loc
    raise KeyError(key) from err
KeyError: 'type_count'
[2023-05-16T16:20:32.004+0000] {taskinstance.py:1373} INFO - Marking task as FAILED. dag_id=fondue_dag, task_id=visualize_data, execution_date=20230516T161454, start_date=20230516T162031, end_date=20230516T162032
[2023-05-16T16:20:32.030+0000] {standard_task_runner.py:109} ERROR - Failed to execute job 32 for task visualize_data ('type_count'; 4026)
[2023-05-16T16:20:32.077+0000] {local_task_job_runner.py:232} INFO - Task exited with return code 1
[2023-05-16T16:20:32.100+0000] {taskinstance.py:2674} INFO - 0 downstream tasks scheduled from follow-on schedule check
