[2023-05-18T04:44:03.825+0000] {taskinstance.py:1125} INFO - Dependencies all met for dep_context=non-requeueable deps ti=<TaskInstance: fondue_dag.visualize_data manual__2023-05-18T04:43:43.099476+00:00 [queued]>
[2023-05-18T04:44:03.838+0000] {taskinstance.py:1125} INFO - Dependencies all met for dep_context=requeueable deps ti=<TaskInstance: fondue_dag.visualize_data manual__2023-05-18T04:43:43.099476+00:00 [queued]>
[2023-05-18T04:44:03.839+0000] {taskinstance.py:1331} INFO - Starting attempt 1 of 2
[2023-05-18T04:44:03.857+0000] {taskinstance.py:1350} INFO - Executing <Task(PythonOperator): visualize_data> on 2023-05-18 04:43:43.099476+00:00
[2023-05-18T04:44:03.865+0000] {standard_task_runner.py:57} INFO - Started process 2092 to run task
[2023-05-18T04:44:03.868+0000] {standard_task_runner.py:84} INFO - Running: ['***', 'tasks', 'run', 'fondue_dag', 'visualize_data', 'manual__2023-05-18T04:43:43.099476+00:00', '--job-id', '66', '--raw', '--subdir', 'DAGS_FOLDER/fondue_dag.py', '--cfg-path', '/tmp/tmpugexun21']
[2023-05-18T04:44:03.870+0000] {standard_task_runner.py:85} INFO - Job 66: Subtask visualize_data
[2023-05-18T04:44:03.924+0000] {task_command.py:410} INFO - Running <TaskInstance: fondue_dag.visualize_data manual__2023-05-18T04:43:43.099476+00:00 [running]> on host b36de7cfc389
[2023-05-18T04:44:04.017+0000] {taskinstance.py:1570} INFO - Exporting env vars: AIRFLOW_CTX_DAG_EMAIL='Bhuribhat@gmail.com' AIRFLOW_CTX_DAG_OWNER='pras' AIRFLOW_CTX_DAG_ID='fondue_dag' AIRFLOW_CTX_TASK_ID='visualize_data' AIRFLOW_CTX_EXECUTION_DATE='2023-05-18T04:43:43.099476+00:00' AIRFLOW_CTX_TRY_NUMBER='1' AIRFLOW_CTX_DAG_RUN_ID='manual__2023-05-18T04:43:43.099476+00:00'
[2023-05-18T04:44:06.597+0000] {font_manager.py:1352} WARNING - findfont: Font family ['TH Sarabun Chula'] not found. Falling back to DejaVu Sans.
[2023-05-18T04:44:06.608+0000] {font_manager.py:1352} WARNING - findfont: Font family ['TH Sarabun Chula'] not found. Falling back to DejaVu Sans.
[2023-05-18T04:44:07.675+0000] {taskinstance.py:1847} ERROR - Task failed with exception
Traceback (most recent call last):
  File "/home/airflow/.local/lib/python3.7/site-packages/airflow/operators/python.py", line 181, in execute
    return_value = self.execute_callable()
  File "/home/airflow/.local/lib/python3.7/site-packages/airflow/operators/python.py", line 198, in execute_callable
    return self.python_callable(*self.op_args, **self.op_kwargs)
  File "/opt/airflow/dags/utils/visualize.py", line 205, in visualize_data
    compare_pie_plot(df, 'state', None)
  File "/opt/airflow/dags/utils/visualize.py", line 63, in compare_pie_plot
    textprops={'size': 'x-large'}, startangle=90
  File "/home/airflow/.local/lib/python3.7/site-packages/matplotlib/pyplot.py", line 2761, in pie
    **({"data": data} if data is not None else {}))
  File "/home/airflow/.local/lib/python3.7/site-packages/matplotlib/__init__.py", line 1414, in inner
    return func(ax, *map(sanitize_sequence, args), **kwargs)
  File "/home/airflow/.local/lib/python3.7/site-packages/matplotlib/axes/_axes.py", line 3066, in pie
    raise ValueError("'explode' must be of length 'x'")
ValueError: 'explode' must be of length 'x'
[2023-05-18T04:44:07.694+0000] {taskinstance.py:1373} INFO - Marking task as UP_FOR_RETRY. dag_id=fondue_dag, task_id=visualize_data, execution_date=20230518T044343, start_date=20230518T044403, end_date=20230518T044407
[2023-05-18T04:44:07.714+0000] {configuration.py:675} WARNING - section/key [smtp/smtp_user] not found in config
[2023-05-18T04:44:07.714+0000] {email.py:268} INFO - Email alerting: attempt 1
[2023-05-18T04:44:07.721+0000] {configuration.py:675} WARNING - section/key [smtp/smtp_user] not found in config
[2023-05-18T04:44:07.722+0000] {email.py:268} INFO - Email alerting: attempt 1
[2023-05-18T04:44:07.724+0000] {taskinstance.py:1912} ERROR - Failed to send email to: ['Bhuribhat@gmail.com']
Traceback (most recent call last):
  File "/home/airflow/.local/lib/python3.7/site-packages/airflow/models/taskinstance.py", line 1430, in _run_raw_task
    self._execute_task_with_callbacks(context, test_mode)
  File "/home/airflow/.local/lib/python3.7/site-packages/airflow/models/taskinstance.py", line 1581, in _execute_task_with_callbacks
    result = self._execute_task(context, task_orig)
  File "/home/airflow/.local/lib/python3.7/site-packages/airflow/models/taskinstance.py", line 1651, in _execute_task
    result = execute_callable(context=context)
  File "/home/airflow/.local/lib/python3.7/site-packages/airflow/operators/python.py", line 181, in execute
    return_value = self.execute_callable()
  File "/home/airflow/.local/lib/python3.7/site-packages/airflow/operators/python.py", line 198, in execute_callable
    return self.python_callable(*self.op_args, **self.op_kwargs)
  File "/opt/airflow/dags/utils/visualize.py", line 205, in visualize_data
    compare_pie_plot(df, 'state', None)
  File "/opt/airflow/dags/utils/visualize.py", line 63, in compare_pie_plot
    textprops={'size': 'x-large'}, startangle=90
  File "/home/airflow/.local/lib/python3.7/site-packages/matplotlib/pyplot.py", line 2761, in pie
    **({"data": data} if data is not None else {}))
  File "/home/airflow/.local/lib/python3.7/site-packages/matplotlib/__init__.py", line 1414, in inner
    return func(ax, *map(sanitize_sequence, args), **kwargs)
  File "/home/airflow/.local/lib/python3.7/site-packages/matplotlib/axes/_axes.py", line 3066, in pie
    raise ValueError("'explode' must be of length 'x'")
ValueError: 'explode' must be of length 'x'

During handling of the above exception, another exception occurred:

Traceback (most recent call last):
  File "/home/airflow/.local/lib/python3.7/site-packages/airflow/models/taskinstance.py", line 2318, in email_alert
    send_email(task.email, subject, html_content)
  File "/home/airflow/.local/lib/python3.7/site-packages/airflow/utils/email.py", line 91, in send_email
    **kwargs,
  File "/home/airflow/.local/lib/python3.7/site-packages/airflow/utils/email.py", line 152, in send_email_smtp
    send_mime_email(e_from=mail_from, e_to=recipients, mime_msg=msg, conn_id=conn_id, dryrun=dryrun)
  File "/home/airflow/.local/lib/python3.7/site-packages/airflow/utils/email.py", line 270, in send_mime_email
    smtp_conn = _get_smtp_connection(smtp_host, smtp_port, smtp_timeout, smtp_ssl)
  File "/home/airflow/.local/lib/python3.7/site-packages/airflow/utils/email.py", line 317, in _get_smtp_connection
    else smtplib.SMTP(host=host, port=port, timeout=timeout)
  File "/usr/local/lib/python3.7/smtplib.py", line 251, in __init__
    (code, msg) = self.connect(host, port)
  File "/usr/local/lib/python3.7/smtplib.py", line 336, in connect
    self.sock = self._get_socket(host, port, self.timeout)
  File "/usr/local/lib/python3.7/smtplib.py", line 307, in _get_socket
    self.source_address)
  File "/usr/local/lib/python3.7/socket.py", line 728, in create_connection
    raise err
  File "/usr/local/lib/python3.7/socket.py", line 716, in create_connection
    sock.connect(sa)
OSError: [Errno 99] Cannot assign requested address

During handling of the above exception, another exception occurred:

Traceback (most recent call last):
  File "/home/airflow/.local/lib/python3.7/site-packages/airflow/models/taskinstance.py", line 1910, in handle_failure
    self.email_alert(error, task)
  File "/home/airflow/.local/lib/python3.7/site-packages/airflow/models/taskinstance.py", line 2320, in email_alert
    send_email(task.email, subject, html_content_err)
  File "/home/airflow/.local/lib/python3.7/site-packages/airflow/utils/email.py", line 91, in send_email
    **kwargs,
  File "/home/airflow/.local/lib/python3.7/site-packages/airflow/utils/email.py", line 152, in send_email_smtp
    send_mime_email(e_from=mail_from, e_to=recipients, mime_msg=msg, conn_id=conn_id, dryrun=dryrun)
  File "/home/airflow/.local/lib/python3.7/site-packages/airflow/utils/email.py", line 270, in send_mime_email
    smtp_conn = _get_smtp_connection(smtp_host, smtp_port, smtp_timeout, smtp_ssl)
  File "/home/airflow/.local/lib/python3.7/site-packages/airflow/utils/email.py", line 317, in _get_smtp_connection
    else smtplib.SMTP(host=host, port=port, timeout=timeout)
  File "/usr/local/lib/python3.7/smtplib.py", line 251, in __init__
    (code, msg) = self.connect(host, port)
  File "/usr/local/lib/python3.7/smtplib.py", line 336, in connect
    self.sock = self._get_socket(host, port, self.timeout)
  File "/usr/local/lib/python3.7/smtplib.py", line 307, in _get_socket
    self.source_address)
  File "/usr/local/lib/python3.7/socket.py", line 728, in create_connection
    raise err
  File "/usr/local/lib/python3.7/socket.py", line 716, in create_connection
    sock.connect(sa)
OSError: [Errno 99] Cannot assign requested address
[2023-05-18T04:44:07.744+0000] {standard_task_runner.py:109} ERROR - Failed to execute job 66 for task visualize_data ('explode' must be of length 'x'; 2092)
[2023-05-18T04:44:07.780+0000] {local_task_job_runner.py:232} INFO - Task exited with return code 1
[2023-05-18T04:44:07.798+0000] {taskinstance.py:2674} INFO - 0 downstream tasks scheduled from follow-on schedule check
