[2023-05-18T04:28:28.601+0000] {taskinstance.py:1125} INFO - Dependencies all met for dep_context=non-requeueable deps ti=<TaskInstance: fondue_dag.visualize_data scheduled__2023-05-17T00:00:00+00:00 [queued]>
[2023-05-18T04:28:28.621+0000] {taskinstance.py:1125} INFO - Dependencies all met for dep_context=requeueable deps ti=<TaskInstance: fondue_dag.visualize_data scheduled__2023-05-17T00:00:00+00:00 [queued]>
[2023-05-18T04:28:28.622+0000] {taskinstance.py:1331} INFO - Starting attempt 2 of 2
[2023-05-18T04:28:28.705+0000] {taskinstance.py:1350} INFO - Executing <Task(PythonOperator): visualize_data> on 2023-05-17 00:00:00+00:00
[2023-05-18T04:28:28.730+0000] {standard_task_runner.py:57} INFO - Started process 1240 to run task
[2023-05-18T04:28:28.752+0000] {standard_task_runner.py:84} INFO - Running: ['***', 'tasks', 'run', 'fondue_dag', 'visualize_data', 'scheduled__2023-05-17T00:00:00+00:00', '--job-id', '48', '--raw', '--subdir', 'DAGS_FOLDER/fondue_dag.py', '--cfg-path', '/tmp/tmp7_s7jxq5']
[2023-05-18T04:28:28.758+0000] {standard_task_runner.py:85} INFO - Job 48: Subtask visualize_data
[2023-05-18T04:28:28.869+0000] {task_command.py:410} INFO - Running <TaskInstance: fondue_dag.visualize_data scheduled__2023-05-17T00:00:00+00:00 [running]> on host b36de7cfc389
[2023-05-18T04:28:29.058+0000] {taskinstance.py:1570} INFO - Exporting env vars: AIRFLOW_CTX_DAG_EMAIL='Bhuribhat@gmail.com' AIRFLOW_CTX_DAG_OWNER='pras' AIRFLOW_CTX_DAG_ID='fondue_dag' AIRFLOW_CTX_TASK_ID='visualize_data' AIRFLOW_CTX_EXECUTION_DATE='2023-05-17T00:00:00+00:00' AIRFLOW_CTX_TRY_NUMBER='2' AIRFLOW_CTX_DAG_RUN_ID='scheduled__2023-05-17T00:00:00+00:00'
[2023-05-18T04:28:29.063+0000] {taskinstance.py:1847} ERROR - Task failed with exception
Traceback (most recent call last):
  File "/home/airflow/.local/lib/python3.7/site-packages/airflow/operators/python.py", line 181, in execute
    return_value = self.execute_callable()
  File "/home/airflow/.local/lib/python3.7/site-packages/airflow/operators/python.py", line 198, in execute_callable
    return self.python_callable(*self.op_args, **self.op_kwargs)
  File "/opt/airflow/dags/utils/visualize.py", line 189, in visualize_data
    geospatial_visualize()
  File "/opt/airflow/dags/utils/visualize.py", line 78, in geospatial_visualize
    df = load_files(['data_cleaned_by_length'])[0]
IndexError: list index out of range
[2023-05-18T04:28:29.155+0000] {taskinstance.py:1373} INFO - Marking task as FAILED. dag_id=fondue_dag, task_id=visualize_data, execution_date=20230517T000000, start_date=20230518T042828, end_date=20230518T042829
[2023-05-18T04:28:29.180+0000] {standard_task_runner.py:109} ERROR - Failed to execute job 48 for task visualize_data (list index out of range; 1240)
[2023-05-18T04:28:29.215+0000] {local_task_job_runner.py:232} INFO - Task exited with return code 1
[2023-05-18T04:28:29.267+0000] {taskinstance.py:2674} INFO - 0 downstream tasks scheduled from follow-on schedule check
