[2023-05-16T07:06:05.175+0000] {taskinstance.py:1125} INFO - Dependencies all met for dep_context=non-requeueable deps ti=<TaskInstance: fondue_dag.clean_fondue_data scheduled__2023-05-13T00:00:00+00:00 [queued]>
[2023-05-16T07:06:05.197+0000] {taskinstance.py:1125} INFO - Dependencies all met for dep_context=requeueable deps ti=<TaskInstance: fondue_dag.clean_fondue_data scheduled__2023-05-13T00:00:00+00:00 [queued]>
[2023-05-16T07:06:05.199+0000] {taskinstance.py:1331} INFO - Starting attempt 1 of 2
[2023-05-16T07:06:05.301+0000] {taskinstance.py:1350} INFO - Executing <Task(PythonOperator): clean_fondue_data> on 2023-05-13 00:00:00+00:00
[2023-05-16T07:06:05.327+0000] {standard_task_runner.py:57} INFO - Started process 331 to run task
[2023-05-16T07:06:05.334+0000] {standard_task_runner.py:84} INFO - Running: ['***', 'tasks', 'run', 'fondue_dag', 'clean_fondue_data', 'scheduled__2023-05-13T00:00:00+00:00', '--job-id', '16', '--raw', '--subdir', 'DAGS_FOLDER/fondue_dag.py', '--cfg-path', '/tmp/tmplh1uqlc1']
[2023-05-16T07:06:05.351+0000] {standard_task_runner.py:85} INFO - Job 16: Subtask clean_fondue_data
[2023-05-16T07:06:05.577+0000] {task_command.py:410} INFO - Running <TaskInstance: fondue_dag.clean_fondue_data scheduled__2023-05-13T00:00:00+00:00 [running]> on host a76a3b1a3408
[2023-05-16T07:06:05.871+0000] {taskinstance.py:1570} INFO - Exporting env vars: AIRFLOW_CTX_DAG_EMAIL='Bhuribhat@gmail.com' AIRFLOW_CTX_DAG_OWNER='pras' AIRFLOW_CTX_DAG_ID='fondue_dag' AIRFLOW_CTX_TASK_ID='clean_fondue_data' AIRFLOW_CTX_EXECUTION_DATE='2023-05-13T00:00:00+00:00' AIRFLOW_CTX_TRY_NUMBER='1' AIRFLOW_CTX_DAG_RUN_ID='scheduled__2023-05-13T00:00:00+00:00'
[2023-05-16T07:06:05.987+0000] {taskinstance.py:1847} ERROR - Task failed with exception
Traceback (most recent call last):
  File "/home/airflow/.local/lib/python3.7/site-packages/airflow/operators/python.py", line 181, in execute
    return_value = self.execute_callable()
  File "/home/airflow/.local/lib/python3.7/site-packages/airflow/operators/python.py", line 198, in execute_callable
    return self.python_callable(*self.op_args, **self.op_kwargs)
  File "/opt/airflow/dags/utils/clean_data.py", line 14, in clean_data
    df.drop(drop_col, axis=1, inplace=True)
  File "/home/airflow/.local/lib/python3.7/site-packages/pandas/util/_decorators.py", line 311, in wrapper
    return func(*args, **kwargs)
  File "/home/airflow/.local/lib/python3.7/site-packages/pandas/core/frame.py", line 4913, in drop
    errors=errors,
  File "/home/airflow/.local/lib/python3.7/site-packages/pandas/core/generic.py", line 4150, in drop
    obj = obj._drop_axis(labels, axis, level=level, errors=errors)
  File "/home/airflow/.local/lib/python3.7/site-packages/pandas/core/generic.py", line 4185, in _drop_axis
    new_axis = axis.drop(labels, errors=errors)
  File "/home/airflow/.local/lib/python3.7/site-packages/pandas/core/indexes/base.py", line 6017, in drop
    raise KeyError(f"{labels[mask]} not found in axis")
KeyError: "['comment' 'photo' 'photo_after' 'organization'] not found in axis"
[2023-05-16T07:06:06.044+0000] {taskinstance.py:1373} INFO - Marking task as UP_FOR_RETRY. dag_id=fondue_dag, task_id=clean_fondue_data, execution_date=20230513T000000, start_date=20230516T070605, end_date=20230516T070606
[2023-05-16T07:06:06.087+0000] {logging_mixin.py:149} WARNING - /home/***/.local/lib/python3.7/site-packages/***/utils/email.py:152 RemovedInAirflow3Warning: Fetching SMTP credentials from configuration variables will be deprecated in a future release. Please set credentials using a connection instead.
[2023-05-16T07:06:06.091+0000] {configuration.py:675} WARNING - section/key [smtp/smtp_user] not found in config
[2023-05-16T07:06:06.092+0000] {email.py:268} INFO - Email alerting: attempt 1
[2023-05-16T07:06:06.103+0000] {configuration.py:675} WARNING - section/key [smtp/smtp_user] not found in config
[2023-05-16T07:06:06.106+0000] {email.py:268} INFO - Email alerting: attempt 1
[2023-05-16T07:06:06.107+0000] {taskinstance.py:1912} ERROR - Failed to send email to: ['Bhuribhat@gmail.com']
Traceback (most recent call last):
  File "/home/airflow/.local/lib/python3.7/site-packages/airflow/models/taskinstance.py", line 1430, in _run_raw_task
    self._execute_task_with_callbacks(context, test_mode)
  File "/home/airflow/.local/lib/python3.7/site-packages/airflow/models/taskinstance.py", line 1581, in _execute_task_with_callbacks
    result = self._execute_task(context, task_orig)
  File "/home/airflow/.local/lib/python3.7/site-packages/airflow/models/taskinstance.py", line 1651, in _execute_task
    result = execute_callable(context=context)
  File "/home/airflow/.local/lib/python3.7/site-packages/airflow/operators/python.py", line 181, in execute
    return_value = self.execute_callable()
  File "/home/airflow/.local/lib/python3.7/site-packages/airflow/operators/python.py", line 198, in execute_callable
    return self.python_callable(*self.op_args, **self.op_kwargs)
  File "/opt/airflow/dags/utils/clean_data.py", line 14, in clean_data
    df.drop(drop_col, axis=1, inplace=True)
  File "/home/airflow/.local/lib/python3.7/site-packages/pandas/util/_decorators.py", line 311, in wrapper
    return func(*args, **kwargs)
  File "/home/airflow/.local/lib/python3.7/site-packages/pandas/core/frame.py", line 4913, in drop
    errors=errors,
  File "/home/airflow/.local/lib/python3.7/site-packages/pandas/core/generic.py", line 4150, in drop
    obj = obj._drop_axis(labels, axis, level=level, errors=errors)
  File "/home/airflow/.local/lib/python3.7/site-packages/pandas/core/generic.py", line 4185, in _drop_axis
    new_axis = axis.drop(labels, errors=errors)
  File "/home/airflow/.local/lib/python3.7/site-packages/pandas/core/indexes/base.py", line 6017, in drop
    raise KeyError(f"{labels[mask]} not found in axis")
KeyError: "['comment' 'photo' 'photo_after' 'organization'] not found in axis"

During handling of the above exception, another exception occurred:

Traceback (most recent call last):
  File "/home/airflow/.local/lib/python3.7/site-packages/airflow/models/taskinstance.py", line 2318, in email_alert
    send_email(task.email, subject, html_content)
  File "/home/airflow/.local/lib/python3.7/site-packages/airflow/utils/email.py", line 91, in send_email
    **kwargs,
  File "/home/airflow/.local/lib/python3.7/site-packages/airflow/utils/email.py", line 152, in send_email_smtp
    send_mime_email(e_from=mail_from, e_to=recipients, mime_msg=msg, conn_id=conn_id, dryrun=dryrun)
  File "/home/airflow/.local/lib/python3.7/site-packages/airflow/utils/email.py", line 270, in send_mime_email
    smtp_conn = _get_smtp_connection(smtp_host, smtp_port, smtp_timeout, smtp_ssl)
  File "/home/airflow/.local/lib/python3.7/site-packages/airflow/utils/email.py", line 317, in _get_smtp_connection
    else smtplib.SMTP(host=host, port=port, timeout=timeout)
  File "/usr/local/lib/python3.7/smtplib.py", line 251, in __init__
    (code, msg) = self.connect(host, port)
  File "/usr/local/lib/python3.7/smtplib.py", line 336, in connect
    self.sock = self._get_socket(host, port, self.timeout)
  File "/usr/local/lib/python3.7/smtplib.py", line 307, in _get_socket
    self.source_address)
  File "/usr/local/lib/python3.7/socket.py", line 728, in create_connection
    raise err
  File "/usr/local/lib/python3.7/socket.py", line 716, in create_connection
    sock.connect(sa)
OSError: [Errno 99] Cannot assign requested address

During handling of the above exception, another exception occurred:

Traceback (most recent call last):
  File "/home/airflow/.local/lib/python3.7/site-packages/airflow/models/taskinstance.py", line 1910, in handle_failure
    self.email_alert(error, task)
  File "/home/airflow/.local/lib/python3.7/site-packages/airflow/models/taskinstance.py", line 2320, in email_alert
    send_email(task.email, subject, html_content_err)
  File "/home/airflow/.local/lib/python3.7/site-packages/airflow/utils/email.py", line 91, in send_email
    **kwargs,
  File "/home/airflow/.local/lib/python3.7/site-packages/airflow/utils/email.py", line 152, in send_email_smtp
    send_mime_email(e_from=mail_from, e_to=recipients, mime_msg=msg, conn_id=conn_id, dryrun=dryrun)
  File "/home/airflow/.local/lib/python3.7/site-packages/airflow/utils/email.py", line 270, in send_mime_email
    smtp_conn = _get_smtp_connection(smtp_host, smtp_port, smtp_timeout, smtp_ssl)
  File "/home/airflow/.local/lib/python3.7/site-packages/airflow/utils/email.py", line 317, in _get_smtp_connection
    else smtplib.SMTP(host=host, port=port, timeout=timeout)
  File "/usr/local/lib/python3.7/smtplib.py", line 251, in __init__
    (code, msg) = self.connect(host, port)
  File "/usr/local/lib/python3.7/smtplib.py", line 336, in connect
    self.sock = self._get_socket(host, port, self.timeout)
  File "/usr/local/lib/python3.7/smtplib.py", line 307, in _get_socket
    self.source_address)
  File "/usr/local/lib/python3.7/socket.py", line 728, in create_connection
    raise err
  File "/usr/local/lib/python3.7/socket.py", line 716, in create_connection
    sock.connect(sa)
OSError: [Errno 99] Cannot assign requested address
[2023-05-16T07:06:06.164+0000] {standard_task_runner.py:109} ERROR - Failed to execute job 16 for task clean_fondue_data ("['comment' 'photo' 'photo_after' 'organization'] not found in axis"; 331)
[2023-05-16T07:06:06.221+0000] {local_task_job_runner.py:232} INFO - Task exited with return code 1
[2023-05-16T07:06:06.289+0000] {taskinstance.py:2674} INFO - 0 downstream tasks scheduled from follow-on schedule check
