[2023-05-17T16:51:44.082+0000] {taskinstance.py:1125} INFO - Dependencies all met for dep_context=non-requeueable deps ti=<TaskInstance: fondue_dag.visualize_data scheduled__2023-05-09T00:00:00+00:00 [queued]>
[2023-05-17T16:51:44.093+0000] {taskinstance.py:1125} INFO - Dependencies all met for dep_context=requeueable deps ti=<TaskInstance: fondue_dag.visualize_data scheduled__2023-05-09T00:00:00+00:00 [queued]>
[2023-05-17T16:51:44.093+0000] {taskinstance.py:1331} INFO - Starting attempt 2 of 2
[2023-05-17T16:51:44.110+0000] {taskinstance.py:1350} INFO - Executing <Task(PythonOperator): visualize_data> on 2023-05-09 00:00:00+00:00
[2023-05-17T16:51:44.117+0000] {standard_task_runner.py:57} INFO - Started process 3346 to run task
[2023-05-17T16:51:44.120+0000] {standard_task_runner.py:84} INFO - Running: ['***', 'tasks', 'run', 'fondue_dag', 'visualize_data', 'scheduled__2023-05-09T00:00:00+00:00', '--job-id', '53', '--raw', '--subdir', 'DAGS_FOLDER/fondue_dag.py', '--cfg-path', '/tmp/tmpyra4vrt3']
[2023-05-17T16:51:44.122+0000] {standard_task_runner.py:85} INFO - Job 53: Subtask visualize_data
[2023-05-17T16:51:44.178+0000] {task_command.py:410} INFO - Running <TaskInstance: fondue_dag.visualize_data scheduled__2023-05-09T00:00:00+00:00 [running]> on host 8cf8fb9e28f7
[2023-05-17T16:51:44.272+0000] {taskinstance.py:1570} INFO - Exporting env vars: AIRFLOW_CTX_DAG_EMAIL='Bhuribhat@gmail.com' AIRFLOW_CTX_DAG_OWNER='pras' AIRFLOW_CTX_DAG_ID='fondue_dag' AIRFLOW_CTX_TASK_ID='visualize_data' AIRFLOW_CTX_EXECUTION_DATE='2023-05-09T00:00:00+00:00' AIRFLOW_CTX_TRY_NUMBER='2' AIRFLOW_CTX_DAG_RUN_ID='scheduled__2023-05-09T00:00:00+00:00'
[2023-05-17T16:51:44.424+0000] {font_manager.py:1352} WARNING - findfont: Font family ['TH Sarabun Chula'] not found. Falling back to DejaVu Sans.
[2023-05-17T16:51:44.432+0000] {font_manager.py:1352} WARNING - findfont: Font family ['TH Sarabun Chula'] not found. Falling back to DejaVu Sans.
[2023-05-17T16:51:45.258+0000] {taskinstance.py:1847} ERROR - Task failed with exception
Traceback (most recent call last):
  File "/home/airflow/.local/lib/python3.7/site-packages/pandas/core/indexes/base.py", line 3361, in get_loc
    return self._engine.get_loc(casted_key)
  File "pandas/_libs/index.pyx", line 76, in pandas._libs.index.IndexEngine.get_loc
  File "pandas/_libs/index.pyx", line 108, in pandas._libs.index.IndexEngine.get_loc
  File "pandas/_libs/hashtable_class_helper.pxi", line 5198, in pandas._libs.hashtable.PyObjectHashTable.get_item
  File "pandas/_libs/hashtable_class_helper.pxi", line 5206, in pandas._libs.hashtable.PyObjectHashTable.get_item
KeyError: 'district'

The above exception was the direct cause of the following exception:

Traceback (most recent call last):
  File "/home/airflow/.local/lib/python3.7/site-packages/airflow/operators/python.py", line 181, in execute
    return_value = self.execute_callable()
  File "/home/airflow/.local/lib/python3.7/site-packages/airflow/operators/python.py", line 198, in execute_callable
    return self.python_callable(*self.op_args, **self.op_kwargs)
  File "/opt/airflow/dags/utils/visualize.py", line 196, in visualize_data
    plot_cluster_by_problems(broke_map)
  File "/opt/airflow/dags/utils/visualize.py", line 129, in plot_cluster_by_problems
    information += f"<br>District: {row['district']}<br>State: {row['state']}<br>Timestamp: {row['timestamp']}"
  File "/home/airflow/.local/lib/python3.7/site-packages/pandas/core/series.py", line 942, in __getitem__
    return self._get_value(key)
  File "/home/airflow/.local/lib/python3.7/site-packages/pandas/core/series.py", line 1051, in _get_value
    loc = self.index.get_loc(label)
  File "/home/airflow/.local/lib/python3.7/site-packages/pandas/core/indexes/base.py", line 3363, in get_loc
    raise KeyError(key) from err
KeyError: 'district'
[2023-05-17T16:51:45.276+0000] {taskinstance.py:1373} INFO - Marking task as FAILED. dag_id=fondue_dag, task_id=visualize_data, execution_date=20230509T000000, start_date=20230517T165144, end_date=20230517T165145
[2023-05-17T16:51:45.391+0000] {standard_task_runner.py:109} ERROR - Failed to execute job 53 for task visualize_data ('district'; 3346)
[2023-05-17T16:51:45.417+0000] {local_task_job_runner.py:232} INFO - Task exited with return code 1
[2023-05-17T16:51:45.434+0000] {taskinstance.py:2674} INFO - 0 downstream tasks scheduled from follow-on schedule check
[2023-05-18T04:28:29.344+0000] {logging_mixin.py:149} INFO - Changing /opt/***/logs/dag_id=fondue_dag/run_id=scheduled__2023-05-09T00:00:00+00:00/task_id=visualize_data permission to 509
[2023-05-18T04:28:29.346+0000] {logging_mixin.py:149} INFO - Failed to change /opt/***/logs/dag_id=fondue_dag/run_id=scheduled__2023-05-09T00:00:00+00:00/task_id=visualize_data permission to 509: [Errno 1] Operation not permitted: '/opt/***/logs/dag_id=fondue_dag/run_id=scheduled__2023-05-09T00:00:00+00:00/task_id=visualize_data'
[2023-05-18T04:28:29.403+0000] {logging_mixin.py:149} INFO - Changing /opt/***/logs/dag_id=fondue_dag/run_id=scheduled__2023-05-09T00:00:00+00:00/task_id=visualize_data permission to 509
[2023-05-18T04:28:29.404+0000] {logging_mixin.py:149} INFO - Failed to change /opt/***/logs/dag_id=fondue_dag/run_id=scheduled__2023-05-09T00:00:00+00:00/task_id=visualize_data permission to 509: [Errno 1] Operation not permitted: '/opt/***/logs/dag_id=fondue_dag/run_id=scheduled__2023-05-09T00:00:00+00:00/task_id=visualize_data'
[2023-05-18T04:28:29.444+0000] {taskinstance.py:1125} INFO - Dependencies all met for dep_context=non-requeueable deps ti=<TaskInstance: fondue_dag.visualize_data scheduled__2023-05-09T00:00:00+00:00 [queued]>
[2023-05-18T04:28:29.464+0000] {taskinstance.py:1125} INFO - Dependencies all met for dep_context=requeueable deps ti=<TaskInstance: fondue_dag.visualize_data scheduled__2023-05-09T00:00:00+00:00 [queued]>
[2023-05-18T04:28:29.466+0000] {taskinstance.py:1331} INFO - Starting attempt 2 of 2
[2023-05-18T04:28:29.489+0000] {taskinstance.py:1350} INFO - Executing <Task(PythonOperator): visualize_data> on 2023-05-09 00:00:00+00:00
[2023-05-18T04:28:29.499+0000] {standard_task_runner.py:57} INFO - Started process 1247 to run task
[2023-05-18T04:28:29.502+0000] {standard_task_runner.py:84} INFO - Running: ['***', 'tasks', 'run', 'fondue_dag', 'visualize_data', 'scheduled__2023-05-09T00:00:00+00:00', '--job-id', '56', '--raw', '--subdir', 'DAGS_FOLDER/fondue_dag.py', '--cfg-path', '/tmp/tmprtc9gekn']
[2023-05-18T04:28:29.504+0000] {standard_task_runner.py:85} INFO - Job 56: Subtask visualize_data
[2023-05-18T04:28:29.572+0000] {logging_mixin.py:149} INFO - Changing /opt/***/logs/dag_id=fondue_dag/run_id=scheduled__2023-05-09T00:00:00+00:00/task_id=visualize_data permission to 509
[2023-05-18T04:28:29.574+0000] {logging_mixin.py:149} INFO - Failed to change /opt/***/logs/dag_id=fondue_dag/run_id=scheduled__2023-05-09T00:00:00+00:00/task_id=visualize_data permission to 509: [Errno 1] Operation not permitted: '/opt/***/logs/dag_id=fondue_dag/run_id=scheduled__2023-05-09T00:00:00+00:00/task_id=visualize_data'
[2023-05-18T04:28:29.577+0000] {task_command.py:410} INFO - Running <TaskInstance: fondue_dag.visualize_data scheduled__2023-05-09T00:00:00+00:00 [running]> on host b36de7cfc389
[2023-05-18T04:28:29.686+0000] {taskinstance.py:1570} INFO - Exporting env vars: AIRFLOW_CTX_DAG_EMAIL='Bhuribhat@gmail.com' AIRFLOW_CTX_DAG_OWNER='pras' AIRFLOW_CTX_DAG_ID='fondue_dag' AIRFLOW_CTX_TASK_ID='visualize_data' AIRFLOW_CTX_EXECUTION_DATE='2023-05-09T00:00:00+00:00' AIRFLOW_CTX_TRY_NUMBER='2' AIRFLOW_CTX_DAG_RUN_ID='scheduled__2023-05-09T00:00:00+00:00'
[2023-05-18T04:28:29.688+0000] {taskinstance.py:1847} ERROR - Task failed with exception
Traceback (most recent call last):
  File "/home/airflow/.local/lib/python3.7/site-packages/airflow/operators/python.py", line 181, in execute
    return_value = self.execute_callable()
  File "/home/airflow/.local/lib/python3.7/site-packages/airflow/operators/python.py", line 198, in execute_callable
    return self.python_callable(*self.op_args, **self.op_kwargs)
  File "/opt/airflow/dags/utils/visualize.py", line 189, in visualize_data
    geospatial_visualize()
  File "/opt/airflow/dags/utils/visualize.py", line 78, in geospatial_visualize
    df = load_files(['data_cleaned_by_length'])[0]
IndexError: list index out of range
[2023-05-18T04:28:29.701+0000] {taskinstance.py:1373} INFO - Marking task as FAILED. dag_id=fondue_dag, task_id=visualize_data, execution_date=20230509T000000, start_date=20230518T042829, end_date=20230518T042829
[2023-05-18T04:28:29.714+0000] {standard_task_runner.py:109} ERROR - Failed to execute job 56 for task visualize_data (list index out of range; 1247)
[2023-05-18T04:28:29.755+0000] {local_task_job_runner.py:232} INFO - Task exited with return code 1
[2023-05-18T04:28:29.773+0000] {taskinstance.py:2674} INFO - 0 downstream tasks scheduled from follow-on schedule check
