[2023-05-17T16:46:19.144+0000] {taskinstance.py:1125} INFO - Dependencies all met for dep_context=non-requeueable deps ti=<TaskInstance: fondue_dag.clustering scheduled__2023-05-13T00:00:00+00:00 [queued]>
[2023-05-17T16:46:19.164+0000] {taskinstance.py:1125} INFO - Dependencies all met for dep_context=requeueable deps ti=<TaskInstance: fondue_dag.clustering scheduled__2023-05-13T00:00:00+00:00 [queued]>
[2023-05-17T16:46:19.165+0000] {taskinstance.py:1331} INFO - Starting attempt 1 of 2
[2023-05-17T16:46:19.194+0000] {taskinstance.py:1350} INFO - Executing <Task(PythonOperator): clustering> on 2023-05-13 00:00:00+00:00
[2023-05-17T16:46:19.209+0000] {standard_task_runner.py:57} INFO - Started process 1207 to run task
[2023-05-17T16:46:19.215+0000] {standard_task_runner.py:84} INFO - Running: ['***', 'tasks', 'run', 'fondue_dag', 'clustering', 'scheduled__2023-05-13T00:00:00+00:00', '--job-id', '27', '--raw', '--subdir', 'DAGS_FOLDER/fondue_dag.py', '--cfg-path', '/tmp/tmp84tp014y']
[2023-05-17T16:46:19.218+0000] {standard_task_runner.py:85} INFO - Job 27: Subtask clustering
[2023-05-17T16:46:19.300+0000] {task_command.py:410} INFO - Running <TaskInstance: fondue_dag.clustering scheduled__2023-05-13T00:00:00+00:00 [running]> on host 8cf8fb9e28f7
[2023-05-17T16:46:19.479+0000] {taskinstance.py:1570} INFO - Exporting env vars: AIRFLOW_CTX_DAG_EMAIL='Bhuribhat@gmail.com' AIRFLOW_CTX_DAG_OWNER='pras' AIRFLOW_CTX_DAG_ID='fondue_dag' AIRFLOW_CTX_TASK_ID='clustering' AIRFLOW_CTX_EXECUTION_DATE='2023-05-13T00:00:00+00:00' AIRFLOW_CTX_TRY_NUMBER='1' AIRFLOW_CTX_DAG_RUN_ID='scheduled__2023-05-13T00:00:00+00:00'
[2023-05-17T16:46:21.401+0000] {logging_mixin.py:149} WARNING - 2023/05/17 16:46:21 INFO mlflow.tracking.fluent: Experiment with name 'fondue' does not exist. Creating a new experiment.
[2023-05-17T16:46:21.603+0000] {logging_mixin.py:149} WARNING - 2023/05/17 16:46:21 WARNING mlflow.utils.git_utils: Failed to import Git (the Git executable is probably not on your PATH), so Git SHA is not available. Error: Failed to initialize: Bad git executable.
The git executable must be specified in one of the following ways:
    - be included in your $PATH
    - be set via $GIT_PYTHON_GIT_EXECUTABLE
    - explicitly set via git.refresh()

All git commands will error until this is rectified.

This initial warning can be silenced or aggravated in the future by setting the
$GIT_PYTHON_REFRESH environment variable. Use one of the following values:
    - quiet|q|silence|s|none|n|0: for no warning or exception
    - warn|w|warning|1: for a printed warning
    - error|e|raise|r|2: for a raised exception

Example:
    export GIT_PYTHON_REFRESH=quiet
[2023-05-17T16:46:28.574+0000] {python.py:183} INFO - Done. Returned value was: None
[2023-05-17T16:46:28.605+0000] {taskinstance.py:1373} INFO - Marking task as SUCCESS. dag_id=fondue_dag, task_id=clustering, execution_date=20230513T000000, start_date=20230517T164619, end_date=20230517T164628
[2023-05-17T16:46:28.692+0000] {local_task_job_runner.py:232} INFO - Task exited with return code 0
[2023-05-17T16:46:28.745+0000] {taskinstance.py:2674} INFO - 1 downstream tasks scheduled from follow-on schedule check
<<<<<<< HEAD
[2023-05-17T17:55:07.840+0000] {taskinstance.py:1125} INFO - Dependencies all met for dep_context=non-requeueable deps ti=<TaskInstance: fondue_dag.clustering scheduled__2023-05-13T00:00:00+00:00 [queued]>
[2023-05-17T17:55:07.861+0000] {taskinstance.py:1125} INFO - Dependencies all met for dep_context=requeueable deps ti=<TaskInstance: fondue_dag.clustering scheduled__2023-05-13T00:00:00+00:00 [queued]>
[2023-05-17T17:55:07.862+0000] {taskinstance.py:1331} INFO - Starting attempt 1 of 2
[2023-05-17T17:55:07.910+0000] {taskinstance.py:1350} INFO - Executing <Task(PythonOperator): clustering> on 2023-05-13 00:00:00+00:00
[2023-05-17T17:55:07.927+0000] {standard_task_runner.py:57} INFO - Started process 957 to run task
[2023-05-17T17:55:07.958+0000] {standard_task_runner.py:84} INFO - Running: ['***', 'tasks', 'run', 'fondue_dag', 'clustering', 'scheduled__2023-05-13T00:00:00+00:00', '--job-id', '36', '--raw', '--subdir', 'DAGS_FOLDER/fondue_dag.py', '--cfg-path', '/tmp/tmp8dflzdb5']
[2023-05-17T17:55:07.969+0000] {standard_task_runner.py:85} INFO - Job 36: Subtask clustering
[2023-05-17T17:55:08.080+0000] {task_command.py:410} INFO - Running <TaskInstance: fondue_dag.clustering scheduled__2023-05-13T00:00:00+00:00 [running]> on host a37c7bc3731c
[2023-05-17T17:55:08.310+0000] {taskinstance.py:1570} INFO - Exporting env vars: AIRFLOW_CTX_DAG_EMAIL='Bhuribhat@gmail.com' AIRFLOW_CTX_DAG_OWNER='pras' AIRFLOW_CTX_DAG_ID='fondue_dag' AIRFLOW_CTX_TASK_ID='clustering' AIRFLOW_CTX_EXECUTION_DATE='2023-05-13T00:00:00+00:00' AIRFLOW_CTX_TRY_NUMBER='1' AIRFLOW_CTX_DAG_RUN_ID='scheduled__2023-05-13T00:00:00+00:00'
[2023-05-17T17:55:30.099+0000] {logging_mixin.py:149} WARNING - 2023/05/17 17:55:30 WARNING mlflow.utils.git_utils: Failed to import Git (the Git executable is probably not on your PATH), so Git SHA is not available. Error: Failed to initialize: Bad git executable.
=======
[2023-05-18T04:22:23.031+0000] {logging_mixin.py:149} INFO - Changing /opt/***/logs/dag_id=fondue_dag/run_id=scheduled__2023-05-13T00:00:00+00:00/task_id=clustering permission to 509
[2023-05-18T04:22:23.033+0000] {logging_mixin.py:149} INFO - Failed to change /opt/***/logs/dag_id=fondue_dag/run_id=scheduled__2023-05-13T00:00:00+00:00/task_id=clustering permission to 509: [Errno 1] Operation not permitted: '/opt/***/logs/dag_id=fondue_dag/run_id=scheduled__2023-05-13T00:00:00+00:00/task_id=clustering'
[2023-05-18T04:22:23.191+0000] {logging_mixin.py:149} INFO - Changing /opt/***/logs/dag_id=fondue_dag/run_id=scheduled__2023-05-13T00:00:00+00:00/task_id=clustering permission to 509
[2023-05-18T04:22:23.192+0000] {logging_mixin.py:149} INFO - Failed to change /opt/***/logs/dag_id=fondue_dag/run_id=scheduled__2023-05-13T00:00:00+00:00/task_id=clustering permission to 509: [Errno 1] Operation not permitted: '/opt/***/logs/dag_id=fondue_dag/run_id=scheduled__2023-05-13T00:00:00+00:00/task_id=clustering'
[2023-05-18T04:22:23.245+0000] {taskinstance.py:1125} INFO - Dependencies all met for dep_context=non-requeueable deps ti=<TaskInstance: fondue_dag.clustering scheduled__2023-05-13T00:00:00+00:00 [queued]>
[2023-05-18T04:22:23.271+0000] {taskinstance.py:1125} INFO - Dependencies all met for dep_context=requeueable deps ti=<TaskInstance: fondue_dag.clustering scheduled__2023-05-13T00:00:00+00:00 [queued]>
[2023-05-18T04:22:23.272+0000] {taskinstance.py:1331} INFO - Starting attempt 1 of 2
[2023-05-18T04:22:23.328+0000] {taskinstance.py:1350} INFO - Executing <Task(PythonOperator): clustering> on 2023-05-13 00:00:00+00:00
[2023-05-18T04:22:23.342+0000] {standard_task_runner.py:57} INFO - Started process 572 to run task
[2023-05-18T04:22:23.351+0000] {standard_task_runner.py:84} INFO - Running: ['***', 'tasks', 'run', 'fondue_dag', 'clustering', 'scheduled__2023-05-13T00:00:00+00:00', '--job-id', '33', '--raw', '--subdir', 'DAGS_FOLDER/fondue_dag.py', '--cfg-path', '/tmp/tmpoo9uhg9p']
[2023-05-18T04:22:23.354+0000] {standard_task_runner.py:85} INFO - Job 33: Subtask clustering
[2023-05-18T04:22:23.512+0000] {logging_mixin.py:149} INFO - Changing /opt/***/logs/dag_id=fondue_dag/run_id=scheduled__2023-05-13T00:00:00+00:00/task_id=clustering permission to 509
[2023-05-18T04:22:23.514+0000] {logging_mixin.py:149} INFO - Failed to change /opt/***/logs/dag_id=fondue_dag/run_id=scheduled__2023-05-13T00:00:00+00:00/task_id=clustering permission to 509: [Errno 1] Operation not permitted: '/opt/***/logs/dag_id=fondue_dag/run_id=scheduled__2023-05-13T00:00:00+00:00/task_id=clustering'
[2023-05-18T04:22:23.519+0000] {task_command.py:410} INFO - Running <TaskInstance: fondue_dag.clustering scheduled__2023-05-13T00:00:00+00:00 [running]> on host b36de7cfc389
[2023-05-18T04:22:23.766+0000] {taskinstance.py:1570} INFO - Exporting env vars: AIRFLOW_CTX_DAG_EMAIL='Bhuribhat@gmail.com' AIRFLOW_CTX_DAG_OWNER='pras' AIRFLOW_CTX_DAG_ID='fondue_dag' AIRFLOW_CTX_TASK_ID='clustering' AIRFLOW_CTX_EXECUTION_DATE='2023-05-13T00:00:00+00:00' AIRFLOW_CTX_TRY_NUMBER='1' AIRFLOW_CTX_DAG_RUN_ID='scheduled__2023-05-13T00:00:00+00:00'
[2023-05-18T04:23:08.371+0000] {logging_mixin.py:149} WARNING - 2023/05/18 04:23:08 WARNING mlflow.utils.git_utils: Failed to import Git (the Git executable is probably not on your PATH), so Git SHA is not available. Error: Failed to initialize: Bad git executable.
>>>>>>> 8e4a41b368593e9ce283ae02afd6c27252f67370
The git executable must be specified in one of the following ways:
    - be included in your $PATH
    - be set via $GIT_PYTHON_GIT_EXECUTABLE
    - explicitly set via git.refresh()

All git commands will error until this is rectified.

This initial warning can be silenced or aggravated in the future by setting the
$GIT_PYTHON_REFRESH environment variable. Use one of the following values:
    - quiet|q|silence|s|none|n|0: for no warning or exception
    - warn|w|warning|1: for a printed warning
    - error|e|raise|r|2: for a raised exception

Example:
    export GIT_PYTHON_REFRESH=quiet
<<<<<<< HEAD
[2023-05-17T17:55:35.160+0000] {python.py:183} INFO - Done. Returned value was: None
[2023-05-17T17:55:35.175+0000] {taskinstance.py:1373} INFO - Marking task as SUCCESS. dag_id=fondue_dag, task_id=clustering, execution_date=20230513T000000, start_date=20230517T175507, end_date=20230517T175535
[2023-05-17T17:55:35.219+0000] {local_task_job_runner.py:232} INFO - Task exited with return code 0
[2023-05-17T17:55:35.243+0000] {taskinstance.py:2674} INFO - 1 downstream tasks scheduled from follow-on schedule check
[2023-05-17T18:18:26.911+0000] {taskinstance.py:1125} INFO - Dependencies all met for dep_context=non-requeueable deps ti=<TaskInstance: fondue_dag.clustering scheduled__2023-05-13T00:00:00+00:00 [queued]>
[2023-05-17T18:18:26.962+0000] {taskinstance.py:1125} INFO - Dependencies all met for dep_context=requeueable deps ti=<TaskInstance: fondue_dag.clustering scheduled__2023-05-13T00:00:00+00:00 [queued]>
[2023-05-17T18:18:26.964+0000] {taskinstance.py:1331} INFO - Starting attempt 1 of 2
[2023-05-17T18:18:27.037+0000] {taskinstance.py:1350} INFO - Executing <Task(PythonOperator): clustering> on 2023-05-13 00:00:00+00:00
[2023-05-17T18:18:27.046+0000] {standard_task_runner.py:57} INFO - Started process 1125 to run task
[2023-05-17T18:18:27.065+0000] {standard_task_runner.py:84} INFO - Running: ['***', 'tasks', 'run', 'fondue_dag', 'clustering', 'scheduled__2023-05-13T00:00:00+00:00', '--job-id', '34', '--raw', '--subdir', 'DAGS_FOLDER/fondue_dag.py', '--cfg-path', '/tmp/tmp_gcwwm7e']
[2023-05-17T18:18:27.069+0000] {standard_task_runner.py:85} INFO - Job 34: Subtask clustering
[2023-05-17T18:18:27.193+0000] {task_command.py:410} INFO - Running <TaskInstance: fondue_dag.clustering scheduled__2023-05-13T00:00:00+00:00 [running]> on host 3390ff13fbf6
[2023-05-17T18:18:28.210+0000] {taskinstance.py:1570} INFO - Exporting env vars: AIRFLOW_CTX_DAG_EMAIL='Bhuribhat@gmail.com' AIRFLOW_CTX_DAG_OWNER='pras' AIRFLOW_CTX_DAG_ID='fondue_dag' AIRFLOW_CTX_TASK_ID='clustering' AIRFLOW_CTX_EXECUTION_DATE='2023-05-13T00:00:00+00:00' AIRFLOW_CTX_TRY_NUMBER='1' AIRFLOW_CTX_DAG_RUN_ID='scheduled__2023-05-13T00:00:00+00:00'
[2023-05-17T18:18:52.757+0000] {logging_mixin.py:149} WARNING - 2023/05/17 18:18:52 WARNING mlflow.utils.git_utils: Failed to import Git (the Git executable is probably not on your PATH), so Git SHA is not available. Error: Failed to initialize: Bad git executable.
The git executable must be specified in one of the following ways:
    - be included in your $PATH
    - be set via $GIT_PYTHON_GIT_EXECUTABLE
    - explicitly set via git.refresh()

All git commands will error until this is rectified.

This initial warning can be silenced or aggravated in the future by setting the
$GIT_PYTHON_REFRESH environment variable. Use one of the following values:
    - quiet|q|silence|s|none|n|0: for no warning or exception
    - warn|w|warning|1: for a printed warning
    - error|e|raise|r|2: for a raised exception

Example:
    export GIT_PYTHON_REFRESH=quiet
[2023-05-17T18:18:59.328+0000] {python.py:183} INFO - Done. Returned value was: None
[2023-05-17T18:18:59.369+0000] {taskinstance.py:1373} INFO - Marking task as SUCCESS. dag_id=fondue_dag, task_id=clustering, execution_date=20230513T000000, start_date=20230517T181826, end_date=20230517T181859
[2023-05-17T18:18:59.475+0000] {local_task_job_runner.py:232} INFO - Task exited with return code 0
[2023-05-17T18:18:59.533+0000] {taskinstance.py:2674} INFO - 1 downstream tasks scheduled from follow-on schedule check
[2023-05-17T18:25:54.729+0000] {taskinstance.py:1125} INFO - Dependencies all met for dep_context=non-requeueable deps ti=<TaskInstance: fondue_dag.clustering scheduled__2023-05-13T00:00:00+00:00 [queued]>
[2023-05-17T18:25:54.792+0000] {taskinstance.py:1125} INFO - Dependencies all met for dep_context=requeueable deps ti=<TaskInstance: fondue_dag.clustering scheduled__2023-05-13T00:00:00+00:00 [queued]>
[2023-05-17T18:25:54.793+0000] {taskinstance.py:1331} INFO - Starting attempt 1 of 2
[2023-05-17T18:25:54.865+0000] {taskinstance.py:1350} INFO - Executing <Task(PythonOperator): clustering> on 2023-05-13 00:00:00+00:00
[2023-05-17T18:25:54.873+0000] {standard_task_runner.py:57} INFO - Started process 1319 to run task
[2023-05-17T18:25:54.876+0000] {standard_task_runner.py:84} INFO - Running: ['***', 'tasks', 'run', 'fondue_dag', 'clustering', 'scheduled__2023-05-13T00:00:00+00:00', '--job-id', '34', '--raw', '--subdir', 'DAGS_FOLDER/fondue_dag.py', '--cfg-path', '/tmp/tmprpag31q0']
[2023-05-17T18:25:54.892+0000] {standard_task_runner.py:85} INFO - Job 34: Subtask clustering
[2023-05-17T18:25:54.974+0000] {task_command.py:410} INFO - Running <TaskInstance: fondue_dag.clustering scheduled__2023-05-13T00:00:00+00:00 [running]> on host 70fcd41af239
[2023-05-17T18:25:55.141+0000] {taskinstance.py:1570} INFO - Exporting env vars: AIRFLOW_CTX_DAG_EMAIL='Bhuribhat@gmail.com' AIRFLOW_CTX_DAG_OWNER='pras' AIRFLOW_CTX_DAG_ID='fondue_dag' AIRFLOW_CTX_TASK_ID='clustering' AIRFLOW_CTX_EXECUTION_DATE='2023-05-13T00:00:00+00:00' AIRFLOW_CTX_TRY_NUMBER='1' AIRFLOW_CTX_DAG_RUN_ID='scheduled__2023-05-13T00:00:00+00:00'
[2023-05-17T18:26:10.515+0000] {logging_mixin.py:149} WARNING - 2023/05/17 18:26:10 WARNING mlflow.utils.git_utils: Failed to import Git (the Git executable is probably not on your PATH), so Git SHA is not available. Error: Failed to initialize: Bad git executable.
The git executable must be specified in one of the following ways:
    - be included in your $PATH
    - be set via $GIT_PYTHON_GIT_EXECUTABLE
    - explicitly set via git.refresh()

All git commands will error until this is rectified.

This initial warning can be silenced or aggravated in the future by setting the
$GIT_PYTHON_REFRESH environment variable. Use one of the following values:
    - quiet|q|silence|s|none|n|0: for no warning or exception
    - warn|w|warning|1: for a printed warning
    - error|e|raise|r|2: for a raised exception

Example:
    export GIT_PYTHON_REFRESH=quiet
[2023-05-17T18:26:15.721+0000] {python.py:183} INFO - Done. Returned value was: None
[2023-05-17T18:26:15.739+0000] {taskinstance.py:1373} INFO - Marking task as SUCCESS. dag_id=fondue_dag, task_id=clustering, execution_date=20230513T000000, start_date=20230517T182554, end_date=20230517T182615
[2023-05-17T18:26:15.777+0000] {local_task_job_runner.py:232} INFO - Task exited with return code 0
[2023-05-17T18:26:15.813+0000] {taskinstance.py:2674} INFO - 1 downstream tasks scheduled from follow-on schedule check
[2023-05-17T18:37:37.907+0000] {taskinstance.py:1125} INFO - Dependencies all met for dep_context=non-requeueable deps ti=<TaskInstance: fondue_dag.clustering scheduled__2023-05-13T00:00:00+00:00 [queued]>
[2023-05-17T18:37:37.929+0000] {taskinstance.py:1125} INFO - Dependencies all met for dep_context=requeueable deps ti=<TaskInstance: fondue_dag.clustering scheduled__2023-05-13T00:00:00+00:00 [queued]>
[2023-05-17T18:37:37.930+0000] {taskinstance.py:1331} INFO - Starting attempt 1 of 2
[2023-05-17T18:37:37.967+0000] {taskinstance.py:1350} INFO - Executing <Task(PythonOperator): clustering> on 2023-05-13 00:00:00+00:00
[2023-05-17T18:37:37.978+0000] {standard_task_runner.py:57} INFO - Started process 1910 to run task
[2023-05-17T18:37:37.982+0000] {standard_task_runner.py:84} INFO - Running: ['***', 'tasks', 'run', 'fondue_dag', 'clustering', 'scheduled__2023-05-13T00:00:00+00:00', '--job-id', '41', '--raw', '--subdir', 'DAGS_FOLDER/fondue_dag.py', '--cfg-path', '/tmp/tmpibu7ur5i']
[2023-05-17T18:37:37.986+0000] {standard_task_runner.py:85} INFO - Job 41: Subtask clustering
[2023-05-17T18:37:38.046+0000] {task_command.py:410} INFO - Running <TaskInstance: fondue_dag.clustering scheduled__2023-05-13T00:00:00+00:00 [running]> on host 1545bed90dab
[2023-05-17T18:37:38.179+0000] {taskinstance.py:1570} INFO - Exporting env vars: AIRFLOW_CTX_DAG_EMAIL='Bhuribhat@gmail.com' AIRFLOW_CTX_DAG_OWNER='pras' AIRFLOW_CTX_DAG_ID='fondue_dag' AIRFLOW_CTX_TASK_ID='clustering' AIRFLOW_CTX_EXECUTION_DATE='2023-05-13T00:00:00+00:00' AIRFLOW_CTX_TRY_NUMBER='1' AIRFLOW_CTX_DAG_RUN_ID='scheduled__2023-05-13T00:00:00+00:00'
[2023-05-17T18:37:41.701+0000] {logging_mixin.py:149} WARNING - 2023/05/17 18:37:41 WARNING mlflow.utils.git_utils: Failed to import Git (the Git executable is probably not on your PATH), so Git SHA is not available. Error: Failed to initialize: Bad git executable.
The git executable must be specified in one of the following ways:
    - be included in your $PATH
    - be set via $GIT_PYTHON_GIT_EXECUTABLE
    - explicitly set via git.refresh()

All git commands will error until this is rectified.

This initial warning can be silenced or aggravated in the future by setting the
$GIT_PYTHON_REFRESH environment variable. Use one of the following values:
    - quiet|q|silence|s|none|n|0: for no warning or exception
    - warn|w|warning|1: for a printed warning
    - error|e|raise|r|2: for a raised exception

Example:
    export GIT_PYTHON_REFRESH=quiet
[2023-05-17T18:37:46.088+0000] {python.py:183} INFO - Done. Returned value was: None
[2023-05-17T18:37:46.104+0000] {taskinstance.py:1373} INFO - Marking task as SUCCESS. dag_id=fondue_dag, task_id=clustering, execution_date=20230513T000000, start_date=20230517T183737, end_date=20230517T183746
[2023-05-17T18:37:46.153+0000] {local_task_job_runner.py:232} INFO - Task exited with return code 0
[2023-05-17T18:37:46.180+0000] {taskinstance.py:2674} INFO - 1 downstream tasks scheduled from follow-on schedule check
[2023-05-18T06:41:19.710+0000] {taskinstance.py:1125} INFO - Dependencies all met for dep_context=non-requeueable deps ti=<TaskInstance: fondue_dag.clustering scheduled__2023-05-13T00:00:00+00:00 [queued]>
[2023-05-18T06:41:19.734+0000] {taskinstance.py:1125} INFO - Dependencies all met for dep_context=requeueable deps ti=<TaskInstance: fondue_dag.clustering scheduled__2023-05-13T00:00:00+00:00 [queued]>
[2023-05-18T06:41:19.736+0000] {taskinstance.py:1331} INFO - Starting attempt 1 of 2
[2023-05-18T06:41:19.769+0000] {taskinstance.py:1350} INFO - Executing <Task(PythonOperator): clustering> on 2023-05-13 00:00:00+00:00
[2023-05-18T06:41:19.783+0000] {standard_task_runner.py:57} INFO - Started process 1389 to run task
[2023-05-18T06:41:19.793+0000] {standard_task_runner.py:84} INFO - Running: ['***', 'tasks', 'run', 'fondue_dag', 'clustering', 'scheduled__2023-05-13T00:00:00+00:00', '--job-id', '40', '--raw', '--subdir', 'DAGS_FOLDER/fondue_dag.py', '--cfg-path', '/tmp/tmpbh53_jqc']
[2023-05-18T06:41:19.797+0000] {standard_task_runner.py:85} INFO - Job 40: Subtask clustering
[2023-05-18T06:41:19.907+0000] {task_command.py:410} INFO - Running <TaskInstance: fondue_dag.clustering scheduled__2023-05-13T00:00:00+00:00 [running]> on host 714a0c7ad307
[2023-05-18T06:41:20.167+0000] {taskinstance.py:1570} INFO - Exporting env vars: AIRFLOW_CTX_DAG_EMAIL='Bhuribhat@gmail.com' AIRFLOW_CTX_DAG_OWNER='pras' AIRFLOW_CTX_DAG_ID='fondue_dag' AIRFLOW_CTX_TASK_ID='clustering' AIRFLOW_CTX_EXECUTION_DATE='2023-05-13T00:00:00+00:00' AIRFLOW_CTX_TRY_NUMBER='1' AIRFLOW_CTX_DAG_RUN_ID='scheduled__2023-05-13T00:00:00+00:00'
[2023-05-18T06:41:46.536+0000] {logging_mixin.py:149} WARNING - 2023/05/18 06:41:46 WARNING mlflow.utils.git_utils: Failed to import Git (the Git executable is probably not on your PATH), so Git SHA is not available. Error: Failed to initialize: Bad git executable.
The git executable must be specified in one of the following ways:
    - be included in your $PATH
    - be set via $GIT_PYTHON_GIT_EXECUTABLE
    - explicitly set via git.refresh()

All git commands will error until this is rectified.

This initial warning can be silenced or aggravated in the future by setting the
$GIT_PYTHON_REFRESH environment variable. Use one of the following values:
    - quiet|q|silence|s|none|n|0: for no warning or exception
    - warn|w|warning|1: for a printed warning
    - error|e|raise|r|2: for a raised exception

Example:
    export GIT_PYTHON_REFRESH=quiet
[2023-05-18T06:41:46.653+0000] {taskinstance.py:1847} ERROR - Task failed with exception
Traceback (most recent call last):
  File "/home/airflow/.local/lib/python3.7/site-packages/airflow/operators/python.py", line 181, in execute
    return_value = self.execute_callable()
  File "/home/airflow/.local/lib/python3.7/site-packages/airflow/operators/python.py", line 198, in execute_callable
    return self.python_callable(*self.op_args, **self.op_kwargs)
  File "/opt/airflow/dags/utils/clustering.py", line 46, in kmean_cluster
    with mlflow.start_run() as run:
  File "/home/airflow/.local/lib/python3.7/site-packages/mlflow/tracking/fluent.py", line 277, in start_run
    ).format(_active_run_stack[0].info.run_id)
Exception: Run with UUID 0f766001b9034fbfb27adeec070d0a42 is already active. To start a new run, first end the current run with mlflow.end_run(). To start a nested run, call start_run with nested=True
[2023-05-18T06:41:46.677+0000] {taskinstance.py:1373} INFO - Marking task as UP_FOR_RETRY. dag_id=fondue_dag, task_id=clustering, execution_date=20230513T000000, start_date=20230518T064119, end_date=20230518T064146
[2023-05-18T06:41:46.707+0000] {configuration.py:675} WARNING - section/key [smtp/smtp_user] not found in config
[2023-05-18T06:41:46.708+0000] {email.py:268} INFO - Email alerting: attempt 1
[2023-05-18T06:41:46.718+0000] {configuration.py:675} WARNING - section/key [smtp/smtp_user] not found in config
[2023-05-18T06:41:46.719+0000] {email.py:268} INFO - Email alerting: attempt 1
[2023-05-18T06:41:46.720+0000] {taskinstance.py:1912} ERROR - Failed to send email to: ['Bhuribhat@gmail.com']
Traceback (most recent call last):
  File "/home/airflow/.local/lib/python3.7/site-packages/airflow/models/taskinstance.py", line 1430, in _run_raw_task
    self._execute_task_with_callbacks(context, test_mode)
  File "/home/airflow/.local/lib/python3.7/site-packages/airflow/models/taskinstance.py", line 1581, in _execute_task_with_callbacks
    result = self._execute_task(context, task_orig)
  File "/home/airflow/.local/lib/python3.7/site-packages/airflow/models/taskinstance.py", line 1651, in _execute_task
    result = execute_callable(context=context)
  File "/home/airflow/.local/lib/python3.7/site-packages/airflow/operators/python.py", line 181, in execute
    return_value = self.execute_callable()
  File "/home/airflow/.local/lib/python3.7/site-packages/airflow/operators/python.py", line 198, in execute_callable
    return self.python_callable(*self.op_args, **self.op_kwargs)
  File "/opt/airflow/dags/utils/clustering.py", line 46, in kmean_cluster
    with mlflow.start_run() as run:
  File "/home/airflow/.local/lib/python3.7/site-packages/mlflow/tracking/fluent.py", line 277, in start_run
    ).format(_active_run_stack[0].info.run_id)
Exception: Run with UUID 0f766001b9034fbfb27adeec070d0a42 is already active. To start a new run, first end the current run with mlflow.end_run(). To start a nested run, call start_run with nested=True

During handling of the above exception, another exception occurred:

Traceback (most recent call last):
  File "/home/airflow/.local/lib/python3.7/site-packages/airflow/models/taskinstance.py", line 2318, in email_alert
    send_email(task.email, subject, html_content)
  File "/home/airflow/.local/lib/python3.7/site-packages/airflow/utils/email.py", line 91, in send_email
    **kwargs,
  File "/home/airflow/.local/lib/python3.7/site-packages/airflow/utils/email.py", line 152, in send_email_smtp
    send_mime_email(e_from=mail_from, e_to=recipients, mime_msg=msg, conn_id=conn_id, dryrun=dryrun)
  File "/home/airflow/.local/lib/python3.7/site-packages/airflow/utils/email.py", line 270, in send_mime_email
    smtp_conn = _get_smtp_connection(smtp_host, smtp_port, smtp_timeout, smtp_ssl)
  File "/home/airflow/.local/lib/python3.7/site-packages/airflow/utils/email.py", line 317, in _get_smtp_connection
    else smtplib.SMTP(host=host, port=port, timeout=timeout)
  File "/usr/local/lib/python3.7/smtplib.py", line 251, in __init__
    (code, msg) = self.connect(host, port)
  File "/usr/local/lib/python3.7/smtplib.py", line 336, in connect
    self.sock = self._get_socket(host, port, self.timeout)
  File "/usr/local/lib/python3.7/smtplib.py", line 307, in _get_socket
    self.source_address)
  File "/usr/local/lib/python3.7/socket.py", line 728, in create_connection
    raise err
  File "/usr/local/lib/python3.7/socket.py", line 716, in create_connection
    sock.connect(sa)
OSError: [Errno 99] Cannot assign requested address

During handling of the above exception, another exception occurred:

Traceback (most recent call last):
  File "/home/airflow/.local/lib/python3.7/site-packages/airflow/models/taskinstance.py", line 1910, in handle_failure
    self.email_alert(error, task)
  File "/home/airflow/.local/lib/python3.7/site-packages/airflow/models/taskinstance.py", line 2320, in email_alert
    send_email(task.email, subject, html_content_err)
  File "/home/airflow/.local/lib/python3.7/site-packages/airflow/utils/email.py", line 91, in send_email
    **kwargs,
  File "/home/airflow/.local/lib/python3.7/site-packages/airflow/utils/email.py", line 152, in send_email_smtp
    send_mime_email(e_from=mail_from, e_to=recipients, mime_msg=msg, conn_id=conn_id, dryrun=dryrun)
  File "/home/airflow/.local/lib/python3.7/site-packages/airflow/utils/email.py", line 270, in send_mime_email
    smtp_conn = _get_smtp_connection(smtp_host, smtp_port, smtp_timeout, smtp_ssl)
  File "/home/airflow/.local/lib/python3.7/site-packages/airflow/utils/email.py", line 317, in _get_smtp_connection
    else smtplib.SMTP(host=host, port=port, timeout=timeout)
  File "/usr/local/lib/python3.7/smtplib.py", line 251, in __init__
    (code, msg) = self.connect(host, port)
  File "/usr/local/lib/python3.7/smtplib.py", line 336, in connect
    self.sock = self._get_socket(host, port, self.timeout)
  File "/usr/local/lib/python3.7/smtplib.py", line 307, in _get_socket
    self.source_address)
  File "/usr/local/lib/python3.7/socket.py", line 728, in create_connection
    raise err
  File "/usr/local/lib/python3.7/socket.py", line 716, in create_connection
    sock.connect(sa)
OSError: [Errno 99] Cannot assign requested address
[2023-05-18T06:41:46.747+0000] {standard_task_runner.py:109} ERROR - Failed to execute job 40 for task clustering (Run with UUID 0f766001b9034fbfb27adeec070d0a42 is already active. To start a new run, first end the current run with mlflow.end_run(). To start a nested run, call start_run with nested=True; 1389)
[2023-05-18T06:41:46.793+0000] {local_task_job_runner.py:232} INFO - Task exited with return code 1
[2023-05-18T06:41:46.820+0000] {taskinstance.py:2674} INFO - 0 downstream tasks scheduled from follow-on schedule check
[2023-05-18T06:53:30.378+0000] {taskinstance.py:1125} INFO - Dependencies all met for dep_context=non-requeueable deps ti=<TaskInstance: fondue_dag.clustering scheduled__2023-05-13T00:00:00+00:00 [queued]>
[2023-05-18T06:53:30.409+0000] {taskinstance.py:1125} INFO - Dependencies all met for dep_context=requeueable deps ti=<TaskInstance: fondue_dag.clustering scheduled__2023-05-13T00:00:00+00:00 [queued]>
[2023-05-18T06:53:30.411+0000] {taskinstance.py:1331} INFO - Starting attempt 1 of 2
[2023-05-18T06:53:30.461+0000] {taskinstance.py:1350} INFO - Executing <Task(PythonOperator): clustering> on 2023-05-13 00:00:00+00:00
[2023-05-18T06:53:30.473+0000] {standard_task_runner.py:57} INFO - Started process 1552 to run task
[2023-05-18T06:53:30.479+0000] {standard_task_runner.py:84} INFO - Running: ['***', 'tasks', 'run', 'fondue_dag', 'clustering', 'scheduled__2023-05-13T00:00:00+00:00', '--job-id', '40', '--raw', '--subdir', 'DAGS_FOLDER/fondue_dag.py', '--cfg-path', '/tmp/tmpwy5fb3hu']
[2023-05-18T06:53:30.483+0000] {standard_task_runner.py:85} INFO - Job 40: Subtask clustering
[2023-05-18T06:53:30.633+0000] {task_command.py:410} INFO - Running <TaskInstance: fondue_dag.clustering scheduled__2023-05-13T00:00:00+00:00 [running]> on host 26547302378e
[2023-05-18T06:53:30.817+0000] {taskinstance.py:1570} INFO - Exporting env vars: AIRFLOW_CTX_DAG_EMAIL='Bhuribhat@gmail.com' AIRFLOW_CTX_DAG_OWNER='pras' AIRFLOW_CTX_DAG_ID='fondue_dag' AIRFLOW_CTX_TASK_ID='clustering' AIRFLOW_CTX_EXECUTION_DATE='2023-05-13T00:00:00+00:00' AIRFLOW_CTX_TRY_NUMBER='1' AIRFLOW_CTX_DAG_RUN_ID='scheduled__2023-05-13T00:00:00+00:00'
[2023-05-18T06:53:52.045+0000] {logging_mixin.py:149} WARNING - 2023/05/18 06:53:52 WARNING mlflow.utils.git_utils: Failed to import Git (the Git executable is probably not on your PATH), so Git SHA is not available. Error: Failed to initialize: Bad git executable.
The git executable must be specified in one of the following ways:
    - be included in your $PATH
    - be set via $GIT_PYTHON_GIT_EXECUTABLE
    - explicitly set via git.refresh()

All git commands will error until this is rectified.

This initial warning can be silenced or aggravated in the future by setting the
$GIT_PYTHON_REFRESH environment variable. Use one of the following values:
    - quiet|q|silence|s|none|n|0: for no warning or exception
    - warn|w|warning|1: for a printed warning
    - error|e|raise|r|2: for a raised exception

Example:
    export GIT_PYTHON_REFRESH=quiet
[2023-05-18T06:54:00.327+0000] {python.py:183} INFO - Done. Returned value was: None
[2023-05-18T06:54:00.348+0000] {taskinstance.py:1373} INFO - Marking task as SUCCESS. dag_id=fondue_dag, task_id=clustering, execution_date=20230513T000000, start_date=20230518T065330, end_date=20230518T065400
[2023-05-18T06:54:00.519+0000] {local_task_job_runner.py:232} INFO - Task exited with return code 0
[2023-05-18T06:54:00.557+0000] {taskinstance.py:2674} INFO - 1 downstream tasks scheduled from follow-on schedule check
=======
[2023-05-18T04:23:16.414+0000] {python.py:183} INFO - Done. Returned value was: None
[2023-05-18T04:23:16.433+0000] {taskinstance.py:1373} INFO - Marking task as SUCCESS. dag_id=fondue_dag, task_id=clustering, execution_date=20230513T000000, start_date=20230518T042223, end_date=20230518T042316
[2023-05-18T04:23:16.502+0000] {local_task_job_runner.py:232} INFO - Task exited with return code 0
[2023-05-18T04:23:16.542+0000] {taskinstance.py:2674} INFO - 1 downstream tasks scheduled from follow-on schedule check
>>>>>>> 8e4a41b368593e9ce283ae02afd6c27252f67370
