[2023-05-16T07:25:12.279+0000] {taskinstance.py:1125} INFO - Dependencies all met for dep_context=non-requeueable deps ti=<TaskInstance: fondue_dag.clean_fondue_data manual__2023-05-16T07:25:05.623499+00:00 [queued]>
[2023-05-16T07:25:12.290+0000] {taskinstance.py:1125} INFO - Dependencies all met for dep_context=requeueable deps ti=<TaskInstance: fondue_dag.clean_fondue_data manual__2023-05-16T07:25:05.623499+00:00 [queued]>
[2023-05-16T07:25:12.291+0000] {taskinstance.py:1331} INFO - Starting attempt 1 of 2
[2023-05-16T07:25:12.309+0000] {taskinstance.py:1350} INFO - Executing <Task(PythonOperator): clean_fondue_data> on 2023-05-16 07:25:05.623499+00:00
[2023-05-16T07:25:12.316+0000] {standard_task_runner.py:57} INFO - Started process 1446 to run task
[2023-05-16T07:25:12.318+0000] {standard_task_runner.py:84} INFO - Running: ['***', 'tasks', 'run', 'fondue_dag', 'clean_fondue_data', 'manual__2023-05-16T07:25:05.623499+00:00', '--job-id', '52', '--raw', '--subdir', 'DAGS_FOLDER/fondue_dag.py', '--cfg-path', '/tmp/tmpc_j9bjsw']
[2023-05-16T07:25:12.320+0000] {standard_task_runner.py:85} INFO - Job 52: Subtask clean_fondue_data
[2023-05-16T07:25:12.373+0000] {task_command.py:410} INFO - Running <TaskInstance: fondue_dag.clean_fondue_data manual__2023-05-16T07:25:05.623499+00:00 [running]> on host a76a3b1a3408
[2023-05-16T07:25:12.466+0000] {taskinstance.py:1570} INFO - Exporting env vars: AIRFLOW_CTX_DAG_EMAIL='Bhuribhat@gmail.com' AIRFLOW_CTX_DAG_OWNER='pras' AIRFLOW_CTX_DAG_ID='fondue_dag' AIRFLOW_CTX_TASK_ID='clean_fondue_data' AIRFLOW_CTX_EXECUTION_DATE='2023-05-16T07:25:05.623499+00:00' AIRFLOW_CTX_TRY_NUMBER='1' AIRFLOW_CTX_DAG_RUN_ID='manual__2023-05-16T07:25:05.623499+00:00'
[2023-05-16T07:25:12.510+0000] {taskinstance.py:1847} ERROR - Task failed with exception
Traceback (most recent call last):
  File "/home/airflow/.local/lib/python3.7/site-packages/airflow/operators/python.py", line 181, in execute
    return_value = self.execute_callable()
  File "/home/airflow/.local/lib/python3.7/site-packages/airflow/operators/python.py", line 198, in execute_callable
    return self.python_callable(*self.op_args, **self.op_kwargs)
  File "/opt/airflow/dags/utils/clean_data.py", line 37, in clean_data
    df = df.astype({"latitude": float, "longitude": float})
  File "/home/airflow/.local/lib/python3.7/site-packages/pandas/core/generic.py", line 5799, in astype
    col.astype(dtype=dtype[col_name], copy=copy, errors=errors)
  File "/home/airflow/.local/lib/python3.7/site-packages/pandas/core/generic.py", line 5815, in astype
    new_data = self._mgr.astype(dtype=dtype, copy=copy, errors=errors)
  File "/home/airflow/.local/lib/python3.7/site-packages/pandas/core/internals/managers.py", line 418, in astype
    return self.apply("astype", dtype=dtype, copy=copy, errors=errors)
  File "/home/airflow/.local/lib/python3.7/site-packages/pandas/core/internals/managers.py", line 327, in apply
    applied = getattr(b, f)(**kwargs)
  File "/home/airflow/.local/lib/python3.7/site-packages/pandas/core/internals/blocks.py", line 591, in astype
    new_values = astype_array_safe(values, dtype, copy=copy, errors=errors)
  File "/home/airflow/.local/lib/python3.7/site-packages/pandas/core/dtypes/cast.py", line 1309, in astype_array_safe
    new_values = astype_array(values, dtype, copy=copy)
  File "/home/airflow/.local/lib/python3.7/site-packages/pandas/core/dtypes/cast.py", line 1257, in astype_array
    values = astype_nansafe(values, dtype, copy=copy)
  File "/home/airflow/.local/lib/python3.7/site-packages/pandas/core/dtypes/cast.py", line 1201, in astype_nansafe
    return arr.astype(dtype, copy=True)
ValueError: could not convert string to float: "['100.53103'"
[2023-05-16T07:25:12.525+0000] {taskinstance.py:1373} INFO - Marking task as UP_FOR_RETRY. dag_id=fondue_dag, task_id=clean_fondue_data, execution_date=20230516T072505, start_date=20230516T072512, end_date=20230516T072512
[2023-05-16T07:25:12.545+0000] {logging_mixin.py:149} WARNING - /home/***/.local/lib/python3.7/site-packages/***/utils/email.py:152 RemovedInAirflow3Warning: Fetching SMTP credentials from configuration variables will be deprecated in a future release. Please set credentials using a connection instead.
[2023-05-16T07:25:12.546+0000] {configuration.py:675} WARNING - section/key [smtp/smtp_user] not found in config
[2023-05-16T07:25:12.547+0000] {email.py:268} INFO - Email alerting: attempt 1
[2023-05-16T07:25:12.554+0000] {configuration.py:675} WARNING - section/key [smtp/smtp_user] not found in config
[2023-05-16T07:25:12.555+0000] {email.py:268} INFO - Email alerting: attempt 1
[2023-05-16T07:25:12.555+0000] {taskinstance.py:1912} ERROR - Failed to send email to: ['Bhuribhat@gmail.com']
Traceback (most recent call last):
  File "/home/airflow/.local/lib/python3.7/site-packages/airflow/models/taskinstance.py", line 1430, in _run_raw_task
    self._execute_task_with_callbacks(context, test_mode)
  File "/home/airflow/.local/lib/python3.7/site-packages/airflow/models/taskinstance.py", line 1581, in _execute_task_with_callbacks
    result = self._execute_task(context, task_orig)
  File "/home/airflow/.local/lib/python3.7/site-packages/airflow/models/taskinstance.py", line 1651, in _execute_task
    result = execute_callable(context=context)
  File "/home/airflow/.local/lib/python3.7/site-packages/airflow/operators/python.py", line 181, in execute
    return_value = self.execute_callable()
  File "/home/airflow/.local/lib/python3.7/site-packages/airflow/operators/python.py", line 198, in execute_callable
    return self.python_callable(*self.op_args, **self.op_kwargs)
  File "/opt/airflow/dags/utils/clean_data.py", line 37, in clean_data
    df = df.astype({"latitude": float, "longitude": float})
  File "/home/airflow/.local/lib/python3.7/site-packages/pandas/core/generic.py", line 5799, in astype
    col.astype(dtype=dtype[col_name], copy=copy, errors=errors)
  File "/home/airflow/.local/lib/python3.7/site-packages/pandas/core/generic.py", line 5815, in astype
    new_data = self._mgr.astype(dtype=dtype, copy=copy, errors=errors)
  File "/home/airflow/.local/lib/python3.7/site-packages/pandas/core/internals/managers.py", line 418, in astype
    return self.apply("astype", dtype=dtype, copy=copy, errors=errors)
  File "/home/airflow/.local/lib/python3.7/site-packages/pandas/core/internals/managers.py", line 327, in apply
    applied = getattr(b, f)(**kwargs)
  File "/home/airflow/.local/lib/python3.7/site-packages/pandas/core/internals/blocks.py", line 591, in astype
    new_values = astype_array_safe(values, dtype, copy=copy, errors=errors)
  File "/home/airflow/.local/lib/python3.7/site-packages/pandas/core/dtypes/cast.py", line 1309, in astype_array_safe
    new_values = astype_array(values, dtype, copy=copy)
  File "/home/airflow/.local/lib/python3.7/site-packages/pandas/core/dtypes/cast.py", line 1257, in astype_array
    values = astype_nansafe(values, dtype, copy=copy)
  File "/home/airflow/.local/lib/python3.7/site-packages/pandas/core/dtypes/cast.py", line 1201, in astype_nansafe
    return arr.astype(dtype, copy=True)
ValueError: could not convert string to float: "['100.53103'"

During handling of the above exception, another exception occurred:

Traceback (most recent call last):
  File "/home/airflow/.local/lib/python3.7/site-packages/airflow/models/taskinstance.py", line 2318, in email_alert
    send_email(task.email, subject, html_content)
  File "/home/airflow/.local/lib/python3.7/site-packages/airflow/utils/email.py", line 91, in send_email
    **kwargs,
  File "/home/airflow/.local/lib/python3.7/site-packages/airflow/utils/email.py", line 152, in send_email_smtp
    send_mime_email(e_from=mail_from, e_to=recipients, mime_msg=msg, conn_id=conn_id, dryrun=dryrun)
  File "/home/airflow/.local/lib/python3.7/site-packages/airflow/utils/email.py", line 270, in send_mime_email
    smtp_conn = _get_smtp_connection(smtp_host, smtp_port, smtp_timeout, smtp_ssl)
  File "/home/airflow/.local/lib/python3.7/site-packages/airflow/utils/email.py", line 317, in _get_smtp_connection
    else smtplib.SMTP(host=host, port=port, timeout=timeout)
  File "/usr/local/lib/python3.7/smtplib.py", line 251, in __init__
    (code, msg) = self.connect(host, port)
  File "/usr/local/lib/python3.7/smtplib.py", line 336, in connect
    self.sock = self._get_socket(host, port, self.timeout)
  File "/usr/local/lib/python3.7/smtplib.py", line 307, in _get_socket
    self.source_address)
  File "/usr/local/lib/python3.7/socket.py", line 728, in create_connection
    raise err
  File "/usr/local/lib/python3.7/socket.py", line 716, in create_connection
    sock.connect(sa)
OSError: [Errno 99] Cannot assign requested address

During handling of the above exception, another exception occurred:

Traceback (most recent call last):
  File "/home/airflow/.local/lib/python3.7/site-packages/airflow/models/taskinstance.py", line 1910, in handle_failure
    self.email_alert(error, task)
  File "/home/airflow/.local/lib/python3.7/site-packages/airflow/models/taskinstance.py", line 2320, in email_alert
    send_email(task.email, subject, html_content_err)
  File "/home/airflow/.local/lib/python3.7/site-packages/airflow/utils/email.py", line 91, in send_email
    **kwargs,
  File "/home/airflow/.local/lib/python3.7/site-packages/airflow/utils/email.py", line 152, in send_email_smtp
    send_mime_email(e_from=mail_from, e_to=recipients, mime_msg=msg, conn_id=conn_id, dryrun=dryrun)
  File "/home/airflow/.local/lib/python3.7/site-packages/airflow/utils/email.py", line 270, in send_mime_email
    smtp_conn = _get_smtp_connection(smtp_host, smtp_port, smtp_timeout, smtp_ssl)
  File "/home/airflow/.local/lib/python3.7/site-packages/airflow/utils/email.py", line 317, in _get_smtp_connection
    else smtplib.SMTP(host=host, port=port, timeout=timeout)
  File "/usr/local/lib/python3.7/smtplib.py", line 251, in __init__
    (code, msg) = self.connect(host, port)
  File "/usr/local/lib/python3.7/smtplib.py", line 336, in connect
    self.sock = self._get_socket(host, port, self.timeout)
  File "/usr/local/lib/python3.7/smtplib.py", line 307, in _get_socket
    self.source_address)
  File "/usr/local/lib/python3.7/socket.py", line 728, in create_connection
    raise err
  File "/usr/local/lib/python3.7/socket.py", line 716, in create_connection
    sock.connect(sa)
OSError: [Errno 99] Cannot assign requested address
[2023-05-16T07:25:12.573+0000] {standard_task_runner.py:109} ERROR - Failed to execute job 52 for task clean_fondue_data (could not convert string to float: "['100.53103'"; 1446)
[2023-05-16T07:25:12.612+0000] {local_task_job_runner.py:232} INFO - Task exited with return code 1
[2023-05-16T07:25:12.633+0000] {taskinstance.py:2674} INFO - 0 downstream tasks scheduled from follow-on schedule check
