[2023-05-18T06:47:54.586+0000] {taskinstance.py:1125} INFO - Dependencies all met for dep_context=non-requeueable deps ti=<TaskInstance: fondue_dag.open_mlflow_ui scheduled__2023-05-10T00:00:00+00:00 [queued]>
[2023-05-18T06:47:54.604+0000] {taskinstance.py:1125} INFO - Dependencies all met for dep_context=requeueable deps ti=<TaskInstance: fondue_dag.open_mlflow_ui scheduled__2023-05-10T00:00:00+00:00 [queued]>
[2023-05-18T06:47:54.605+0000] {taskinstance.py:1331} INFO - Starting attempt 1 of 2
[2023-05-18T06:47:54.633+0000] {taskinstance.py:1350} INFO - Executing <Task(BashOperator): open_mlflow_ui> on 2023-05-10 00:00:00+00:00
[2023-05-18T06:47:54.643+0000] {standard_task_runner.py:57} INFO - Started process 5089 to run task
[2023-05-18T06:47:54.646+0000] {standard_task_runner.py:84} INFO - Running: ['***', 'tasks', 'run', 'fondue_dag', 'open_mlflow_ui', 'scheduled__2023-05-10T00:00:00+00:00', '--job-id', '69', '--raw', '--subdir', 'DAGS_FOLDER/fondue_dag.py', '--cfg-path', '/tmp/tmpfizsq1nm']
[2023-05-18T06:47:54.649+0000] {standard_task_runner.py:85} INFO - Job 69: Subtask open_mlflow_ui
[2023-05-18T06:47:54.725+0000] {task_command.py:410} INFO - Running <TaskInstance: fondue_dag.open_mlflow_ui scheduled__2023-05-10T00:00:00+00:00 [running]> on host 714a0c7ad307
[2023-05-18T06:47:54.867+0000] {taskinstance.py:1570} INFO - Exporting env vars: AIRFLOW_CTX_DAG_EMAIL='Bhuribhat@gmail.com' AIRFLOW_CTX_DAG_OWNER='pras' AIRFLOW_CTX_DAG_ID='fondue_dag' AIRFLOW_CTX_TASK_ID='open_mlflow_ui' AIRFLOW_CTX_EXECUTION_DATE='2023-05-10T00:00:00+00:00' AIRFLOW_CTX_TRY_NUMBER='1' AIRFLOW_CTX_DAG_RUN_ID='scheduled__2023-05-10T00:00:00+00:00'
[2023-05-18T06:47:54.870+0000] {subprocess.py:63} INFO - Tmp dir root location: 
 /tmp
[2023-05-18T06:47:54.872+0000] {subprocess.py:75} INFO - Running command: ['/bin/bash', '-c', 'mlflow ui --host 0.0.0.0 --port 5000']
[2023-05-18T06:47:54.898+0000] {subprocess.py:86} INFO - Output:
[2023-05-18T06:47:59.109+0000] {subprocess.py:93} INFO - [2023-05-18 06:47:59 +0000] [5209] [INFO] Starting gunicorn 20.1.0
[2023-05-18T06:47:59.110+0000] {subprocess.py:93} INFO - [2023-05-18 06:47:59 +0000] [5209] [ERROR] Connection in use: ('0.0.0.0', 5000)
[2023-05-18T06:47:59.111+0000] {subprocess.py:93} INFO - [2023-05-18 06:47:59 +0000] [5209] [ERROR] Retrying in 1 second.
[2023-05-18T06:48:00.111+0000] {subprocess.py:93} INFO - [2023-05-18 06:48:00 +0000] [5209] [ERROR] Connection in use: ('0.0.0.0', 5000)
[2023-05-18T06:48:00.113+0000] {subprocess.py:93} INFO - [2023-05-18 06:48:00 +0000] [5209] [ERROR] Retrying in 1 second.
[2023-05-18T06:48:01.113+0000] {subprocess.py:93} INFO - [2023-05-18 06:48:01 +0000] [5209] [ERROR] Connection in use: ('0.0.0.0', 5000)
[2023-05-18T06:48:01.114+0000] {subprocess.py:93} INFO - [2023-05-18 06:48:01 +0000] [5209] [ERROR] Retrying in 1 second.
[2023-05-18T06:48:02.115+0000] {subprocess.py:93} INFO - [2023-05-18 06:48:02 +0000] [5209] [ERROR] Connection in use: ('0.0.0.0', 5000)
[2023-05-18T06:48:02.116+0000] {subprocess.py:93} INFO - [2023-05-18 06:48:02 +0000] [5209] [ERROR] Retrying in 1 second.
[2023-05-18T06:48:02.430+0000] {local_task_job_runner.py:122} ERROR - Received SIGTERM. Terminating subprocesses
[2023-05-18T06:48:02.501+0000] {process_utils.py:135} INFO - Sending Signals.SIGTERM to group 5089. PIDs of all processes in the group: [5095, 5209, 5089]
[2023-05-18T06:48:02.535+0000] {process_utils.py:86} INFO - Sending the signal Signals.SIGTERM to group 5089
[2023-05-18T06:48:02.551+0000] {taskinstance.py:1540} ERROR - Received SIGTERM. Terminating subprocesses.
[2023-05-18T06:48:02.566+0000] {subprocess.py:104} INFO - Sending SIGTERM signal to process group
[2023-05-18T06:48:02.684+0000] {taskinstance.py:1847} ERROR - Task failed with exception
Traceback (most recent call last):
  File "/home/airflow/.local/lib/python3.7/site-packages/airflow/operators/bash.py", line 205, in execute
    cwd=self.cwd,
  File "/home/airflow/.local/lib/python3.7/site-packages/airflow/hooks/subprocess.py", line 91, in run_command
    for raw_line in iter(self.sub_process.stdout.readline, b""):
  File "/home/airflow/.local/lib/python3.7/site-packages/airflow/models/taskinstance.py", line 1542, in signal_handler
    raise AirflowException("Task received SIGTERM signal")
airflow.exceptions.AirflowException: Task received SIGTERM signal
[2023-05-18T06:48:02.702+0000] {taskinstance.py:1373} INFO - Marking task as UP_FOR_RETRY. dag_id=fondue_dag, task_id=open_mlflow_ui, execution_date=20230510T000000, start_date=20230518T064754, end_date=20230518T064802
[2023-05-18T06:48:02.790+0000] {configuration.py:675} WARNING - section/key [smtp/smtp_user] not found in config
[2023-05-18T06:48:02.792+0000] {email.py:268} INFO - Email alerting: attempt 1
[2023-05-18T06:48:02.826+0000] {configuration.py:675} WARNING - section/key [smtp/smtp_user] not found in config
[2023-05-18T06:48:02.831+0000] {email.py:268} INFO - Email alerting: attempt 1
[2023-05-18T06:48:02.833+0000] {taskinstance.py:1912} ERROR - Failed to send email to: ['Bhuribhat@gmail.com']
Traceback (most recent call last):
  File "/home/airflow/.local/lib/python3.7/site-packages/airflow/models/taskinstance.py", line 1430, in _run_raw_task
    self._execute_task_with_callbacks(context, test_mode)
  File "/home/airflow/.local/lib/python3.7/site-packages/airflow/models/taskinstance.py", line 1581, in _execute_task_with_callbacks
    result = self._execute_task(context, task_orig)
  File "/home/airflow/.local/lib/python3.7/site-packages/airflow/models/taskinstance.py", line 1651, in _execute_task
    result = execute_callable(context=context)
  File "/home/airflow/.local/lib/python3.7/site-packages/airflow/operators/bash.py", line 205, in execute
    cwd=self.cwd,
  File "/home/airflow/.local/lib/python3.7/site-packages/airflow/hooks/subprocess.py", line 91, in run_command
    for raw_line in iter(self.sub_process.stdout.readline, b""):
  File "/home/airflow/.local/lib/python3.7/site-packages/airflow/models/taskinstance.py", line 1542, in signal_handler
    raise AirflowException("Task received SIGTERM signal")
airflow.exceptions.AirflowException: Task received SIGTERM signal

During handling of the above exception, another exception occurred:

Traceback (most recent call last):
  File "/home/airflow/.local/lib/python3.7/site-packages/airflow/models/taskinstance.py", line 2318, in email_alert
    send_email(task.email, subject, html_content)
  File "/home/airflow/.local/lib/python3.7/site-packages/airflow/utils/email.py", line 91, in send_email
    **kwargs,
  File "/home/airflow/.local/lib/python3.7/site-packages/airflow/utils/email.py", line 152, in send_email_smtp
    send_mime_email(e_from=mail_from, e_to=recipients, mime_msg=msg, conn_id=conn_id, dryrun=dryrun)
  File "/home/airflow/.local/lib/python3.7/site-packages/airflow/utils/email.py", line 270, in send_mime_email
    smtp_conn = _get_smtp_connection(smtp_host, smtp_port, smtp_timeout, smtp_ssl)
  File "/home/airflow/.local/lib/python3.7/site-packages/airflow/utils/email.py", line 317, in _get_smtp_connection
    else smtplib.SMTP(host=host, port=port, timeout=timeout)
  File "/usr/local/lib/python3.7/smtplib.py", line 251, in __init__
    (code, msg) = self.connect(host, port)
  File "/usr/local/lib/python3.7/smtplib.py", line 336, in connect
    self.sock = self._get_socket(host, port, self.timeout)
  File "/usr/local/lib/python3.7/smtplib.py", line 307, in _get_socket
    self.source_address)
  File "/usr/local/lib/python3.7/socket.py", line 728, in create_connection
    raise err
  File "/usr/local/lib/python3.7/socket.py", line 716, in create_connection
    sock.connect(sa)
OSError: [Errno 99] Cannot assign requested address

During handling of the above exception, another exception occurred:

Traceback (most recent call last):
  File "/home/airflow/.local/lib/python3.7/site-packages/airflow/models/taskinstance.py", line 1910, in handle_failure
    self.email_alert(error, task)
  File "/home/airflow/.local/lib/python3.7/site-packages/airflow/models/taskinstance.py", line 2320, in email_alert
    send_email(task.email, subject, html_content_err)
  File "/home/airflow/.local/lib/python3.7/site-packages/airflow/utils/email.py", line 91, in send_email
    **kwargs,
  File "/home/airflow/.local/lib/python3.7/site-packages/airflow/utils/email.py", line 152, in send_email_smtp
    send_mime_email(e_from=mail_from, e_to=recipients, mime_msg=msg, conn_id=conn_id, dryrun=dryrun)
  File "/home/airflow/.local/lib/python3.7/site-packages/airflow/utils/email.py", line 270, in send_mime_email
    smtp_conn = _get_smtp_connection(smtp_host, smtp_port, smtp_timeout, smtp_ssl)
  File "/home/airflow/.local/lib/python3.7/site-packages/airflow/utils/email.py", line 317, in _get_smtp_connection
    else smtplib.SMTP(host=host, port=port, timeout=timeout)
  File "/usr/local/lib/python3.7/smtplib.py", line 251, in __init__
    (code, msg) = self.connect(host, port)
  File "/usr/local/lib/python3.7/smtplib.py", line 336, in connect
    self.sock = self._get_socket(host, port, self.timeout)
  File "/usr/local/lib/python3.7/smtplib.py", line 307, in _get_socket
    self.source_address)
  File "/usr/local/lib/python3.7/socket.py", line 728, in create_connection
    raise err
  File "/usr/local/lib/python3.7/socket.py", line 716, in create_connection
    sock.connect(sa)
OSError: [Errno 99] Cannot assign requested address
[2023-05-18T06:48:02.902+0000] {standard_task_runner.py:109} ERROR - Failed to execute job 69 for task open_mlflow_ui (Task received SIGTERM signal; 5089)
[2023-05-18T06:48:02.935+0000] {process_utils.py:79} INFO - Process psutil.Process(pid=5089, status='terminated', exitcode=1, started='06:47:53') (5089) terminated with exit code 1
[2023-05-18T06:48:02.937+0000] {process_utils.py:79} INFO - Process psutil.Process(pid=5095, status='terminated', started='06:47:54') (5095) terminated with exit code None
[2023-05-18T06:48:05.641+0000] {local_task_job_runner.py:122} ERROR - Received SIGTERM. Terminating subprocesses
[2023-05-18T06:48:05.642+0000] {standard_task_runner.py:174} ERROR - Job 69 was killed before it finished (likely due to running out of memory)
