[2023-05-16T07:15:23.001+0000] {taskinstance.py:1125} INFO - Dependencies all met for dep_context=non-requeueable deps ti=<TaskInstance: fondue_dag.clean_fondue_data manual__2023-05-16T07:10:13.242711+00:00 [queued]>
[2023-05-16T07:15:23.022+0000] {taskinstance.py:1125} INFO - Dependencies all met for dep_context=requeueable deps ti=<TaskInstance: fondue_dag.clean_fondue_data manual__2023-05-16T07:10:13.242711+00:00 [queued]>
[2023-05-16T07:15:23.023+0000] {taskinstance.py:1331} INFO - Starting attempt 2 of 2
[2023-05-16T07:15:23.044+0000] {taskinstance.py:1350} INFO - Executing <Task(PythonOperator): clean_fondue_data> on 2023-05-16 07:10:13.242711+00:00
[2023-05-16T07:15:23.050+0000] {standard_task_runner.py:57} INFO - Started process 937 to run task
[2023-05-16T07:15:23.053+0000] {standard_task_runner.py:84} INFO - Running: ['***', 'tasks', 'run', 'fondue_dag', 'clean_fondue_data', 'manual__2023-05-16T07:10:13.242711+00:00', '--job-id', '40', '--raw', '--subdir', 'DAGS_FOLDER/fondue_dag.py', '--cfg-path', '/tmp/tmpz3ohsaw8']
[2023-05-16T07:15:23.055+0000] {standard_task_runner.py:85} INFO - Job 40: Subtask clean_fondue_data
[2023-05-16T07:15:23.107+0000] {task_command.py:410} INFO - Running <TaskInstance: fondue_dag.clean_fondue_data manual__2023-05-16T07:10:13.242711+00:00 [running]> on host a76a3b1a3408
[2023-05-16T07:15:23.195+0000] {taskinstance.py:1570} INFO - Exporting env vars: AIRFLOW_CTX_DAG_EMAIL='Bhuribhat@gmail.com' AIRFLOW_CTX_DAG_OWNER='pras' AIRFLOW_CTX_DAG_ID='fondue_dag' AIRFLOW_CTX_TASK_ID='clean_fondue_data' AIRFLOW_CTX_EXECUTION_DATE='2023-05-16T07:10:13.242711+00:00' AIRFLOW_CTX_TRY_NUMBER='2' AIRFLOW_CTX_DAG_RUN_ID='manual__2023-05-16T07:10:13.242711+00:00'
[2023-05-16T07:15:23.244+0000] {taskinstance.py:1847} ERROR - Task failed with exception
Traceback (most recent call last):
  File "/home/airflow/.local/lib/python3.7/site-packages/pandas/core/indexes/range.py", line 385, in get_loc
    return self._range.index(new_key)
ValueError: -3 is not in range

The above exception was the direct cause of the following exception:

Traceback (most recent call last):
  File "/home/airflow/.local/lib/python3.7/site-packages/airflow/operators/python.py", line 181, in execute
    return_value = self.execute_callable()
  File "/home/airflow/.local/lib/python3.7/site-packages/airflow/operators/python.py", line 198, in execute_callable
    return self.python_callable(*self.op_args, **self.op_kwargs)
  File "/opt/airflow/dags/utils/clean_data.py", line 25, in clean_data
    df['province'] = df['address'].str.split(' ')[-3]
  File "/home/airflow/.local/lib/python3.7/site-packages/pandas/core/series.py", line 942, in __getitem__
    return self._get_value(key)
  File "/home/airflow/.local/lib/python3.7/site-packages/pandas/core/series.py", line 1051, in _get_value
    loc = self.index.get_loc(label)
  File "/home/airflow/.local/lib/python3.7/site-packages/pandas/core/indexes/range.py", line 387, in get_loc
    raise KeyError(key) from err
KeyError: -3
[2023-05-16T07:15:23.262+0000] {taskinstance.py:1373} INFO - Marking task as FAILED. dag_id=fondue_dag, task_id=clean_fondue_data, execution_date=20230516T071013, start_date=20230516T071523, end_date=20230516T071523
[2023-05-16T07:15:23.276+0000] {standard_task_runner.py:109} ERROR - Failed to execute job 40 for task clean_fondue_data (-3; 937)
[2023-05-16T07:15:23.306+0000] {local_task_job_runner.py:232} INFO - Task exited with return code 1
[2023-05-16T07:15:23.325+0000] {taskinstance.py:2674} INFO - 0 downstream tasks scheduled from follow-on schedule check
